Workbook

Sheet 估值汇总
A1: 招商轮船 估值汇总
A2: 估值基准日 2026-09-30；模型状态 screen-grade；DCF 各情景经营预测取自三表模型；不构成投资建议
A4: 情景 | B4: WACC | C4: 永续增长率 | D4: 企业价值（百万元） | E4: 股权价值（百万元） | F4: 每股价值（元） | G4: 较现价空间 | H4: 终值占 EV | I4: 隐含 EV/EBITDA | J4: 情景说明
A5: 基准 | B5: 0.0836 | C5: 0.015 | D5: 77027.371 | E5: 60600.327 | F5: 7.5051133 | G5: -0.6275378 | H5: 0.76322717 | I5: 7.7559709 | J5: 2026 年地缘冲突推高油轮运价、新船集中交付，收入大增；2027～2028 年运价回落，2029 年起回归周期中枢。
A6: 悲观 | B6: 0.0886 | C6: 0.01 | D6: 37478.778 | E6: 21051.734 | F6: 2.6071748 | G6: -0.87061167 | H6: 0.77916554 | I6: 5.8062303 | J6: 地缘溢价快速消退、新船集中交付压低运价，收入增幅较小且回落更深，毛利率承压。
A7: 乐观 | B7: 0.0811 | C7: 0.02 | D7: 118099.13 | E7: 101672.09 | F7: 12.59169 | G7: -0.37510222 | H7: 0.76465321 | I7: 9.1751518 | J7: 油轮高景气延续至 2027 年，LNG 与干散货长约贡献增量，运价回落更缓。
A9: 方法 | B9: 低 | C9: 中/基准 | D9: 高
A10: DCF 每股价值（元） | B10: 2.6071748 | C10: 7.5051133 | D10: 12.59169
A11: 参考股价（元） | C11: 20.15
A12: DCF 与三表模型逐期核对：最大偏差 1.82e-12 百万元（一致）

Sheet 盈利预测
A1: 盈利预测（基准情景）
A2: 单位：百万元（每股为元）；蓝色为报表值或三表模型输出，黑色为公式；预测期归母净利润 = 净利润 × 最近实际年度归母占比；EPS 按最近期末总股本摊薄
A4: 项目 | B4: 2024A | C4: 2025A | D4: 2026E | E4: 2027E | F4: 2028E | G4: 2029E | H4: 2030E
A5: 营业收入 | B5: 25799.279 | C5: 28177.211 | D5: ='三表-利润表'!D5 -> 39448.096 | E5: ='三表-利润表'!E5 -> 35503.286 | F5: ='三表-利润表'!F5 -> 32663.023 | G5: ='三表-利润表'!G5 -> 33316.284 | H5: ='三表-利润表'!H5 -> 34315.772
A6: 营业收入增长率 | C6: =C5/B5-1 -> 0.092170471 | D6: =D5/C5-1 -> 0.4 | E6: =E5/D5-1 -> -0.1 | F6: =F5/E5-1 -> -0.08 | G6: =G5/F5-1 -> 0.02 | H6: =H5/G5-1 -> 0.03
A7: 营业成本 | B7: 18466.915 | C7: 20717.507 | D7: ='三表-利润表'!D6 -> 22090.934 | E7: ='三表-利润表'!E6 -> 22722.103 | F7: ='三表-利润表'!F6 -> 22864.116 | G7: ='三表-利润表'!G6 -> 23987.724 | H7: ='三表-利润表'!H6 -> 24707.356
A8: 毛利 | B8: =B5-B7 -> 7332.3648 | C8: =C5-C7 -> 7459.7039 | D8: =D5-D7 -> 17357.162 | E8: =E5-E7 -> 12781.183 | F8: =F5-F7 -> 9798.9069 | G8: =G5-G7 -> 9328.5594 | H8: =H5-H7 -> 9608.4162
A9: 毛利率 | B9: =B8/B5 -> 0.28420812 | C9: =C8/C5 -> 0.26474245 | D9: =D8/D5 -> 0.44 | E9: =E8/E5 -> 0.36 | F9: =F8/F5 -> 0.3 | G9: =G8/G5 -> 0.28 | H9: =H8/H5 -> 0.28
A10: EBIT（经营性） | B10: 6337.8402 | C10: 7079.5029 | D10: ='三表-利润表'!D11 -> 16544.625 | E10: ='三表-利润表'!E11 -> 11408.236 | F10: ='三表-利润表'!F11 -> 8013.4199 | G10: ='三表-利润表'!G11 -> 7410.8637 | H10: ='三表-利润表'!H11 -> 7663.1691
A11: 净利润 | B11: 5209.2038 | C11: 6070.7131 | D11: ='三表-利润表'!D17 -> 13503.206 | E11: ='三表-利润表'!E17 -> 8967.4699 | F11: ='三表-利润表'!F17 -> 5969.6464 | G11: ='三表-利润表'!G17 -> 5437.5536 | H11: ='三表-利润表'!H17 -> 5660.3542
A12: 归母净利润 | B12: 5107.4479 | C12: 6012.0963 | D12: =D11*$C$12/$C$11 -> 13372.823 | E12: =E11*$C$12/$C$11 -> 8880.883 | F12: =F11*$C$12/$C$11 -> 5912.0054 | G12: =G11*$C$12/$C$11 -> 5385.0504 | H12: =H11*$C$12/$C$11 -> 5605.6997
A13: 归母净利润增长率 | C13: =C12/B12-1 -> 0.17712336 | D13: =D12/C12-1 -> 1.2243196 | E13: =E12/D12-1 -> -0.33590068 | F13: =F12/E12-1 -> -0.33429982 | G13: =G12/F12-1 -> -0.089133052 | H13: =H12/G12-1 -> 0.040974418
A14: 归母净利率 | B14: =B12/B5 -> 0.19796863 | C14: =C12/C5 -> 0.21336733 | D14: =D12/D5 -> 0.33899795 | E14: =E12/E5 -> 0.25014256 | F14: =F12/F5 -> 0.18099995 | G14: =G12/G5 -> 0.16163419 | H14: =H12/H5 -> 0.16335636
A16: 总股本（百万股） | B16: 8074.5385
A17: 参考股价（元） | B17: 20.15
A18: 总市值（百万元） | B18: =B16*B17 -> 162701.95
A20: 每股指标与估值 | B20: 2024A | C20: 2025A | D20: 2026E | E20: 2027E | F20: 2028E | G20: 2029E | H20: 2030E
A21: 每股收益（元） | B21: 0.63 | C21: 0.74 | D21: =D12/$B$16 -> 1.6561719 | E21: =E12/$B$16 -> 1.0998626 | F21: =F12/$B$16 -> 0.73217874 | G21: =G12/$B$16 -> 0.66691742 | H21: =H12/$B$16 -> 0.69424397
A22: P/E（倍，按参考股价） | B22: =$B$17/B21 -> 31.984127 | C22: =$B$17/C21 -> 27.22973 | D22: =$B$17/D21 -> 12.166612 | E22: =$B$17/E21 -> 18.32047 | F22: =$B$17/F21 -> 27.520602 | G22: =$B$17/G21 -> 30.213636 | H22: =$B$17/H21 -> 29.024379
A23: 注：实际年度 EPS 为报表基本每股收益（加权平均股本）；预测期归母净利润 = 三表模型净利润 × 0.9903（2025 年归母净利润/净利润，假设少数股东损益占比不变）；预测期 EPS 按 2025 年末总股本摊薄，未考虑回购注销对股本的影响

Sheet DCF
A1: 招商轮船 DCF 估值（FCFF，情景随“三表-假设”B5 开关，默认基准）
A2: 单位：百万元（每股为元）；蓝色为输入（财报抽取值、三表模型输出、估值假设），黑色为公式，绿色为跨表引用；预测期经营数据引用三表联动页
A4: 项目（百万元） | B4: FY2025A | C4: FY2026E | D4: FY2027E | E4: FY2028E | F4: FY2029E | G4: FY2030E | I4: 来源及计算口径
A5: 营业收入 | B5: 28177.211 | C5: ='三表-利润表'!D5 -> 39448.096 | D5: ='三表-利润表'!E5 -> 35503.286 | E5: ='三表-利润表'!F5 -> 32663.023 | F5: ='三表-利润表'!G5 -> 33316.284 | G5: ='三表-利润表'!H5 -> 34315.772 | I5: 历史期取合并报表真值表；预测期引用三表-利润表。
A6: 收入增速 | C6: =C5/B5-1 -> 0.4 | D6: =D5/C5-1 -> -0.1 | E6: =E5/D5-1 -> -0.08 | F6: =F5/E5-1 -> 0.02 | G6: =G5/F5-1 -> 0.03
A7: EBIT（剔除投资收益与公允价值变动） | B7: 7079.5029 | C7: ='三表-利润表'!D11 -> 16544.625 | D7: ='三表-利润表'!E11 -> 11408.236 | E7: ='三表-利润表'!F11 -> 8013.4199 | F7: ='三表-利润表'!G11 -> 7410.8637 | G7: ='三表-利润表'!H11 -> 7663.1691 | I7: 经营 EBIT = 利润总额 + 财务费用 − 投资收益 − 公允价值变动收益；预测期引用三表-利润表。
A8: EBIT 利润率 | B8: =B7/B5 -> 0.25124924 | C8: =C7/C5 -> 0.41940237 | D8: =D7/D5 -> 0.32132901 | E8: =E7/E5 -> 0.24533614 | F8: =F7/F5 -> 0.22243969 | G8: =G7/G5 -> 0.22331332
A9: 减：现金税（EBIT × 税率） | B9: 827.88235 | C9: =C7*'三表-假设'!D16 -> 1934.7408 | D9: =D7*'三表-假设'!E16 -> 1334.0876 | E9: =E7*'三表-假设'!F16 -> 937.0953 | F9: =F7*'三表-假设'!G16 -> 866.63193 | G9: =G7*'三表-假设'!H16 -> 896.13671 | I9: 现金税 = 经营 EBIT × 所得税率；税率引用三表-假设。
A10: NOPAT | B10: =B7-B9 -> 6251.6205 | C10: =C7-C9 -> 14609.884 | D10: =D7-D9 -> 10074.148 | E10: =E7-E9 -> 7076.3246 | F10: =F7-F9 -> 6544.2318 | G10: =G7-G9 -> 6767.0323 | I10: NOPAT = 经营 EBIT − 现金税。
A11: 加：折旧摊销 | B11: 2396.4622 | C11: ='三表-利润表'!D10 -> 2784.9419 | D11: ='三表-利润表'!E10 -> 3148.1115 | E11: ='三表-利润表'!F10 -> 3418.6382 | F11: ='三表-利润表'!G10 -> 3583.5099 | G11: ='三表-利润表'!H10 -> 3661.0357 | I11: 预测期引用三表-现金流量表。
A12: 减：资本开支 | B12: 7796.8791 | C12: ='三表-假设'!D50 -> 11045.467 | D12: ='三表-假设'!E50 -> 9940.9201 | E12: ='三表-假设'!F50 -> 7839.1256 | F12: ='三表-假设'!G50 -> 5996.931 | G12: ='三表-假设'!H50 -> 4461.0504 | I12: 预测期引用三表-现金流量表。
A13: 减：营运资本增加 | B13: 154.24661 | C13: ='三表-假设'!D47 -> 519.33957 | D13: ='三表-假设'!E47 -> -209.93936 | E13: ='三表-假设'!F47 -> -143.24058 | F13: ='三表-假设'!G47 -> 3.6498424 | G13: ='三表-假设'!H47 -> 30.90748 | I13: 经营营运资本 = 应收账款 + 存货 − 应付账款；预测期引用三表-假设的辅助计算。
A14: 无杠杆自由现金流（FCFF） | B14: =B10+B11-B12-B13 -> 696.95703 | C14: =C10+C11-C12-C13 -> 5830.0197 | D14: =D10+D11-D12-D13 -> 3491.2789 | E14: =E10+E11-E12-E13 -> 2799.0778 | F14: =F10+F11-F12-F13 -> 4127.1608 | G14: =G10+G11-G12-G13 -> 5936.1102 | I14: FCFF = NOPAT + 折旧摊销 − 资本开支 − 营运资本增加。
A16: 折现期（年，年中折现） | C16: 0.5 | D16: 1.5 | E16: 2.5 | F16: 3.5 | G16: 4.5
A17: 折现系数 | C17: =1/(1+$B$21)^C16 -> 0.9606507 | D17: =1/(1+$B$21)^D16 -> 0.88653626 | E17: =1/(1+$B$21)^E16 -> 0.81813978 | F17: =1/(1+$B$21)^F16 -> 0.7550201 | G17: =1/(1+$B$21)^G16 -> 0.69677012 | I17: 年中折现：1 / (1 + WACC) ^ 折现期。
A18: FCFF 现值 | C18: =C14*C17 -> 5600.6125 | D18: =D14*D17 -> 3095.1454 | E18: =E14*E17 -> 2290.0369 | F18: =F14*F17 -> 3116.0893 | G18: =G14*G17 -> 4136.1042
A20: 估值与股权桥 | B20: 百万元 | D20: 来源及计算口径
A21: WACC（基准 + 情景调整） | B21: =WACC!$B$20+'三表-假设'!$D$41 -> 0.0836
A22: 永续增长率 | B22: ='三表-假设'!$D$37 -> 0.015
A23: 预测期 FCFF 现值合计 | B23: =SUM(C18:G18) -> 18237.988
A24: 终值（永续增长法） | B24: =G14*(1+B22)/(B21-B22) -> 87830.202 | D24: Gordon 增长模型：末年 FCFF × (1 + g) / (WACC − g)。
A25: 终值现值 | B25: =B24/(1+B21)^COUNT(C16:G16) -> 58789.383
A26: 企业价值（EV） | B26: =B23+B25 -> 77027.371 | D26: 企业价值 = 预测期 FCFF 现值合计 + 终值现值。
A27: 终值占 EV | B27: =B25/B26 -> 0.76322717
A28: 加：货币资金 | B28: 4720.9147
A29: 加：非经营性资产 | B29: ='非经营性资产'!$B$8 -> 7999.1416
A30: 加：联营投资 | B30: 0
A31: 减：有息负债 | B31: 27271.213
A32: 减：租赁负债 | B32: 1126.7165
A33: 减：少数股东权益 | B33: 749.17164
A34: 减：养老金、优先股、期权及其他类债务 | B34: 0
A35: 股权价值 | B35: =B26+B28+B29+B30-B31-B32-B33-B34 -> 60600.327 | D35: 股权价值 = 企业价值 + 货币资金 + 非经营性资产 + 联营投资 − 有息负债 − 租赁负债 − 少数股东权益等。
A36: 摊薄股本（百万股） | B36: 8074.5385
A37: 每股价值（元） | B37: =B35/B36 -> 7.5051133 | D37: 每股价值 = 股权价值（百万元）/ 摊薄股本（百万股）。
A38: 参考股价（元） | B38: 20.15
A39: 较现价空间 | B39: =B37/B38-1 -> -0.6275378

Sheet WACC
A1: WACC 测算（基准情景）
A2: 蓝色为估值假设文件输入，黑色为公式；各情景在基准 WACC 上加情景调整
A4: 项目 | B4: 数值 | C4: 说明
A5: 无风险利率 | B5: 0.018 | C5: 10 年期国债收益率
A6: β | B6: 1.2 | C6: 可比公司均值
A7: 股权风险溢价 | B7: 0.065
A8: 规模溢价 | B8: 0
A9: 公司特定风险溢价 | B9: 0
A10: 国别风险溢价 | B10: 0
A11: 股权成本 Ke | B11: =B5+B6*B7+B8+B9+B10 -> 0.096 | C11: Rf + β × ERP + 各项溢价
A12: 税前债务成本 | B12: 0.04
A13: 边际税率 | B13: 0.15
A14: 税后债务成本 Kd | B14: =B12*(1-B13) -> 0.034 | C14: 税前债务成本 × (1 − 税率)
A15: 目标债务占比 | B15: 0.2
A16: 目标股权占比 | B16: 0.8
A17: 优先股占比 | B17: 0
A18: 优先股成本 | B18: 0
A19: 情景调整（基准） | B19: 0
A20: WACC | B20: =B16*B11+B15*B14+B17*B18+B19 -> 0.0836 | C20: E% × Ke + D% × Kd + P% × Kp + 情景调整

Sheet 敏感性
A1: DCF 敏感性分析（基准情景，每股价值，元）
A2: 黄色为基准情景；WACC、永续增长率与退出倍数为绝对值，收入增速与利润率为相对基准的变动
A4: WACC × 永续增长率
A5: WACC ↓ ／ 永续增长率 → | B5: 0.005 | C5: 0.01 | D5: 0.015 | E5: 0.02 | F5: 0.025
A6: 0.0736 | B6: 7.8252313 | C6: 8.4593974 | D6: 9.2017829 | E6: 10.082673 | F6: 11.144817
A7: 0.0786 | B7: 7.1254681 | C7: 7.6633794 | D7: 8.285868 | E7: 9.0145832 | F7: 9.8792528
A8: 0.0836 | B8: 6.5161923 | C8: 6.9770618 | D8: 7.5051133 | E8: 8.1161919 | F8: 8.8315501
A9: 0.0886 | B9: 5.9811215 | C9: 6.3794599 | D9: 6.8319203 | E9: 7.350337 | F9: 7.9502658
A10: 0.0936 | B10: 5.5076504 | C10: 5.8546111 | D10: 6.2457143 | E10: 6.6899566 | F10: 7.1989572
A12: WACC × 退出 EV/EBITDA 倍数
A13: WACC ↓ ／ 退出 EV/EBITDA → | B13: 4 | C13: 5 | D13: 6 | E13: 7 | F13: 8
A14: 0.0736 | B14: 4.2071938 | C14: 5.1904744 | D14: 6.1737551 | E14: 7.1570357 | F14: 8.1403164
A15: 0.0786 | B15: 4.0917223 | C15: 5.0524226 | D15: 6.0131229 | E15: 6.9738232 | F15: 7.9345235
A16: 0.0836 | B16: 3.9792357 | C16: 4.9179751 | D16: 5.8567144 | E16: 6.7954538 | F16: 7.7341931
A17: 0.0886 | B17: 3.8696416 | C17: 4.7870197 | D17: 5.7043978 | E17: 6.6217759 | F17: 7.5391539
A18: 0.0936 | B18: 3.7628512 | C18: 4.6594486 | D18: 5.5560461 | E18: 6.4526435 | F18: 7.349241
A20: 收入增速 × EBIT 利润率
A21: 收入增速变动 ↓ ／ EBIT 利润率变动 → | B21: -0.03 | C21: -0.015 | D21: 0 | E21: 0.015 | F21: 0.03
A22: -0.02 | B22: 5.2771596 | C22: 6.0085721 | D22: 6.7399847 | E22: 7.4713972 | F22: 8.2028098
A23: -0.01 | B23: 5.5897722 | C23: 6.3527124 | D23: 7.1156527 | E23: 7.8785929 | F23: 8.6415332
A24: 0 | B24: 5.9138391 | C24: 6.7094762 | D24: 7.5051133 | E24: 8.3007505 | F24: 9.0963876
A25: 0.01 | B25: 6.2496769 | C25: 7.0792134 | D25: 7.9087498 | E25: 8.7382863 | F25: 9.5678228
A26: 0.02 | B26: 6.5976081 | C26: 7.4622802 | D26: 8.3269523 | E26: 9.1916244 | F26: 10.056296

Sheet 非经营性资产
A1: 股权桥：非经营性资产明细
A2: 单位：百万元；逐项核对年报原文（valuation/non_operating_assets.json）；负数为类负债项
A4: 项目 | B4: 百万元 | C4: 来源页 | D4: 原文数（元）
A5: 长期股权投资 | B5: 8674.3754 | C5: p.98 | D5: 8,674,375,446.43
A6: 其他权益工具投资 | B6: 2.1313241 | C6: p.98 | D6: 2,131,324.12
A7: 减：长期应付款（主要为租赁公司借款） | B7: -677.3652 | C7: p.99 | D7: 677,365,204.37
A8: 合计 | B8: =SUM(B5:B7) -> 7999.1416

Sheet 三表-假设
A1: 三表联动模型：驱动假设与辅助计算
A2: 单位：百万元；蓝色为输入（报表值、驱动假设），黑色为公式，绿色为跨表引用；改 B5 情景开关（1 悲观 / 2 基准 / 3 乐观）即联动三表与 DCF
A4: 驱动假设 | B4: FY2024A | C4: FY2025A | D4: FY2026E | E4: FY2027E | F4: FY2028E | G4: FY2029E | H4: FY2030E | J4: 来源及计算口径
A5: 情景开关（1 悲观 / 2 基准 / 3 乐观） | B5: 2 | C5: =CHOOSE(B5,"悲观","基准","乐观") -> 基准
A6: 收入与利润率
A7: 收入增速：悲观 | D7: 0.25 | E7: -0.18 | F7: -0.1 | G7: 0 | H7: 0.02
A8: 收入增速：基准 | D8: 0.4 | E8: -0.1 | F8: -0.08 | G8: 0.02 | H8: 0.03
A9: 收入增速：乐观 | D9: 0.48 | E9: 0 | F9: -0.06 | G9: 0 | H9: 0.03
A10: 收入增速（选用） | C10: ='三表-利润表'!C5/'三表-利润表'!B5-1 -> 0.092170471 | D10: =CHOOSE($B$5,D7,D8,D9) -> 0.4 | E10: =CHOOSE($B$5,E7,E8,E9) -> -0.1 | F10: =CHOOSE($B$5,F7,F8,F9) -> -0.08 | G10: =CHOOSE($B$5,G7,G8,G9) -> 0.02 | H10: =CHOOSE($B$5,H7,H8,H9) -> 0.03 | J10: 实际期由历史收入反算；预测期按情景开关选用悲观、基准或乐观假设。
A11: 毛利率：悲观 | D11: 0.4 | E11: 0.32 | F11: 0.26 | G11: 0.24 | H11: 0.24
A12: 毛利率：基准 | D12: 0.44 | E12: 0.36 | F12: 0.3 | G12: 0.28 | H12: 0.28
A13: 毛利率：乐观 | D13: 0.47 | E13: 0.39 | F13: 0.33 | G13: 0.31 | H13: 0.31
A14: 毛利率（选用） | B14: =1-'三表-利润表'!B6/'三表-利润表'!B5 -> 0.28420812 | C14: =1-'三表-利润表'!C6/'三表-利润表'!C5 -> 0.26474245 | D14: =CHOOSE($B$5,D11,D12,D13) -> 0.44 | E14: =CHOOSE($B$5,E11,E12,E13) -> 0.36 | F14: =CHOOSE($B$5,F11,F12,F13) -> 0.3 | G14: =CHOOSE($B$5,G11,G12,G13) -> 0.28 | H14: =CHOOSE($B$5,H11,H12,H13) -> 0.28 | J14: 实际期由收入与营业成本反算；预测期按情景开关选用。
A15: 经营费用率（不含折旧摊销，含税金及附加） | B15: ='三表-利润表'!B8/'三表-利润表'!B5 -> -0.049863687 | C15: ='三表-利润表'!C8/'三表-利润表'!C5 -> -0.071556449 | D15: -0.05 | E15: -0.05 | F15: -0.05 | G15: -0.05 | H15: -0.05 | J15: 经营费用率不含折旧摊销，含税金及附加；预测期按收入比例计算。
A16: 所得税率 | B16: ='三表-利润表'!B16/'三表-利润表'!B15 -> 0.1248473 | C16: ='三表-利润表'!C16/'三表-利润表'!C15 -> 0.11694075 | D16: 0.11694075 | E16: 0.11694075 | F16: 0.11694075 | G16: 0.11694075 | H16: 0.11694075 | J16: 所得税率 = 所得税费用 / 利润总额；预测期用于计算账面税与现金税。
A17: 现金分红率（占净利润） | D17: 0.43 | E17: 0.43 | F17: 0.43 | G17: 0.43 | H17: 0.43
A18: 营运资本（天）
A19: 应收账款周转天数：悲观 | D19: 17.945352 | E19: 17.945352 | F19: 17.945352 | G19: 17.945352 | H19: 17.945352
A20: 应收账款周转天数：基准 | D20: 17.945352 | E20: 17.945352 | F20: 17.945352 | G20: 17.945352 | H20: 17.945352
A21: 应收账款周转天数：乐观 | D21: 17.945352 | E21: 17.945352 | F21: 17.945352 | G21: 17.945352 | H21: 17.945352
A22: 应收账款周转天数（选用） | B22: ='三表-资产负债表'!B7/'三表-利润表'!B5*365 -> 16.243363 | C22: ='三表-资产负债表'!C7/'三表-利润表'!C5*365 -> 17.945352 | D22: =CHOOSE($B$5,D19,D20,D21) -> 17.945352 | E22: =CHOOSE($B$5,E19,E20,E21) -> 17.945352 | F22: =CHOOSE($B$5,F19,F20,F21) -> 17.945352 | G22: =CHOOSE($B$5,G19,G20,G21) -> 17.945352 | H22: =CHOOSE($B$5,H19,H20,H21) -> 17.945352 | J22: 应收账款周转天数 = 应收账款 / 营业收入 × 365。
A23: 存货周转天数（按营业成本） | B23: ='三表-资产负债表'!B8/'三表-利润表'!B6*365 -> 28.034617 | C23: ='三表-资产负债表'!C8/'三表-利润表'!C6*365 -> 23.10532 | D23: 23.10532 | E23: 23.10532 | F23: 23.10532 | G23: 23.10532 | H23: 23.10532 | J23: 存货周转天数 = 存货 / 营业成本 × 365。
A24: 应付账款周转天数（按营业成本） | B24: ='三表-资产负债表'!B13/'三表-利润表'!B6*365 -> 36.76951 | C24: ='三表-资产负债表'!C13/'三表-利润表'!C6*365 -> 32.353026 | D24: 32.353026 | E24: 32.353026 | F24: 32.353026 | G24: 32.353026 | H24: 32.353026 | J24: 应付账款周转天数 = 应付账款 / 营业成本 × 365。
A25: 资本开支、折旧与财务
A26: 资本开支 / 收入：悲观 | D26: 0.3 | E26: 0.32 | F26: 0.27 | G26: 0.2 | H26: 0.14
A27: 资本开支 / 收入：基准 | D27: 0.28 | E27: 0.28 | F27: 0.24 | G27: 0.18 | H27: 0.13
A28: 资本开支 / 收入：乐观 | D28: 0.26 | E28: 0.25 | F28: 0.22 | G28: 0.17 | H28: 0.13
A29: 资本开支 / 收入（选用） | B29: =-'三表-现金流量表'!B12/'三表-利润表'!B5 -> 0.29265296 | C29: =-'三表-现金流量表'!C12/'三表-利润表'!C5 -> 0.27670869 | D29: =CHOOSE($B$5,D26,D27,D28) -> 0.28 | E29: =CHOOSE($B$5,E26,E27,E28) -> 0.28 | F29: =CHOOSE($B$5,F26,F27,F28) -> 0.24 | G29: =CHOOSE($B$5,G26,G27,G28) -> 0.18 | H29: =CHOOSE($B$5,H26,H27,H28) -> 0.13 | J29: 资本开支率 = 资本开支 / 营业收入。
A30: 折旧率（期初 PP&E + 半年资本开支） | C30: ='三表-利润表'!C10/('三表-资产负债表'!B9-0.5*'三表-现金流量表'!C12) -> 0.047114398 | D30: 0.047114398 | E30: 0.047114398 | F30: 0.047114398 | G30: 0.047114398 | H30: 0.047114398
A31: 利率（财务费用 / 平均有息负债；财务费用为净利息收入时为负） | C31: ='三表-利润表'!C12/AVERAGE('三表-资产负债表'!B14,'三表-资产负债表'!C14) -> 0.044131108 | D31: 0.044131108 | E31: 0.044131108 | F31: 0.044131108 | G31: 0.044131108 | H31: 0.044131108
A32: 有息负债计划还款 | D32: 0 | E32: 0 | F32: 0 | G32: 0 | H32: 0
A33: 估值参数（DCF，全预测期适用）
A34: 永续增长率：悲观 | D34: 0.01
A35: 永续增长率：基准 | D35: 0.015
A36: 永续增长率：乐观 | D36: 0.02
A37: 永续增长率（选用） | D37: =CHOOSE($B$5,D34,D35,D36) -> 0.015
A38: WACC 情景调整：悲观 | D38: 0.005
A39: WACC 情景调整：基准 | D39: 0
A40: WACC 情景调整：乐观 | D40: -0.0025
A41: WACC 情景调整（选用） | D41: =CHOOSE($B$5,D38,D39,D40) -> 0
...

Sheet 三表-利润表
A1: 三表联动模型：利润表（情景见“三表-假设”B5，默认基准）
A2: 单位：百万元；蓝色为输入（报表值、驱动假设），黑色为公式，绿色为跨表引用；预测期由“三表-假设”驱动
A4: 利润表（百万元） | B4: FY2024A | C4: FY2025A | D4: FY2026E | E4: FY2027E | F4: FY2028E | G4: FY2029E | H4: FY2030E | J4: 来源及计算口径
A5: 营业收入 | B5: 25799.279 | C5: 28177.211 | D5: =C5*(1+'三表-假设'!D10) -> 39448.096 | E5: =D5*(1+'三表-假设'!E10) -> 35503.286 | F5: =E5*(1+'三表-假设'!F10) -> 32663.023 | G5: =F5*(1+'三表-假设'!G10) -> 33316.284 | H5: =G5*(1+'三表-假设'!H10) -> 34315.772 | J5: 实际期取合并利润表；预测期 = 上年收入 × (1 + 收入增速)。
A6: 营业成本 | B6: 18466.915 | C6: 20717.507 | D6: =D5*(1-'三表-假设'!D14) -> 22090.934 | E6: =E5*(1-'三表-假设'!E14) -> 22722.103 | F6: =F5*(1-'三表-假设'!F14) -> 22864.116 | G6: =G5*(1-'三表-假设'!G14) -> 23987.724 | H6: =H5*(1-'三表-假设'!H14) -> 24707.356 | J6: 营业成本 = 营业收入 × (1 − 毛利率)。
A7: 毛利 | B7: =B5-B6 -> 7332.3648 | C7: =C5-C6 -> 7459.7039 | D7: =D5-D6 -> 17357.162 | E7: =E5-E6 -> 12781.183 | F7: =F5-F6 -> 9798.9069 | G7: =G5-G6 -> 9328.5594 | H7: =H5-H6 -> 9608.4162 | J7: 毛利 = 营业收入 − 营业成本。
A8: 经营费用（不含折旧摊销） | B8: -1286.4472 | C8: -2016.2612 | D8: =D5*'三表-假设'!D15 -> -1972.4048 | E8: =E5*'三表-假设'!E15 -> -1775.1643 | F8: =F5*'三表-假设'!F15 -> -1633.1512 | G8: =G5*'三表-假设'!G15 -> -1665.8142 | H8: =H5*'三表-假设'!H15 -> -1715.7886
A9: EBITDA | B9: =B7-B8 -> 8618.812 | C9: =C7-C8 -> 9475.9651 | D9: =D7-D8 -> 19329.567 | E9: =E7-E8 -> 14556.347 | F9: =F7-F8 -> 11432.058 | G9: =G7-G8 -> 10994.374 | H9: =H7-H8 -> 11324.205
A10: 折旧摊销 | B10: 2280.9718 | C10: 2396.4622 | D10: ='三表-假设'!D51 -> 2784.9419 | E10: ='三表-假设'!E51 -> 3148.1115 | F10: ='三表-假设'!F51 -> 3418.6382 | G10: ='三表-假设'!G51 -> 3583.5099 | H10: ='三表-假设'!H51 -> 3661.0357
A11: EBIT（经营性） | B11: =B9-B10 -> 6337.8402 | C11: =C9-C10 -> 7079.5029 | D11: =D9-D10 -> 16544.625 | E11: =E9-E10 -> 11408.236 | F11: =F9-F10 -> 8013.4199 | G11: =G9-G10 -> 7410.8637 | H11: =H9-H10 -> 7663.1691 | J11: 经营 EBIT = 毛利 − 经营费用 − 折旧摊销；不含投资收益与公允价值变动收益。
A12: 利息费用（财务费用） | B12: 1056.5391 | C12: 1159.7116 | D12: ='三表-假设'!D57 -> 1253.2321 | E12: ='三表-假设'!E57 -> 1253.2321 | F12: ='三表-假设'!F57 -> 1253.2321 | G12: ='三表-假设'!G57 -> 1253.2321 | H12: ='三表-假设'!H57 -> 1253.2321
A13: 经营性税前利润 | B13: =B11-B12 -> 5281.3011 | C13: =C11-C12 -> 5919.7913 | D13: =D11-D12 -> 15291.393 | E13: =E11-E12 -> 10155.004 | F13: =F11-F12 -> 6760.1878 | G13: =G11-G12 -> 6157.6316 | H13: =H11-H12 -> 6409.937
A14: 加：投资收益与公允价值变动 | B14: 671.03594 | C14: 954.84711 | D14: 0 | E14: 0 | F14: 0 | G14: 0 | H14: 0
A15: 利润总额 | B15: =B13+B14 -> 5952.3371 | C15: =C13+C14 -> 6874.6384 | D15: =D13+D14 -> 15291.393 | E15: =E13+E14 -> 10155.004 | F15: =F13+F14 -> 6760.1878 | G15: =G13+G14 -> 6157.6316 | H15: =H13+H14 -> 6409.937 | J15: 利润总额 = 经营 EBIT − 利息费用 + 投资收益及公允价值变动收益。
A16: 减：所得税 | B16: 743.13322 | C16: 803.92535 | D16: =MAX(D15,0)*'三表-假设'!D16 -> 1788.1869 | E16: =MAX(E15,0)*'三表-假设'!E16 -> 1187.5337 | F16: =MAX(F15,0)*'三表-假设'!F16 -> 790.5414 | G16: =MAX(G15,0)*'三表-假设'!G16 -> 720.07804 | H16: =MAX(H15,0)*'三表-假设'!H16 -> 749.58281
A17: 净利润 | B17: =B15-B16 -> 5209.2038 | C17: =C15-C16 -> 6070.7131 | D17: =D15-D16 -> 13503.206 | E17: =E15-E16 -> 8967.4699 | F17: =F15-F16 -> 5969.6464 | G17: =G15-G16 -> 5437.5536 | H17: =H15-H16 -> 5660.3542 | J17: 净利润 = 利润总额 − 所得税费用。
A19: 主要比率
A20: 营业收入增长率 | C20: =C5/B5-1 -> 0.092170471 | D20: =D5/C5-1 -> 0.4 | E20: =E5/D5-1 -> -0.1 | F20: =F5/E5-1 -> -0.08 | G20: =G5/F5-1 -> 0.02 | H20: =H5/G5-1 -> 0.03
A21: 毛利率 | B21: =B7/B5 -> 0.28420812 | C21: =C7/C5 -> 0.26474245 | D21: =D7/D5 -> 0.44 | E21: =E7/E5 -> 0.36 | F21: =F7/F5 -> 0.3 | G21: =G7/G5 -> 0.28 | H21: =H7/H5 -> 0.28
A22: EBIT 利润率 | B22: =B11/B5 -> 0.24565958 | C22: =C11/C5 -> 0.25124924 | D22: =D11/D5 -> 0.41940237 | E22: =E11/E5 -> 0.32132901 | F22: =F11/F5 -> 0.24533614 | G22: =G11/G5 -> 0.22243969 | H22: =H11/H5 -> 0.22331332
A23: 净利率 | B23: =B17/B5 -> 0.20191277 | C23: =C17/C5 -> 0.21544762 | D23: =D17/D5 -> 0.34230311 | E23: =E17/E5 -> 0.25258141 | F23: =F17/F5 -> 0.18276466 | G23: =G17/G5 -> 0.16321009 | H23: =H17/H5 -> 0.16494905
A24: 有效税率 | B24: =B16/B15 -> 0.1248473 | C24: =C16/C15 -> 0.11694075 | D24: =D16/D15 -> 0.11694075 | E24: =E16/E15 -> 0.11694075 | F24: =F16/F15 -> 0.11694075 | G24: =G16/G15 -> 0.11694075 | H24: =H16/H15 -> 0.11694075

Sheet 三表-资产负债表
A1: 三表联动模型：资产负债表（情景见“三表-假设”B5，默认基准）
A2: 单位：百万元；蓝色为输入（报表值、驱动假设），黑色为公式，绿色为跨表引用；权益（含少数股东）合并列示，留存收益为预测期累计
A4: 资产负债表（百万元） | B4: FY2024A | C4: FY2025A | D4: FY2026E | E4: FY2027E | F4: FY2028E | G4: FY2029E | H4: FY2030E | J4: 来源及计算口径
A5: 资产
A6: 货币资金 | B6: 4589.2268 | C6: 4720.9147 | D6: ='三表-现金流量表'!D21 -> 3637.8776 | E6: ='三表-现金流量表'!E21 -> 2166.4663 | F6: ='三表-现金流量表'!F21 -> 1291.918 | G6: ='三表-现金流量表'!G21 -> 1974.2526 | H6: ='三表-现金流量表'!H21 -> 4369.7323 | J6: 预测期货币资金引用现金流量表期末现金。
A7: 应收账款 | B7: 1148.1289 | C7: 1385.3424 | D7: ='三表-假设'!D43 -> 1939.4793 | E7: ='三表-假设'!E43 -> 1745.5314 | F7: ='三表-假设'!F43 -> 1605.8889 | G7: ='三表-假设'!G43 -> 1638.0066 | H7: ='三表-假设'!H43 -> 1687.1468 | J7: 应收账款 = 营业收入 × 应收账款周转天数 / 365。
A8: 存货 | B8: 1418.3914 | C8: 1311.4648 | D8: ='三表-假设'!D44 -> 1398.4057 | E8: ='三表-假设'!E44 -> 1438.3602 | F8: ='三表-假设'!F44 -> 1447.3499 | G8: ='三表-假设'!G44 -> 1518.4769 | H8: ='三表-假设'!H44 -> 1564.0312 | J8: 存货 = 营业成本 × 存货周转天数 / 365。
A9: 固定资产 + 在建工程 | B9: 46966.312 | C9: 53587.475 | D9: ='三表-假设'!D52 -> 61848 | E9: ='三表-假设'!E52 -> 68640.809 | F9: ='三表-假设'!F52 -> 73061.296 | G9: ='三表-假设'!G52 -> 75474.717 | H9: ='三表-假设'!H52 -> 76274.732 | J9: 固定资产及在建工程引用固定资产滚动辅助计算。
A10: 其他资产（含财务公司类现金资产） | B10: 16497.249 | C10: 21049.683 | D10: =C10 -> 21049.683 | E10: =D10 -> 21049.683 | F10: =E10 -> 21049.683 | G10: =F10 -> 21049.683 | H10: =G10 -> 21049.683
A11: 资产总计 | B11: =SUM(B6:B10) -> 70619.308 | C11: =SUM(C6:C10) -> 82054.88 | D11: =SUM(D6:D10) -> 89873.446 | E11: =SUM(E6:E10) -> 95040.85 | F11: =SUM(F6:F10) -> 98456.136 | G11: =SUM(G6:G10) -> 101655.14 | H11: =SUM(H6:H10) -> 104945.33 | J11: 资产总计 = 各项资产合计。
A12: 负债
A13: 应付账款 | B13: 1860.3271 | C13: 1836.3673 | D13: ='三表-假设'!D45 -> 1958.1056 | E13: ='三表-假设'!E45 -> 2014.0515 | F13: ='三表-假设'!F45 -> 2026.6393 | G13: ='三表-假设'!G45 -> 2126.2342 | H13: ='三表-假设'!H45 -> 2190.0212 | J13: 应付账款 = 营业成本 × 应付账款周转天数 / 365。
A14: 有息负债（含租赁负债） | B14: 24159.626 | C14: 28397.929 | D14: ='三表-假设'!D56 -> 28397.929 | E14: ='三表-假设'!E56 -> 28397.929 | F14: ='三表-假设'!F56 -> 28397.929 | G14: ='三表-假设'!G56 -> 28397.929 | H14: ='三表-假设'!H56 -> 28397.929
A15: 其他负债 | B15: 3750.1692 | C15: 8065.7902 | D15: =C15 -> 8065.7902 | E15: =D15 -> 8065.7902 | F15: =E15 -> 8065.7902 | G15: =F15 -> 8065.7902 | H15: =G15 -> 8065.7902
A16: 负债合计 | B16: =SUM(B13:B15) -> 29770.122 | C16: =SUM(C13:C15) -> 38300.087 | D16: =SUM(D13:D15) -> 38421.825 | E16: =SUM(E13:E15) -> 38477.771 | F16: =SUM(F13:F15) -> 38490.359 | G16: =SUM(G13:G15) -> 38589.954 | H16: =SUM(H13:H15) -> 38653.741
A17: 所有者权益
A18: 股本、资本公积及其他权益 | B18: 40849.186 | C18: 43754.793 | D18: =C18 -> 43754.793 | E18: =D18 -> 43754.793 | F18: =E18 -> 43754.793 | G18: =F18 -> 43754.793 | H18: =G18 -> 43754.793
A19: 留存收益（预测期累计） | B19: 0 | C19: 0 | D19: =C19+'三表-利润表'!D17-'三表-假设'!D59 -> 7696.8274 | E19: =D19+'三表-利润表'!E17-'三表-假设'!E59 -> 12808.285 | F19: =E19+'三表-利润表'!F17-'三表-假设'!F59 -> 16210.984 | G19: =F19+'三表-利润表'!G17-'三表-假设'!G59 -> 19310.389 | H19: =G19+'三表-利润表'!H17-'三表-假设'!H59 -> 22536.791
A20: 所有者权益合计 | B20: =B18+B19 -> 40849.186 | C20: =C18+C19 -> 43754.793 | D20: =D18+D19 -> 51451.621 | E20: =E18+E19 -> 56563.079 | F20: =F18+F19 -> 59965.777 | G20: =G18+G19 -> 63065.183 | H20: =H18+H19 -> 66291.585
A21: 负债和所有者权益总计 | B21: =B16+B20 -> 70619.308 | C21: =C16+C20 -> 82054.88 | D21: =D16+D20 -> 89873.446 | E21: =E16+E20 -> 95040.85 | F21: =F16+F20 -> 98456.136 | G21: =G16+G20 -> 101655.14 | H21: =H16+H20 -> 104945.33 | J21: 负债和权益总计 = 各项负债与权益合计。
A23: 勾稽检查（应全部为 0，显示为“-”）
A24: 资产总计 − 负债和所有者权益总计 | B24: =ROUND(B11-B21,6) -> 0 | C24: =ROUND(C11-C21,6) -> 0 | D24: =ROUND(D11-D21,6) -> 0 | E24: =ROUND(E11-E21,6) -> 0 | F24: =ROUND(F11-F21,6) -> 0 | G24: =ROUND(G11-G21,6) -> 0 | H24: =ROUND(H11-H21,6) -> 0 | J24: 模型检查 = 资产总计 − 负债和权益总计；容差内应为 0.00。
A25: 现金流量表期末现金 − 货币资金 | D25: =ROUND('三表-现金流量表'!D21-D6,6) -> 0 | E25: =ROUND('三表-现金流量表'!E21-E6,6) -> 0 | F25: =ROUND('三表-现金流量表'!F21-F6,6) -> 0 | G25: =ROUND('三表-现金流量表'!G21-G6,6) -> 0 | H25: =ROUND('三表-现金流量表'!H21-H6,6) -> 0
A26: 留存收益滚动（期初 + 净利润 − 分红 − 期末） | D26: =ROUND(C19+'三表-利润表'!D17-'三表-假设'!D59-D19,6) -> 0 | E26: =ROUND(D19+'三表-利润表'!E17-'三表-假设'!E59-E19,6) -> 0 | F26: =ROUND(E19+'三表-利润表'!F17-'三表-假设'!F59-F19,6) -> 0 | G26: =ROUND(F19+'三表-利润表'!G17-'三表-假设'!G59-G19,6) -> 0 | H26: =ROUND(G19+'三表-利润表'!H17-'三表-假设'!H59-H19,6) -> 0
A27: PP&E 滚动（期初 + 资本开支 − 折旧 − 期末） | D27: =ROUND('三表-假设'!D49+'三表-假设'!D50-'三表-假设'!D51-'三表-假设'!D52,6) -> 0 | E27: =ROUND('三表-假设'!E49+'三表-假设'!E50-'三表-假设'!E51-'三表-假设'!E52,6) -> 0 | F27: =ROUND('三表-假设'!F49+'三表-假设'!F50-'三表-假设'!F51-'三表-假设'!F52,6) -> 0 | G27: =ROUND('三表-假设'!G49+'三表-假设'!G50-'三表-假设'!G51-'三表-假设'!G52,6) -> 0 | H27: =ROUND('三表-假设'!H49+'三表-假设'!H50-'三表-假设'!H51-'三表-假设'!H52,6) -> 0
A28: 有息负债滚动（期初 − 偿还 − 期末） | D28: =ROUND('三表-假设'!D54-'三表-假设'!D55-'三表-假设'!D56,6) -> 0 | E28: =ROUND('三表-假设'!E54-'三表-假设'!E55-'三表-假设'!E56,6) -> 0 | F28: =ROUND('三表-假设'!F54-'三表-假设'!F55-'三表-假设'!F56,6) -> 0 | G28: =ROUND('三表-假设'!G54-'三表-假设'!G55-'三表-假设'!G56,6) -> 0 | H28: =ROUND('三表-假设'!H54-'三表-假设'!H55-'三表-假设'!H56,6) -> 0
A29: 勾稽结论 | B29: =IF(SUM(ABS(B24),ABS(C24),ABS(D24),ABS(E24),ABS(F24),ABS(G24),ABS(H24),ABS(B25),ABS(C25),ABS(D25),ABS(E25),ABS(F25),ABS(G25),ABS(H25),ABS(B26),ABS(C26),ABS(D26),ABS(E26),ABS(F26),ABS(G26),ABS(H26),ABS(B27),ABS(C27),ABS(D27),ABS(E27),ABS(F27),ABS(G27),ABS(H27),ABS(B28),ABS(C28),ABS(D28),ABS(E28),ABS(F28),ABS(G28),ABS(H28))<0.001,"全部平衡","不平衡，请检查") -> 全部平衡 | D29: 汇总资产负债、现金、留存收益、PP&E 与有息负债滚动检查。

Sheet 三表-现金流量表
A1: 三表联动模型：现金流量表（情景见“三表-假设”B5，默认基准）
A2: 单位：百万元；蓝色为输入（报表值、驱动假设），黑色为公式，绿色为跨表引用；实际年度经营现金流为报表值，“其他经营项目”为轧差（含财务公司存款变动）
A4: 现金流量表（百万元） | B4: FY2024A | C4: FY2025A | D4: FY2026E | E4: FY2027E | F4: FY2028E | G4: FY2029E | H4: FY2030E | J4: 来源及计算口径
A5: 经营活动
A6: 净利润 | B6: ='三表-利润表'!B17 -> 5209.2038 | C6: ='三表-利润表'!C17 -> 6070.7131 | D6: ='三表-利润表'!D17 -> 13503.206 | E6: ='三表-利润表'!E17 -> 8967.4699 | F6: ='三表-利润表'!F17 -> 5969.6464 | G6: ='三表-利润表'!G17 -> 5437.5536 | H6: ='三表-利润表'!H17 -> 5660.3542
A7: 加：折旧摊销 | B7: ='三表-利润表'!B10 -> 2280.9718 | C7: ='三表-利润表'!C10 -> 2396.4622 | D7: ='三表-利润表'!D10 -> 2784.9419 | E7: ='三表-利润表'!E10 -> 3148.1115 | F7: ='三表-利润表'!F10 -> 3418.6382 | G7: ='三表-利润表'!G10 -> 3583.5099 | H7: ='三表-利润表'!H10 -> 3661.0357
A8: 减：营运资本增加 | C8: =-'三表-假设'!C47 -> -154.24661 | D8: =-'三表-假设'!D47 -> -519.33957 | E8: =-'三表-假设'!E47 -> 209.93936 | F8: =-'三表-假设'!F47 -> 143.24058 | G8: =-'三表-假设'!G47 -> -3.6498424 | H8: =-'三表-假设'!H47 -> -30.90748
A9: 其他经营项目 | C9: =C10-C6-C7-C8 -> 741.99899 | D9: 0 | E9: 0 | F9: 0 | G9: 0 | H9: 0
A10: 经营活动现金流量净额 | B10: 8476.2206 | C10: 9054.9276 | D10: =SUM(D6:D9) -> 15768.808 | E10: =SUM(E6:E9) -> 12325.521 | F10: =SUM(F6:F9) -> 9531.5252 | G10: =SUM(G6:G9) -> 9017.4136 | H10: =SUM(H6:H9) -> 9290.4824 | J10: 经营活动现金流 = 净利润 + 折旧摊销 − 营运资本增加 + 其他经营项目。
A11: 投资活动
A12: 购建长期资产（资本开支） | B12: -7550.2355 | C12: -7796.8791 | D12: =-'三表-假设'!D50 -> -11045.467 | E12: =-'三表-假设'!E50 -> -9940.9201 | F12: =-'三表-假设'!F50 -> -7839.1256 | G12: =-'三表-假设'!G50 -> -5996.931 | H12: =-'三表-假设'!H50 -> -4461.0504 | J12: 资本开支为现金流出，取负号列示。
A13: 投资活动现金流量净额（模型口径） | D13: =D12 -> -11045.467 | E13: =E12 -> -9940.9201 | F13: =F12 -> -7839.1256 | G13: =G12 -> -5996.931 | H13: =H12 -> -4461.0504
A14: 筹资活动
A15: 偿还有息负债 | D15: =-'三表-假设'!D55 -> 0 | E15: =-'三表-假设'!E55 -> 0 | F15: =-'三表-假设'!F55 -> 0 | G15: =-'三表-假设'!G55 -> 0 | H15: =-'三表-假设'!H55 -> 0
A16: 现金分红 | D16: =-'三表-假设'!D59 -> -5806.3786 | E16: =-'三表-假设'!E59 -> -3856.0121 | F16: =-'三表-假设'!F59 -> -2566.9479 | G16: =-'三表-假设'!G59 -> -2338.148 | H16: =-'三表-假设'!H59 -> -2433.9523
A17: 筹资活动现金流量净额（模型口径） | D17: =D15+D16 -> -5806.3786 | E17: =E15+E16 -> -3856.0121 | F17: =F15+F16 -> -2566.9479 | G17: =G15+G16 -> -2338.148 | H17: =H15+H16 -> -2433.9523
A19: 现金净增加额 | D19: =D10+D13+D17 -> -1083.037 | E19: =E10+E13+E17 -> -1471.4113 | F19: =F10+F13+F17 -> -874.5483 | G19: =G10+G13+G17 -> 682.33454 | H19: =H10+H13+H17 -> 2395.4798
A20: 期初现金 | D20: ='三表-资产负债表'!C6 -> 4720.9147 | E20: =D21 -> 3637.8776 | F20: =E21 -> 2166.4663 | G20: =F21 -> 1291.918 | H20: =G21 -> 1974.2526
A21: 期末现金 | D21: =D20+D19 -> 3637.8776 | E21: =E20+E19 -> 2166.4663 | F21: =F20+F19 -> 1291.918 | G21: =G20+G19 -> 1974.2526 | H21: =H20+H19 -> 4369.7323 | J21: 期末现金 = 期初现金 + 经营、投资与筹资活动现金流。

Sheet 历史财务
A1: 历史财务数据（2024A / 2025A，合并报表）
A2: 金额单位：百万元（每股为元）；蓝色为年报抽取值（逐字核对原文），黑色为公式；来源为年报 PDF 页码
A4: 项目 | B4: FY2024A | C4: FY2025A | D4: 同比 / 变动 | E4: 来源页 | F4: 原文科目
A5: 利润表
A6: 营业收入（百万元） | B6: 25799.279 | C6: 28177.211 | D6: =IF(B6=0,"NM",(C6-B6)/ABS(B6)) -> 0.092170471 | E6: p.9 | F6: 营业收入
A7: 营业成本（百万元） | B7: 18466.915 | C7: 20717.507 | D7: =IF(B7=0,"NM",(C7-B7)/ABS(B7)) -> 0.12187161 | E7: p.20 | F7: 营业成本
A8: 销售费用（百万元） | B8: 107.63346 | C8: 113.83516 | D8: =IF(B8=0,"NM",(C8-B8)/ABS(B8)) -> 0.05761864 | E8: p.20 | F8: 销售费用
A9: 管理费用（百万元） | B9: 819.10273 | C9: 976.12318 | D9: =IF(B9=0,"NM",(C9-B9)/ABS(B9)) -> 0.19169811 | E9: p.20 | F9: 管理费用
A10: 研发费用（百万元） | B10: 18.583964 | C10: 27.580622 | D10: =IF(B10=0,"NM",(C10-B10)/ABS(B10)) -> 0.48410867 | E10: p.20 | F10: 研发费用
A11: 财务费用（百万元） | B11: 1056.5391 | C11: 1159.7116 | D11: =IF(B11=0,"NM",(C11-B11)/ABS(B11)) -> 0.097651332 | E11: p.20 | F11: 财务费用
A12: 投资收益（百万元） | B12: 671.03594 | C12: 789.46761 | D12: =IF(B12=0,"NM",(C12-B12)/ABS(B12)) -> 0.17649079 | E12: p.103 | F12: 投资收益（损失以“－”号填 列）
A13: 公允价值变动收益（百万元） | C13: 165.3795 | E13: p.103 | F13: 公允价值变动收益（损失以 “－”号填列）
A14: 营业利润（百万元） | B14: 5955.1794 | C14: 6808.6806 | D14: =IF(B14=0,"NM",(C14-B14)/ABS(B14)) -> 0.14332082 | E14: p.103 | F14: 三、营业利润（亏损以“－”号填列）
A15: 利润总额（百万元） | B15: 5952.3371 | C15: 6874.6384 | D15: =IF(B15=0,"NM",(C15-B15)/ABS(B15)) -> 0.15494777 | E15: p.9 | F15: 利润总额
A16: 所得税费用（百万元） | B16: 743.13322 | C16: 803.92535 | D16: =IF(B16=0,"NM",(C16-B16)/ABS(B16)) -> 0.081805153 | E16: p.103 | F16: 减：所得税费用
A17: 净利润（百万元） | B17: 5209.2038 | C17: 6070.7131 | D17: =IF(B17=0,"NM",(C17-B17)/ABS(B17)) -> 0.16538213 | E17: p.103 | F17: 五、净利润（净亏损以“－”号填列）
A18: 归属于上市公司股东的净利润（百万元） | B18: 5107.4479 | C18: 6012.0963 | D18: =IF(B18=0,"NM",(C18-B18)/ABS(B18)) -> 0.17712336 | E18: p.9 | F18: 归属于上市公司股 东的净利润
A19: 归属于上市公司股东的扣除非经常性损益的净利润（百万元） | B19: 5015.0047 | C19: 5024.0111 | D19: =IF(B19=0,"NM",(C19-B19)/ABS(B19)) -> 0.0017959031 | E19: p.9 | F19: 归属于上市公司股 东的扣除非经常性 损益的净利润
A20: 非经常性损益合计（百万元） | B20: 92.443267 | C20: 988.08513 | D20: =IF(B20=0,"NM",(C20-B20)/ABS(B20)) -> 9.6885571 | E20: p.12 | F20: 非经常性损益合计
A21: 资产负债表
A22: 货币资金（百万元） | B22: 4589.2268 | C22: 4720.9147 | D22: =IF(B22=0,"NM",(C22-B22)/ABS(B22)) -> 0.028694999 | E22: p.98 | F22: 货币资金
A23: 应收账款（百万元） | B23: 1148.1289 | C23: 1385.3424 | D23: =IF(B23=0,"NM",(C23-B23)/ABS(B23)) -> 0.20660869 | E23: p.98 | F23: 应收账款
A24: 存货（百万元） | B24: 1418.3914 | C24: 1311.4648 | D24: =IF(B24=0,"NM",(C24-B24)/ABS(B24)) -> -0.075385862 | E24: p.98 | F24: 存货
A25: 固定资产（百万元） | B25: 40409.229 | C25: 42178.694 | D25: =IF(B25=0,"NM",(C25-B25)/ABS(B25)) -> 0.043788644 | E25: p.98 | F25: 固定资产
A26: 在建工程（百万元） | B26: 6557.0834 | C26: 11408.781 | D26: =IF(B26=0,"NM",(C26-B26)/ABS(B26)) -> 0.73991705 | E26: p.98 | F26: 在建工程
A27: 资产总计（百万元） | B27: 70619.308 | C27: 82054.88 | D27: =IF(B27=0,"NM",(C27-B27)/ABS(B27)) -> 0.16193265 | E27: p.10 | F27: 总资产
A28: 应付账款（百万元） | B28: 1860.3271 | C28: 1836.3673 | D28: =IF(B28=0,"NM",(C28-B28)/ABS(B28)) -> -0.01287938 | E28: p.99 | F28: 应付账款
A29: 一年内到期的非流动负债（百万元） | B29: 3336.4007 | C29: 4064.7235 | D29: =IF(B29=0,"NM",(C29-B29)/ABS(B29)) -> 0.21829596 | E29: p.99 | F29: 一年内到期的非流动负债
A30: 租赁负债（百万元） | B30: 225.59927 | C30: 1126.7165 | D30: =IF(B30=0,"NM",(C30-B30)/ABS(B30)) -> 3.9943268 | E30: p.99 | F30: 租赁负债
A31: 负债合计（百万元） | B31: 29770.122 | C31: 38300.087 | D31: =IF(B31=0,"NM",(C31-B31)/ABS(B31)) -> 0.28652769 | E31: p.99 | F31: 负债合计
A32: 归属于母公司所有者权益合计（百万元） | B32: 40043.683 | C32: 43005.622 | D32: =IF(B32=0,"NM",(C32-B32)/ABS(B32)) -> 0.073967701 | E32: p.10 | F32: 归属于上市公司股东的净资产
A33: 少数股东权益（百万元） | B33: 805.50332 | C33: 749.17164 | D33: =IF(B33=0,"NM",(C33-B33)/ABS(B33)) -> -0.069933514 | E33: p.100 | F33: 少数股东权益
A34: 所有者权益合计（百万元） | B34: 40849.186 | C34: 43754.793 | D34: =IF(B34=0,"NM",(C34-B34)/ABS(B34)) -> 0.071130119 | E34: p.100 | F34: 所有者权益（或股东权益）合计
A35: 现金流量表
A36: 经营活动产生的现金流量净额（百万元） | B36: 8476.2206 | C36: 9054.9276 | D36: =IF(B36=0,"NM",(C36-B36)/ABS(B36)) -> 0.068274182 | E36: p.9 | F36: 经营活动产生的现 金流量净额
A37: 购建固定资产、无形资产和其他长期资产支付的现金（百万元） | B37: 7550.2355 | C37: 7796.8791 | D37: =IF(B37=0,"NM",(C37-B37)/ABS(B37)) -> 0.032667007 | E37: p.108 | F37: 购建固定资产、无形资产和其他长期资产支付的现金
A38: 固定资产折旧、油气资产折耗、生产性生物资产折旧（百万元） | B38: 2263.046 | C38: 2375.0273 | D38: =IF(B38=0,"NM",(C38-B38)/ABS(B38)) -> 0.049482552 | E38: p.193 | F38: 固定资产折旧、油气资产折耗、生产 性生物资产折旧
A39: 无形资产摊销（百万元） | B39: 17.925744 | C39: 21.43486 | D39: =IF(B39=0,"NM",(C39-B39)/ABS(B39)) -> 0.19575841 | E39: p.194 | F39: 无形资产摊销
A40: 每股与比率
A41: 基本每股收益（元） | B41: 0.63 | C41: 0.74 | D41: =IF(B41=0,"NM",(C41-B41)/ABS(B41)) -> 0.17460317 | E41: p.10 | F41: 基本每股收益（元／股）
...

Sheet 分季度
A1: 2025 年分季度数据（单季，合并报表）
A2: 单位：百万元；蓝色为年报“分季度主要财务数据”列示值，黑色为公式；差异 = 四季合计 − 全年报表值
A4: 项目（百万元） | B4: Q1 | C4: Q2 | D4: Q3 | E4: Q4 | F4: 四季合计 | G4: 全年（报表） | H4: 差异
A5: 营业收入 | B5: 5595.1745 | C5: 6989.4571 | D5: 6725.3032 | E5: 8867.2764 | F5: =SUM(B5:E5) -> 28177.211 | G5: 28177.211 | H5: =ROUND(F5-G5,2) -> 0
A6: 归属于上市公司股东的净利润 | B6: 865.44084 | C6: 1259.1274 | D6: 1175.3198 | E6: 2712.2082 | F6: =SUM(B6:E6) -> 6012.0963 | G6: 6012.0963 | H6: =ROUND(F6-G6,2) -> 0
A7: 归属于上市公司股东的扣除非经常性损益的净利润 | B7: 853.1805 | C7: 1053.003 | D7: 994.71294 | E7: 2123.1147 | F7: =SUM(B7:E7) -> 5024.0111 | G7: 5024.0111 | H7: =ROUND(F7-G7,2) -> 0
A8: 非经常性损益合计 | B8: =B6-B7 -> 12.260336 | C8: =C6-C7 -> 206.12444 | D8: =D6-D7 -> 180.60681 | E8: =E6-E7 -> 589.09355 | F8: =SUM(B8:E8) -> 988.08513 | G8: 988.08513 | H8: =ROUND(F8-G8,2) -> 0
A9: 经营活动产生的现金流量净额 | B9: 1380.0714 | C9: 2146.3149 | D9: 2277.1034 | E9: 3251.4379 | F9: =SUM(B9:E9) -> 9054.9276 | G9: 9054.9276 | H9: =ROUND(F9-G9,2) -> 0

Sheet 经营数据
A1: 经营数据（分产品 / 渠道 / 地区，量价）
A2: 金额单位：百万元；蓝色为年报原文数（逐格核对，见 financials/extras.json），黑色为公式；页码为年报 PDF 页
A4: 分部经营情况（分板块收入、成本、净利润）（p.20）
A5: 项目 | B5: 营业收入（百万元） | C5: 营业收入同比 | D5: 营业成本（百万元） | E5: 营业成本同比 | F5: 净利润（百万元） | G5: 净利润同比
A6: 油轮运输 | B6: 10289 | C6: 0.1177 | D6: 6183 | E6: 0.0329 | F6: 4191 | G6: 0.5906
A7: 干散货船队 | B7: 8769 | C7: 0.1045 | D7: 7262 | E7: 0.1955 | F7: 1135 | G7: -0.2669
A8: 集装箱船队 | B8: 6149 | C8: 0.1316 | D8: 4770 | E8: 0.253 | F8: 1359 | G8: 0.0346
A9: 滚装船队 | B9: 1690 | C9: -0.0798 | D9: 1271 | E9: -0.0101 | F9: 229 | G9: -0.3191
A10: LNG船队 | B10: 55 | C10: 0.8316 | D10: 39 | E10: 1.4327 | F10: 671 | G10: 0.1108
A11: 主营业务分行业（收入、成本、毛利率）（p.21）
A12: 项目 | B12: 营业收入（百万元） | C12: 营业成本（百万元） | D12: 毛利率 | E12: 营业收入同比 | F12: 营业成本同比
A13: 油轮运输 | B13: 10289.277 | C13: 6183.1851 | D13: 0.3991 | E13: 0.1177 | F13: 0.0329
A14: 散货船运输 | B14: 8769.3884 | C14: 7301.3443 | D14: 0.1674 | E14: 0.1044 | F14: 0.202
A15: 集装箱运输 | B15: 6149.2152 | C15: 4770.4837 | D15: 0.2242 | E15: 0.1315 | F15: 0.253
A16: 滚装船运输 | B16: 1690.4278 | C16: 1273.2592 | D16: 0.2468 | E16: -0.0797 | F16: -0.0083
A17: LNG运输 | B17: 54.949095 | C17: 39.085391 | D17: 0.2887 | E17: 0.8316 | F17: 1.4428
A18: 报告期末船队概况（p.15）
A19: 项目 | B19: 现有船舶艘数（艘） | C19: 现有总载重量（万吨） | D19: 平均船龄（年） | E19: 订单船舶艘数（艘） | F19: 订单总载重量（万吨）
A20: 油轮小计 | B20: 58 | C20: 1642.7 | D20: 10.08 | E20: 13 | F20: 244.85
A21: VLCC | B21: 51 | C21: 1576.01 | D21: 10.3 | E21: 5 | F21: 152.95
A22: 气体船小计 | B22: 30 | C22: 260.92 | D22: 7.1 | E22: 34 | F22: 301.66
A23: 散货船小计 | B23: 98 | C23: 1882.03 | D23: 10.61 | E23: 12 | F23: 227.2
A24: VLOC | B24: 34 | C24: 1313.13 | D24: 8.18
A25: 滚装船小计 | B25: 23 | C25: 13.53 | D25: 11.5 | E25: 4 | F25: 8.2
A26: 集装箱船小计 | B26: 19 | C26: 42.4 | D26: 11.5
A27: 自有船总计 | B27: 235 | C27: 3884.59 | E27: 64 | F27: 788.02
A28: 船队货运量（p.15）
A29: 项目 | B29: 货运量（万吨）
A30: 油轮 | B30: 8162
A31: 干散货 | B31: 11419
A32: LNG | B32: 2467
A33: 滚装 | B33: 664
A34: 汽车滚装船队运量（p.17）
A35: 项目 | B35: 运量（万辆） | C35: 同比
A36: 全年完成运量 | B36: 68.71
A37: 外贸运量 | B37: 15.67 | C37: 0.47
A38: 沿海运量 | B38: 31.33 | C38: -0.19
A39: 长江运量 | B39: 21.71 | C39: -0.25
A40: LNG 船队投资项目（p.16）
A41: 项目 | B41: 艘数（艘）
...

Sheet 模型检查
A1: 模型检查
A2: 硬性失败会使模型状态变为 blocked；警示需在报告中说明
A4: 类型 | B4: 内容
A5: 警示 | B5: 终值占企业价值 76.3%，结论高度依赖终值假设，需重点复核 WACC 与永续增长率
A6: 警示 | B6: 以下关键输入依赖分析师假设：forecast、terminal_value、wacc
A7: 提示 | B7: 基准 WACC 8.36%，永续增长率 1.50%
A8: 提示 | B8: DCF 预测与三表模型逐期核对（revenue、ebit、da、capex、nwc），最大偏差 1.82e-12 百万元
