Workbook

Sheet 估值汇总
A1: 宇树科技 估值汇总
A2: 估值基准日 2026-09-30；模型状态 screen-grade；DCF 各情景经营预测取自三表模型；不构成投资建议
A4: 情景 | B4: WACC | C4: 永续增长率 | D4: 企业价值（百万元） | E4: 股权价值（百万元） | F4: 每股价值（元） | G4: 较现价空间 | H4: 终值占 EV | I4: 隐含 EV/EBITDA | J4: 情景说明
A5: 基准 | B5: 0.1125 | C5: 0.03 | D5: 15600.05 | E5: 18158.917 | F5: 49.884682 | G5: -0.8892436 | H5: 0.67562432 | I5: 8.3779818 | J5: 科研与消费级放量、工业场景逐步切入：销量高增长，人形均价两位数下降，收入增速逐年放缓且低于行业。
A6: 悲观 | B6: 0.1225 | C6: 0.025 | D6: 4946.669 | E6: 7505.5366 | F6: 20.618592 | G6: -0.9542216 | H6: 0.55651716 | I6: 6.7869317 | J6: 科研需求见顶、工业订单旁落于全尺寸对手，价格战加剧，收入增速快速回落，毛利率再降 4 个百分点。
A7: 乐观 | B7: 0.1075 | C7: 0.035 | D7: 37139.621 | E7: 39698.489 | F7: 109.05642 | G7: -0.75786763 | H7: 0.7466226 | I7: 9.2894268 | J7: H2 等全尺寸产品切入工业、消费级放量，销量增长抵消降价，收入维持高增长，毛利率高 2 个百分点。
A9: 方法 | B9: 低 | C9: 中/基准 | D9: 高
A10: DCF 每股价值（元） | B10: 20.618592 | C10: 49.884682 | D10: 109.05642
A11: 参考股价（元） | C11: 450.4
A12: DCF 与三表模型逐期核对：最大偏差 4.55e-13 百万元（一致）

Sheet 盈利预测
A1: 盈利预测（基准情景）
A2: 单位：百万元（每股为元）；蓝色为报表值或三表模型输出，黑色为公式；预测期归母净利润 = 净利润 × 最近实际年度归母占比；EPS 按最近期末总股本摊薄
A4: 项目 | B4: 2024A | C4: 2025A | D4: 2026E | E4: 2027E | F4: 2028E | G4: 2029E | H4: 2030E | I4: 2031E | J4: 2032E | K4: 2033E
A5: 营业收入 | B5: 392.7707 | C5: 1699.2693 | D5: ='三表-利润表'!D5 -> 2344.9916 | E5: ='三表-利润表'!E5 -> 3282.9883 | F5: ='三表-利润表'!F5 -> 4432.0342 | G5: ='三表-利润表'!G5 -> 5761.6444 | H5: ='三表-利润表'!H5 -> 7202.0556 | I5: ='三表-利润表'!I5 -> 8642.4667 | J5: ='三表-利润表'!J5 -> 9938.8367 | K5: ='三表-利润表'!K5 -> 10932.72
A6: 营业收入增长率 | C6: =C5/B5-1 -> 3.3263647 | D6: =D5/C5-1 -> 0.38 | E6: =E5/D5-1 -> 0.4 | F6: =F5/E5-1 -> 0.35 | G6: =G5/F5-1 -> 0.3 | H6: =H5/G5-1 -> 0.25 | I6: =I5/H5-1 -> 0.2 | J6: =J5/I5-1 -> 0.15 | K6: =K5/J5-1 -> 0.1
A7: 营业成本 | B7: 168.0441 | C7: 672.261 | D7: ='三表-利润表'!D6 -> 1031.7963 | E7: ='三表-利润表'!E6 -> 1510.1746 | F7: ='三表-利润表'!F6 -> 2127.3764 | G7: ='三表-利润表'!G6 -> 2823.2058 | H7: ='三表-利润表'!H6 -> 3601.0278 | I7: ='三表-利润表'!I6 -> 4321.2333 | J7: ='三表-利润表'!J6 -> 4969.4183 | K7: ='三表-利润表'!K6 -> 5466.3602
A8: 毛利 | B8: =B5-B7 -> 224.7266 | C8: =C5-C7 -> 1027.0083 | D8: =D5-D7 -> 1313.1953 | E8: =E5-E7 -> 1772.8137 | F8: =F5-F7 -> 2304.6578 | G8: =G5-G7 -> 2938.4387 | H8: =H5-H7 -> 3601.0278 | I8: =I5-I7 -> 4321.2333 | ... K8: =K5-K7 -> 5466.3602
A9: 毛利率 | B9: =B8/B5 -> 0.57215724 | C9: =C8/C5 -> 0.60438231 | D9: =D8/D5 -> 0.56 | E9: =E8/E5 -> 0.54 | F9: =F8/F5 -> 0.52 | G9: =G8/G5 -> 0.51 | H9: =H8/H5 -> 0.5 | I9: =I8/I5 -> 0.5 | ... K9: =K8/K5 -> 0.5
A10: EBIT（经营性） | B10: 73.2026 | C10: 345.5213 | D10: ='三表-利润表'!D11 -> 638.91582 | E10: ='三表-利润表'!E11 -> 843.63473 | F10: ='三表-利润表'!F11 -> 1081.9168 | G10: ='三表-利润表'!G11 -> 1401.7842 | H10: ='三表-利润表'!H11 -> 1749.2301 | I10: ='三表-利润表'!I11 -> 2178.0288 | J10: ='三表-利润表'!J11 -> 2492.164 | K10: ='三表-利润表'!K11 -> 2722.9813
A11: 净利润 | B11: 95.4747 | C11: 278.2105 | D11: ='三表-利润表'!D17 -> 541.69076 | E11: ='三表-利润表'!E17 -> 715.70184 | F11: ='三表-利润表'!F17 -> 918.2416 | G11: ='三表-利润表'!G17 -> 1190.1289 | H11: ='三表-利润表'!H17 -> 1485.4579 | I11: ='三表-利润表'!I17 -> 1849.9368 | J11: ='三表-利润表'!J17 -> 2116.9517 | K11: ='三表-利润表'!K17 -> 2313.1464
A12: 归母净利润 | B12: 95.4747 | C12: 278.2105 | D12: =D11*$C$12/$C$11 -> 541.69076 | E12: =E11*$C$12/$C$11 -> 715.70184 | F12: =F11*$C$12/$C$11 -> 918.2416 | G12: =G11*$C$12/$C$11 -> 1190.1289 | H12: =H11*$C$12/$C$11 -> 1485.4579 | I12: =I11*$C$12/$C$11 -> 1849.9368 | J12: =J11*$C$12/$C$11 -> 2116.9517 | K12: =K11*$C$12/$C$11 -> 2313.1464
A13: 归母净利润增长率 | C13: =C12/B12-1 -> 1.9139709 | D13: =D12/C12-1 -> 0.9470536 | E13: =E12/D12-1 -> 0.32123694 | F13: =F12/E12-1 -> 0.28299462 | G13: =G12/F12-1 -> 0.29609561 | H13: =H12/G12-1 -> 0.24814872 | I13: =I12/H12-1 -> 0.24536467 | J13: =J12/I12-1 -> 0.14433735 | K13: =K12/J12-1 -> 0.092677923
A14: 归母净利率 | B14: =B12/B5 -> 0.24308 | C14: =C12/C5 -> 0.16372361 | D14: =D12/D5 -> 0.23099901 | E14: =E12/E5 -> 0.21800316 | F14: =F12/F5 -> 0.20718288 | G14: =G12/G5 -> 0.20656063 | H14: =H12/H5 -> 0.20625471 | I14: =I12/I5 -> 0.21405194 | ... K14: =K12/K5 -> 0.21158013
A16: 总股本（百万股） | B16: 364.0179
A17: 参考股价（元） | B17: 450.4
A18: 总市值（百万元） | B18: =B16*B17 -> 163953.66
A20: 每股指标与估值 | B20: 2024A | C20: 2025A | D20: 2026E | E20: 2027E | F20: 2028E | G20: 2029E | H20: 2030E | I20: 2031E | J20: 2032E | K20: 2033E
A21: 每股收益（元） | C21: 0.76 | D21: =D12/$B$16 -> 1.4880882 | E21: =E12/$B$16 -> 1.9661172 | F21: =F12/$B$16 -> 2.5225177 | G21: =G12/$B$16 -> 3.2694241 | H21: =H12/$B$16 -> 4.0807275 | I21: =I12/$B$16 -> 5.0819939 | J21: =J12/$B$16 -> 5.8155155 | K21: =K12/$B$16 -> 6.3544854
A22: P/E（倍，按参考股价） | B22: =$B$17/B21 | C22: =$B$17/C21 -> 592.63158 | D22: =$B$17/D21 -> 302.67022 | E22: =$B$17/E21 -> 229.08096 | F22: =$B$17/F21 -> 178.55177 | G22: =$B$17/G21 -> 137.76126 | H22: =$B$17/H21 -> 110.37248 | I22: =$B$17/I21 -> 88.626631 | ... K22: =$B$17/K21 -> 70.879068
A23: 注：实际年度 EPS 为报表基本每股收益（加权平均股本）；预测期归母净利润 = 三表模型净利润 × 1.0000（2025 年归母净利润/净利润，假设少数股东损益占比不变）；预测期 EPS 按 2025 年末总股本摊薄，未考虑回购注销对股本的影响

Sheet DCF
A1: 宇树科技 DCF 估值（FCFF，情景随“三表-假设”B5 开关，默认基准）
A2: 单位：百万元（每股为元）；蓝色为输入（财报抽取值、三表模型输出、估值假设），黑色为公式，绿色为跨表引用；预测期经营数据引用三表联动页
A4: 项目（百万元） | B4: FY2025A | C4: FY2026E | D4: FY2027E | E4: FY2028E | F4: FY2029E | G4: FY2030E | H4: FY2031E | I4: FY2032E | J4: FY2033E | L4: 来源及计算口径
A5: 营业收入 | B5: 1699.2693 | C5: ='三表-利润表'!D5 -> 2344.9916 | D5: ='三表-利润表'!E5 -> 3282.9883 | E5: ='三表-利润表'!F5 -> 4432.0342 | F5: ='三表-利润表'!G5 -> 5761.6444 | G5: ='三表-利润表'!H5 -> 7202.0556 | H5: ='三表-利润表'!I5 -> 8642.4667 | I5: ='三表-利润表'!J5 -> 9938.8367 | J5: ='三表-利润表'!K5 -> 10932.72 | L5: 历史期取合并报表真值表；预测期引用三表-利润表。
A6: 收入增速 | C6: =C5/B5-1 -> 0.38 | D6: =D5/C5-1 -> 0.4 | E6: =E5/D5-1 -> 0.35 | F6: =F5/E5-1 -> 0.3 | G6: =G5/F5-1 -> 0.25 | H6: =H5/G5-1 -> 0.2 | I6: =I5/H5-1 -> 0.15 | J6: =J5/I5-1 -> 0.1
A7: EBIT（剔除投资收益与公允价值变动） | B7: 345.5213 | C7: ='三表-利润表'!D11 -> 638.91582 | D7: ='三表-利润表'!E11 -> 843.63473 | E7: ='三表-利润表'!F11 -> 1081.9168 | F7: ='三表-利润表'!G11 -> 1401.7842 | G7: ='三表-利润表'!H11 -> 1749.2301 | H7: ='三表-利润表'!I11 -> 2178.0288 | I7: ='三表-利润表'!J11 -> 2492.164 | J7: ='三表-利润表'!K11 -> 2722.9813 | L7: 经营 EBIT = 利润总额 + 财务费用 − 投资收益 − 公允价值变动收益；预测期引用三表-利润表。
A8: EBIT 利润率 | B8: =B7/B5 -> 0.20333522 | C8: =C7/C5 -> 0.27245974 | D8: =D7/D5 -> 0.25697159 | E8: =E7/E5 -> 0.24411292 | F8: =F7/F5 -> 0.24329586 | G8: =G7/G5 -> 0.24287928 | H8: =H7/H5 -> 0.25201471 | I8: =I7/I5 -> 0.25075007 | J8: =J7/J5 -> 0.24906713
A9: 减：现金税（EBIT × 税率） | B9: 84.630255 | C9: =C7*'三表-假设'!D16 -> 95.837372 | D9: =D7*'三表-假设'!E16 -> 126.54521 | E9: =E7*'三表-假设'!F16 -> 162.28752 | F9: =F7*'三表-假设'!G16 -> 210.26763 | G9: =G7*'三表-假设'!H16 -> 262.38451 | H9: =H7*'三表-假设'!I16 -> 326.70431 | I9: =I7*'三表-假设'!J16 -> 373.8246 | J9: =J7*'三表-假设'!K16 -> 408.44719 | L9: 现金税 = 经营 EBIT × 所得税率；税率引用三表-假设。
A10: NOPAT | B10: =B7-B9 -> 260.89105 | C10: =C7-C9 -> 543.07844 | D10: =D7-D9 -> 717.08952 | E10: =E7-E9 -> 919.62929 | F10: =F7-F9 -> 1191.5166 | G10: =G7-G9 -> 1486.8456 | H10: =H7-H9 -> 1851.3244 | I10: =I7-I9 -> 2118.3394 | J10: =J7-J9 -> 2314.5341 | L10: NOPAT = 经营 EBIT − 现金税。
A11: 加：折旧摊销 | B11: 6.3726 | C11: ='三表-利润表'!D10 -> 17.681842 | D11: ='三表-利润表'!E10 -> 42.772105 | E11: ='三表-利润表'!F10 -> 70.412076 | F11: ='三表-利润表'!G10 -> 96.243326 | G11: ='三表-利润表'!H10 -> 123.30438 | H11: ='三表-利润表'!I10 -> 155.43724 | I11: ='三表-利润表'!J10 -> 191.32188 | J11: ='三表-利润表'!K10 -> 228.85319 | L11: 预测期引用三表-现金流量表。
A12: 减：资本开支 | B12: 50.3627 | C12: ='三表-假设'!D50 -> 140.6995 | D12: ='三表-假设'!E50 -> 196.9793 | E12: ='三表-假设'!F50 -> 221.60171 | F12: ='三表-假设'!G50 -> 230.46578 | G12: ='三表-假设'!H50 -> 288.08222 | H12: ='三表-假设'!I50 -> 345.69867 | I12: ='三表-假设'!J50 -> 397.55347 | J12: ='三表-假设'!K50 -> 437.30881 | L12: 预测期引用三表-现金流量表。
A13: 减：营运资本增加 | B13: 109.7731 | C13: ='三表-假设'!D47 -> 88.078453 | D13: ='三表-假设'!E47 -> 119.91724 | E13: ='三表-假设'!F47 -> 152.60303 | F13: ='三表-假设'!G47 -> 173.22519 | G13: ='三表-假设'!H47 -> 192.05152 | H13: ='三表-假设'!I47 -> 181.51337 | I13: ='三表-假设'!J47 -> 163.36203 | J13: ='三表-假设'!K47 -> 125.24422 | L13: 经营营运资本 = 应收账款 + 存货 − 应付账款；预测期引用三表-假设的辅助计算。
A14: 无杠杆自由现金流（FCFF） | B14: =B10+B11-B12-B13 -> 107.12785 | C14: =C10+C11-C12-C13 -> 331.98233 | D14: =D10+D11-D12-D13 -> 442.96509 | E14: =E10+E11-E12-E13 -> 615.83663 | F14: =F10+F11-F12-F13 -> 884.06895 | G14: =G10+G11-G12-G13 -> 1130.0162 | H14: =H10+H11-H12-H13 -> 1479.5497 | I14: =I10+I11-I12-I13 -> 1748.7458 | J14: =J10+J11-J12-J13 -> 1980.8343 | L14: FCFF = NOPAT + 折旧摊销 − 资本开支 − 营运资本增加。
A16: 折现期（年，年中折现） | C16: 0.5 | D16: 1.5 | E16: 2.5 | F16: 3.5 | G16: 4.5 | H16: 5.5 | I16: 6.5 | J16: 7.5
A17: 折现系数 | C17: =1/(1+$B$21)^C16 -> 0.94809093 | D17: =1/(1+$B$21)^D16 -> 0.85221656 | E17: =1/(1+$B$21)^E16 -> 0.76603736 | F17: =1/(1+$B$21)^F16 -> 0.68857291 | G17: =1/(1+$B$21)^G16 -> 0.61894194 | H17: =1/(1+$B$21)^H16 -> 0.55635231 | I17: =1/(1+$B$21)^I16 -> 0.50009196 | J17: =1/(1+$B$21)^J16 -> 0.44952086 | L17: 年中折现：1 / (1 + WACC) ^ 折现期。
A18: FCFF 现值 | C18: =C14*C17 -> 314.74944 | D18: =D14*D17 -> 377.50219 | E18: =E14*E17 -> 471.75387 | F18: =F14*F17 -> 608.74593 | G18: =G14*G17 -> 699.41441 | H18: =H14*H17 -> 823.15086 | I18: =I14*I17 -> 874.53371 | J18: =J14*J17 -> 890.42633
A20: 估值与股权桥 | B20: 百万元 | D20: 来源及计算口径
A21: WACC（基准 + 情景调整） | B21: =WACC!$B$20+'三表-假设'!$D$41 -> 0.1125
A22: 永续增长率 | B22: ='三表-假设'!$D$37 -> 0.03
A23: 预测期 FCFF 现值合计 | B23: =SUM(C18:J18) -> 5060.2767
A24: 终值（永续增长法） | B24: =J14*(1+B22)/(B21-B22) -> 24730.416 | D24: Gordon 增长模型：末年 FCFF × (1 + g) / (WACC − g)。
A25: 终值现值 | B25: =B24/(1+B21)^COUNT(C16:J16) -> 10539.773
A26: 企业价值（EV） | B26: =B23+B25 -> 15600.05 | D26: 企业价值 = 预测期 FCFF 现值合计 + 终值现值。
A27: 终值占 EV | B27: =B25/B26 -> 0.67562432
A28: 加：货币资金 | B28: 1419.2579
A29: 加：非经营性资产 | B29: ='非经营性资产'!$B$8 -> 1169.8569
A30: 加：联营投资 | B30: 0
A31: 减：有息负债 | B31: 16.108
A32: 减：租赁负债 | B32: 14.1392
A33: 减：少数股东权益 | B33: 0
A34: 减：养老金、优先股、期权及其他类债务 | B34: 0
A35: 股权价值 | B35: =B26+B28+B29+B30-B31-B32-B33-B34 -> 18158.917 | D35: 股权价值 = 企业价值 + 货币资金 + 非经营性资产 + 联营投资 − 有息负债 − 租赁负债 − 少数股东权益等。
A36: 摊薄股本（百万股） | B36: 364.0179
A37: 每股价值（元） | B37: =B35/B36 -> 49.884682 | D37: 每股价值 = 股权价值（百万元）/ 摊薄股本（百万股）。
A38: 参考股价（元） | B38: 450.4
A39: 较现价空间 | B39: =B37/B38-1 -> -0.8892436

Sheet WACC
A1: WACC 测算（基准情景）
A2: 蓝色为估值假设文件输入，黑色为公式；各情景在基准 WACC 上加情景调整
A4: 项目 | B4: 数值 | C4: 说明
A5: 无风险利率 | B5: 0.018 | C5: 10 年期国债收益率
A6: β | B6: 1.3 | C6: 可比公司均值
A7: 股权风险溢价 | B7: 0.065
A8: 规模溢价 | B8: 0
A9: 公司特定风险溢价 | B9: 0.01
A10: 国别风险溢价 | B10: 0
A11: 股权成本 Ke | B11: =B5+B6*B7+B8+B9+B10 -> 0.1125 | C11: Rf + β × ERP + 各项溢价
A12: 税前债务成本 | B12: 0.035
A13: 边际税率 | B13: 0.15
A14: 税后债务成本 Kd | B14: =B12*(1-B13) -> 0.02975 | C14: 税前债务成本 × (1 − 税率)
A15: 目标债务占比 | B15: 0
A16: 目标股权占比 | B16: 1
A17: 优先股占比 | B17: 0
A18: 优先股成本 | B18: 0
A19: 情景调整（基准） | B19: 0
A20: WACC | B20: =B16*B11+B15*B14+B17*B18+B19 -> 0.1125 | C20: E% × Ke + D% × Kd + P% × Kp + 情景调整

Sheet 敏感性
A1: DCF 敏感性分析（基准情景，每股价值，元）
A2: 黄色为基准情景；WACC、永续增长率与退出倍数为绝对值，收入增速与利润率为相对基准的变动
A4: WACC × 永续增长率
A5: WACC ↓ ／ 永续增长率 → | B5: 0.02 | C5: 0.025 | D5: 0.03 | E5: 0.035 | F5: 0.04
A6: 0.1025 | B6: 52.364169 | C6: 54.513432 | D6: 56.959145 | E6: 59.767186 | F6: 63.024513
A7: 0.1075 | B7: 49.258837 | C7: 51.103119 | D7: 53.185373 | E7: 55.554834 | F7: 58.275326
A8: 0.1125 | B8: 46.503804 | C8: 48.097647 | D8: 49.884682 | E8: 51.902304 | F8: 54.198217
A9: 0.1175 | B9: 44.044646 | C9: 45.430815 | D9: 46.975404 | E9: 48.707216 | F9: 50.662487
A10: 0.1225 | B10: 41.837584 | C10: 43.05003 | D10: 44.393551 | E10: 45.890618 | F10: 47.569147
A12: WACC × 退出 EV/EBITDA 倍数
A13: WACC ↓ ／ 退出 EV/EBITDA → | B13: 20 | C13: 22.5 | D13: 25 | E13: 27.5 | F13: 30
A14: 0.1025 | B14: 95.840307 | C14: 105.12741 | D14: 114.41452 | E14: 123.70163 | F14: 132.98874
A15: 0.1075 | B15: 92.887892 | C15: 101.84483 | D15: 110.80176 | E15: 119.75869 | F15: 128.71563
A16: 0.1125 | B16: 90.049949 | C16: 98.689857 | D16: 107.32977 | E16: 115.96967 | F16: 124.60958
A17: 0.1175 | B17: 87.321513 | C17: 95.656962 | D17: 103.99241 | E17: 112.32786 | F17: 120.66331
A18: 0.1225 | B18: 84.697853 | C18: 92.740861 | D18: 100.78387 | E18: 108.82688 | F18: 116.86988
A20: 收入增速 × EBIT 利润率
A21: 收入增速变动 ↓ ／ EBIT 利润率变动 → | B21: -0.05 | C21: -0.025 | D21: 0 | E21: 0.025 | F21: 0.05
A22: -0.05 | B22: 32.301011 | C22: 36.273407 | D22: 40.245802 | E22: 44.218198 | F22: 48.190593
A23: -0.025 | B23: 35.651038 | C23: 40.214374 | D23: 44.777711 | E23: 49.341048 | F23: 53.904384
A24: 0 | B24: 39.411297 | C24: 44.64799 | D24: 49.884682 | E24: 55.121375 | F24: 60.358067
A25: 0.025 | B25: 43.624618 | C25: 49.627111 | D25: 55.629604 | E25: 61.632098 | F25: 67.634591
A26: 0.05 | B26: 48.337456 | C26: 55.209239 | D26: 62.081022 | E26: 68.952805 | F26: 75.824588

Sheet 非经营性资产
A1: 股权桥：非经营性资产明细
A2: 单位：百万元；逐项核对年报原文（valuation/non_operating_assets.json）；负数为类负债项
A4: 项目 | B4: 百万元 | C4: 来源页 | D4: 原文数（元）
A5: 交易性金融资产 | B5: 282.231 | C5: p.160 | D5: 28,223.10
A6: 债权投资 | B6: 882.7901 | C6: p.160 | D6: 88,279.01
A7: 长期股权投资 | B7: 4.8358 | C7: p.160 | D7: 483.58
A8: 合计 | B8: =SUM(B5:B7) -> 1169.8569

Sheet 三表-假设
A1: 三表联动模型：驱动假设与辅助计算
A2: 单位：百万元；蓝色为输入（报表值、驱动假设），黑色为公式，绿色为跨表引用；改 B5 情景开关（1 悲观 / 2 基准 / 3 乐观）即联动三表与 DCF
A4: 驱动假设 | B4: FY2024A | C4: FY2025A | D4: FY2026E | E4: FY2027E | F4: FY2028E | G4: FY2029E | H4: FY2030E | I4: FY2031E | J4: FY2032E | K4: FY2033E | M4: 来源及计算口径
A5: 情景开关（1 悲观 / 2 基准 / 3 乐观） | B5: 2 | C5: =CHOOSE(B5,"悲观","基准","乐观") -> 基准
A6: 收入与利润率
A7: 收入增速：悲观 | D7: 0.28 | E7: 0.2 | F7: 0.15 | G7: 0.12 | H7: 0.1 | I7: 0.08 | J7: 0.06 | K7: 0.05
A8: 收入增速：基准 | D8: 0.38 | E8: 0.4 | F8: 0.35 | G8: 0.3 | H8: 0.25 | I8: 0.2 | J8: 0.15 | K8: 0.1
A9: 收入增速：乐观 | D9: 0.55 | E9: 0.6 | F9: 0.5 | G9: 0.4 | H9: 0.35 | I9: 0.3 | J9: 0.25 | K9: 0.2
A10: 收入增速（选用） | C10: ='三表-利润表'!C5/'三表-利润表'!B5-1 -> 3.3263647 | D10: =CHOOSE($B$5,D7,D8,D9) -> 0.38 | E10: =CHOOSE($B$5,E7,E8,E9) -> 0.4 | F10: =CHOOSE($B$5,F7,F8,F9) -> 0.35 | G10: =CHOOSE($B$5,G7,G8,G9) -> 0.3 | H10: =CHOOSE($B$5,H7,H8,H9) -> 0.25 | I10: =CHOOSE($B$5,I7,I8,I9) -> 0.2 | J10: =CHOOSE($B$5,J7,J8,J9) -> 0.15 | K10: =CHOOSE($B$5,K7,K8,K9) -> 0.1 | M10: 实际期由历史收入反算；预测期按情景开关选用悲观、基准或乐观假设。
A11: 毛利率：悲观 | D11: 0.52 | E11: 0.5 | F11: 0.48 | G11: 0.47 | H11: 0.46 | I11: 0.46 | J11: 0.46 | K11: 0.46
A12: 毛利率：基准 | D12: 0.56 | E12: 0.54 | F12: 0.52 | G12: 0.51 | H12: 0.5 | I12: 0.5 | J12: 0.5 | K12: 0.5
A13: 毛利率：乐观 | D13: 0.58 | E13: 0.56 | F13: 0.54 | G13: 0.53 | H13: 0.52 | I13: 0.52 | J13: 0.52 | K13: 0.52
A14: 毛利率（选用） | B14: =1-'三表-利润表'!B6/'三表-利润表'!B5 -> 0.57215724 | C14: =1-'三表-利润表'!C6/'三表-利润表'!C5 -> 0.60438231 | D14: =CHOOSE($B$5,D11,D12,D13) -> 0.56 | E14: =CHOOSE($B$5,E11,E12,E13) -> 0.54 | F14: =CHOOSE($B$5,F11,F12,F13) -> 0.52 | G14: =CHOOSE($B$5,G11,G12,G13) -> 0.51 | H14: =CHOOSE($B$5,H11,H12,H13) -> 0.5 | I14: =CHOOSE($B$5,I11,I12,I13) -> 0.5 | J14: =CHOOSE($B$5,J11,J12,J13) -> 0.5 | K14: =CHOOSE($B$5,K11,K12,K13) -> 0.5 | M14: 实际期由收入与营业成本反算；预测期按情景开关选用。
A15: 经营费用率（不含折旧摊销，含税金及附加） | B15: ='三表-利润表'!B8/'三表-利润表'!B5 -> 0.38040465 | C15: ='三表-利润表'!C8/'三表-利润表'!C5 -> 0.39729689 | D15: 0.28 | E15: 0.27 | F15: 0.26 | G15: 0.25 | H15: 0.24 | I15: 0.23 | J15: 0.23 | K15: 0.23 | M15: 经营费用率不含折旧摊销，含税金及附加；预测期按收入比例计算。
A16: 所得税率 | B16: ='三表-利润表'!B16/'三表-利润表'!B15 -> 0.051114216 | C16: ='三表-利润表'!C16/'三表-利润表'!C15 -> 0.24493499 | D16: 0.15 | E16: 0.15 | F16: 0.15 | G16: 0.15 | H16: 0.15 | I16: 0.15 | J16: 0.15 | K16: 0.15 | M16: 所得税率 = 所得税费用 / 利润总额；预测期用于计算账面税与现金税。
A17: 现金分红率（占净利润） | D17: 0 | E17: 0 | F17: 0 | G17: 0 | H17: 0 | I17: 0 | J17: 0 | K17: 0
A18: 营运资本（天）
A19: 应收账款周转天数：悲观 | D19: 12.615872 | E19: 12.615872 | F19: 12.615872 | G19: 12.615872 | H19: 12.615872 | I19: 12.615872 | J19: 12.615872 | K19: 12.615872
A20: 应收账款周转天数：基准 | D20: 12.615872 | E20: 12.615872 | F20: 12.615872 | G20: 12.615872 | H20: 12.615872 | I20: 12.615872 | J20: 12.615872 | K20: 12.615872
A21: 应收账款周转天数：乐观 | D21: 12.615872 | E21: 12.615872 | F21: 12.615872 | G21: 12.615872 | H21: 12.615872 | I21: 12.615872 | J21: 12.615872 | K21: 12.615872
A22: 应收账款周转天数（选用） | B22: ='三表-资产负债表'!B7/'三表-利润表'!B5*365 -> 19.111889 | C22: ='三表-资产负债表'!C7/'三表-利润表'!C5*365 -> 12.615872 | D22: =CHOOSE($B$5,D19,D20,D21) -> 12.615872 | E22: =CHOOSE($B$5,E19,E20,E21) -> 12.615872 | F22: =CHOOSE($B$5,F19,F20,F21) -> 12.615872 | G22: =CHOOSE($B$5,G19,G20,G21) -> 12.615872 | H22: =CHOOSE($B$5,H19,H20,H21) -> 12.615872 | I22: =CHOOSE($B$5,I19,I20,I21) -> 12.615872 | J22: =CHOOSE($B$5,J19,J20,J21) -> 12.615872 | K22: =CHOOSE($B$5,K19,K20,K21) -> 12.615872 | M22: 应收账款周转天数 = 应收账款 / 营业收入 × 365。
A23: 存货周转天数（按营业成本） | B23: ='三表-资产负债表'!B8/'三表-利润表'!B6*365 -> 306.98457 | C23: ='三表-资产负债表'!C8/'三表-利润表'!C6*365 -> 199.66946 | D23: 199.66946 | E23: 199.66946 | F23: 199.66946 | G23: 199.66946 | H23: 199.66946 | I23: 199.66946 | J23: 199.66946 | K23: 199.66946 | M23: 存货周转天数 = 存货 / 营业成本 × 365。
A24: 应付账款周转天数（按营业成本） | B24: ='三表-资产负债表'!B13/'三表-利润表'!B6*365 -> 195.44487 | C24: ='三表-资产负债表'!C13/'三表-利润表'!C6*365 -> 132.91027 | D24: 132.91027 | E24: 132.91027 | F24: 132.91027 | G24: 132.91027 | H24: 132.91027 | I24: 132.91027 | J24: 132.91027 | K24: 132.91027 | M24: 应付账款周转天数 = 应付账款 / 营业成本 × 365。
A25: 资本开支、折旧与财务
A26: 资本开支 / 收入：悲观 | D26: 0.06 | E26: 0.06 | F26: 0.05 | G26: 0.045 | H26: 0.045 | I26: 0.045 | J26: 0.045 | K26: 0.045
A27: 资本开支 / 收入：基准 | D27: 0.06 | E27: 0.06 | F27: 0.05 | G27: 0.04 | H27: 0.04 | I27: 0.04 | J27: 0.04 | K27: 0.04
A28: 资本开支 / 收入：乐观 | D28: 0.06 | E28: 0.055 | F28: 0.05 | G28: 0.04 | H28: 0.04 | I28: 0.04 | J28: 0.04 | K28: 0.04
A29: 资本开支 / 收入（选用） | B29: =-'三表-现金流量表'!B12/'三表-利润表'!B5 -> 0.024684377 | C29: =-'三表-现金流量表'!C12/'三表-利润表'!C5 -> 0.029637857 | D29: =CHOOSE($B$5,D26,D27,D28) -> 0.06 | E29: =CHOOSE($B$5,E26,E27,E28) -> 0.06 | F29: =CHOOSE($B$5,F26,F27,F28) -> 0.05 | G29: =CHOOSE($B$5,G26,G27,G28) -> 0.04 | H29: =CHOOSE($B$5,H26,H27,H28) -> 0.04 | I29: =CHOOSE($B$5,I26,I27,I28) -> 0.04 | J29: =CHOOSE($B$5,J26,J27,J28) -> 0.04 | K29: =CHOOSE($B$5,K26,K27,K28) -> 0.04 | M29: 资本开支率 = 资本开支 / 营业收入。
A30: 折旧率（期初 PP&E + 半年资本开支） | C30: ='三表-利润表'!C10/('三表-资产负债表'!B9-0.5*'三表-现金流量表'!C12) -> 0.16598749 | D30: 0.16598749 | E30: 0.16598749 | F30: 0.16598749 | G30: 0.16598749 | H30: 0.16598749 | I30: 0.16598749 | J30: 0.16598749 | K30: 0.16598749
A31: 利率（财务费用 / 平均有息负债；财务费用为净利息收入时为负） | C31: ='三表-利润表'!C12/AVERAGE('三表-资产负债表'!B14,'三表-资产负债表'!C14) -> 0.053974318 | D31: 0.053974318 | E31: 0.053974318 | F31: 0.053974318 | G31: 0.053974318 | H31: 0.053974318 | I31: 0.053974318 | J31: 0.053974318 | K31: 0.053974318
A32: 有息负债计划还款 | D32: 0 | E32: 0 | F32: 0 | G32: 0 | H32: 0 | I32: 0 | J32: 0 | K32: 0
A33: 估值参数（DCF，全预测期适用）
A34: 永续增长率：悲观 | D34: 0.025
A35: 永续增长率：基准 | D35: 0.03
A36: 永续增长率：乐观 | D36: 0.035
A37: 永续增长率（选用） | D37: =CHOOSE($B$5,D34,D35,D36) -> 0.03
A38: WACC 情景调整：悲观 | D38: 0.01
A39: WACC 情景调整：基准 | D39: 0
A40: WACC 情景调整：乐观 | D40: -0.005
A41: WACC 情景调整（选用） | D41: =CHOOSE($B$5,D38,D39,D40) -> 0
...

Sheet 三表-利润表
A1: 三表联动模型：利润表（情景见“三表-假设”B5，默认基准）
A2: 单位：百万元；蓝色为输入（报表值、驱动假设），黑色为公式，绿色为跨表引用；预测期由“三表-假设”驱动
A4: 利润表（百万元） | B4: FY2024A | C4: FY2025A | D4: FY2026E | E4: FY2027E | F4: FY2028E | G4: FY2029E | H4: FY2030E | I4: FY2031E | J4: FY2032E | K4: FY2033E | M4: 来源及计算口径
A5: 营业收入 | B5: 392.7707 | C5: 1699.2693 | D5: =C5*(1+'三表-假设'!D10) -> 2344.9916 | E5: =D5*(1+'三表-假设'!E10) -> 3282.9883 | F5: =E5*(1+'三表-假设'!F10) -> 4432.0342 | G5: =F5*(1+'三表-假设'!G10) -> 5761.6444 | H5: =G5*(1+'三表-假设'!H10) -> 7202.0556 | I5: =H5*(1+'三表-假设'!I10) -> 8642.4667 | J5: =I5*(1+'三表-假设'!J10) -> 9938.8367 | K5: =J5*(1+'三表-假设'!K10) -> 10932.72 | M5: 实际期取合并利润表；预测期 = 上年收入 × (1 + 收入增速)。
A6: 营业成本 | B6: 168.0441 | C6: 672.261 | D6: =D5*(1-'三表-假设'!D14) -> 1031.7963 | E6: =E5*(1-'三表-假设'!E14) -> 1510.1746 | F6: =F5*(1-'三表-假设'!F14) -> 2127.3764 | G6: =G5*(1-'三表-假设'!G14) -> 2823.2058 | H6: =H5*(1-'三表-假设'!H14) -> 3601.0278 | I6: =I5*(1-'三表-假设'!I14) -> 4321.2333 | J6: =J5*(1-'三表-假设'!J14) -> 4969.4183 | K6: =K5*(1-'三表-假设'!K14) -> 5466.3602 | M6: 营业成本 = 营业收入 × (1 − 毛利率)。
A7: 毛利 | B7: =B5-B6 -> 224.7266 | C7: =C5-C6 -> 1027.0083 | D7: =D5-D6 -> 1313.1953 | E7: =E5-E6 -> 1772.8137 | F7: =F5-F6 -> 2304.6578 | G7: =G5-G6 -> 2938.4387 | H7: =H5-H6 -> 3601.0278 | I7: =I5-I6 -> 4321.2333 | ... K7: =K5-K6 -> 5466.3602 | M7: 毛利 = 营业收入 − 营业成本。
A8: 经营费用（不含折旧摊销） | B8: 149.4118 | C8: 675.1144 | D8: =D5*'三表-假设'!D15 -> 656.59766 | E8: =E5*'三表-假设'!E15 -> 886.40684 | F8: =F5*'三表-假设'!F15 -> 1152.3289 | G8: =G5*'三表-假设'!G15 -> 1440.4111 | H8: =H5*'三表-假设'!H15 -> 1728.4933 | I8: =I5*'三表-假设'!I15 -> 1987.7673 | J8: =J5*'三表-假设'!J15 -> 2285.9324 | K8: =K5*'三表-假设'!K15 -> 2514.5257
A9: EBITDA | B9: =B7-B8 -> 75.3148 | C9: =C7-C8 -> 351.8939 | D9: =D7-D8 -> 656.59766 | E9: =E7-E8 -> 886.40684 | F9: =F7-F8 -> 1152.3289 | G9: =G7-G8 -> 1498.0276 | H9: =H7-H8 -> 1872.5344 | I9: =I7-I8 -> 2333.466 | ... K9: =K7-K8 -> 2951.8345
A10: 折旧摊销 | B10: 2.1122 | C10: 6.3726 | D10: ='三表-假设'!D51 -> 17.681842 | E10: ='三表-假设'!E51 -> 42.772105 | F10: ='三表-假设'!F51 -> 70.412076 | G10: ='三表-假设'!G51 -> 96.243326 | H10: ='三表-假设'!H51 -> 123.30438 | I10: ='三表-假设'!I51 -> 155.43724 | J10: ='三表-假设'!J51 -> 191.32188 | K10: ='三表-假设'!K51 -> 228.85319
A11: EBIT（经营性） | B11: =B9-B10 -> 73.2026 | C11: =C9-C10 -> 345.5213 | D11: =D9-D10 -> 638.91582 | E11: =E9-E10 -> 843.63473 | F11: =F9-F10 -> 1081.9168 | G11: =G9-G10 -> 1401.7842 | H11: =H9-H10 -> 1749.2301 | I11: =I9-I10 -> 2178.0288 | ... K11: =K9-K10 -> 2722.9813 | M11: 经营 EBIT = 毛利 − 经营费用 − 折旧摊销；不含投资收益与公允价值变动收益。
A12: 利息费用（财务费用） | B12: -17.1864 | C12: 0.9861 | D12: ='三表-假设'!D57 -> 1.632572 | E12: ='三表-假设'!E57 -> 1.632572 | F12: ='三表-假设'!F57 -> 1.632572 | G12: ='三表-假设'!G57 -> 1.632572 | H12: ='三表-假设'!H57 -> 1.632572 | I12: ='三表-假设'!I57 -> 1.632572 | J12: ='三表-假设'!J57 -> 1.632572 | K12: ='三表-假设'!K57 -> 1.632572
A13: 经营性税前利润 | B13: =B11-B12 -> 90.389 | C13: =C11-C12 -> 344.5352 | D13: =D11-D12 -> 637.28324 | E13: =E11-E12 -> 842.00216 | F13: =F11-F12 -> 1080.2842 | G13: =G11-G12 -> 1400.1517 | H13: =H11-H12 -> 1747.5975 | I13: =I11-I12 -> 2176.3962 | ... K13: =K11-K12 -> 2721.3487
A14: 加：投资收益与公允价值变动 | B14: 10.2288 | C14: 23.9238 | D14: 0 | E14: 0 | F14: 0 | G14: 0 | H14: 0 | I14: 0 | J14: 0 | K14: 0
A15: 利润总额 | B15: =B13+B14 -> 100.6178 | C15: =C13+C14 -> 368.459 | D15: =D13+D14 -> 637.28324 | E15: =E13+E14 -> 842.00216 | F15: =F13+F14 -> 1080.2842 | G15: =G13+G14 -> 1400.1517 | H15: =H13+H14 -> 1747.5975 | I15: =I13+I14 -> 2176.3962 | ... K15: =K13+K14 -> 2721.3487 | M15: 利润总额 = 经营 EBIT − 利息费用 + 投资收益及公允价值变动收益。
A16: 减：所得税 | B16: 5.143 | C16: 90.2485 | D16: =MAX(D15,0)*'三表-假设'!D16 -> 95.592487 | E16: =MAX(E15,0)*'三表-假设'!E16 -> 126.30032 | F16: =MAX(F15,0)*'三表-假设'!F16 -> 162.04264 | G16: =MAX(G15,0)*'三表-假设'!G16 -> 210.02275 | H16: =MAX(H15,0)*'三表-假设'!H16 -> 262.13962 | I16: =MAX(I15,0)*'三表-假设'!I16 -> 326.45943 | J16: =MAX(J15,0)*'三表-假设'!J16 -> 373.57972 | K16: =MAX(K15,0)*'三表-假设'!K16 -> 408.20231
A17: 净利润 | B17: =B15-B16 -> 95.4748 | C17: =C15-C16 -> 278.2105 | D17: =D15-D16 -> 541.69076 | E17: =E15-E16 -> 715.70184 | F17: =F15-F16 -> 918.2416 | G17: =G15-G16 -> 1190.1289 | H17: =H15-H16 -> 1485.4579 | I17: =I15-I16 -> 1849.9368 | ... K17: =K15-K16 -> 2313.1464 | M17: 净利润 = 利润总额 − 所得税费用。
A19: 主要比率
A20: 营业收入增长率 | C20: =C5/B5-1 -> 3.3263647 | D20: =D5/C5-1 -> 0.38 | E20: =E5/D5-1 -> 0.4 | F20: =F5/E5-1 -> 0.35 | G20: =G5/F5-1 -> 0.3 | H20: =H5/G5-1 -> 0.25 | I20: =I5/H5-1 -> 0.2 | J20: =J5/I5-1 -> 0.15 | K20: =K5/J5-1 -> 0.1
A21: 毛利率 | B21: =B7/B5 -> 0.57215724 | C21: =C7/C5 -> 0.60438231 | D21: =D7/D5 -> 0.56 | E21: =E7/E5 -> 0.54 | F21: =F7/F5 -> 0.52 | G21: =G7/G5 -> 0.51 | H21: =H7/H5 -> 0.5 | I21: =I7/I5 -> 0.5 | ... K21: =K7/K5 -> 0.5
A22: EBIT 利润率 | B22: =B11/B5 -> 0.1863749 | C22: =C11/C5 -> 0.20333522 | D22: =D11/D5 -> 0.27245974 | E22: =E11/E5 -> 0.25697159 | F22: =F11/F5 -> 0.24411292 | G22: =G11/G5 -> 0.24329586 | H22: =H11/H5 -> 0.24287928 | I22: =I11/I5 -> 0.25201471 | ... K22: =K11/K5 -> 0.24906713
A23: 净利率 | B23: =B17/B5 -> 0.24308025 | C23: =C17/C5 -> 0.16372361 | D23: =D17/D5 -> 0.23099901 | E23: =E17/E5 -> 0.21800316 | F23: =F17/F5 -> 0.20718288 | G23: =G17/G5 -> 0.20656063 | H23: =H17/H5 -> 0.20625471 | I23: =I17/I5 -> 0.21405194 | ... K23: =K17/K5 -> 0.21158013
A24: 有效税率 | B24: =B16/B15 -> 0.051114216 | C24: =C16/C15 -> 0.24493499 | D24: =D16/D15 -> 0.15 | E24: =E16/E15 -> 0.15 | F24: =F16/F15 -> 0.15 | G24: =G16/G15 -> 0.15 | H24: =H16/H15 -> 0.15 | I24: =I16/I15 -> 0.15 | ... K24: =K16/K15 -> 0.15

Sheet 三表-资产负债表
A1: 三表联动模型：资产负债表（情景见“三表-假设”B5，默认基准）
A2: 单位：百万元；蓝色为输入（报表值、驱动假设），黑色为公式，绿色为跨表引用；权益（含少数股东）合并列示，留存收益为预测期累计
A4: 资产负债表（百万元） | B4: FY2024A | C4: FY2025A | D4: FY2026E | E4: FY2027E | F4: FY2028E | G4: FY2029E | H4: FY2030E | I4: FY2031E | J4: FY2032E | K4: FY2033E | M4: 来源及计算口径
A5: 资产
A6: 货币资金 | B6: 565.9428 | C6: 1419.2579 | D6: ='三表-现金流量表'!D21 -> 1749.8525 | E6: ='三表-现金流量表'!E21 -> 2191.43 | F6: ='三表-现金流量表'!F21 -> 2805.8789 | G6: ='三表-现金流量表'!G21 -> 3688.5602 | H6: ='三表-现金流量表'!H21 -> 4817.1887 | I6: ='三表-现金流量表'!I21 -> 6295.3506 | J6: ='三表-现金流量表'!J21 -> 8042.7088 | K6: ='三表-现金流量表'!K21 -> 10022.155 | M6: 预测期货币资金引用现金流量表期末现金。
A7: 应收账款 | B7: 20.566 | C7: 58.7336 | D7: ='三表-假设'!D43 -> 81.052368 | E7: ='三表-假设'!E43 -> 113.47332 | F7: ='三表-假设'!F43 -> 153.18898 | G7: ='三表-假设'!G43 -> 199.14567 | H7: ='三表-假设'!H43 -> 248.93209 | I7: ='三表-假设'!I43 -> 298.7185 | J7: ='三表-假设'!J43 -> 343.52628 | K7: ='三表-假设'!K43 -> 377.87891 | M7: 应收账款 = 营业收入 × 应收账款周转天数 / 365。
A8: 存货 | B8: 141.3341 | C8: 367.7534 | D8: ='三表-假设'!D44 -> 564.43346 | E8: ='三表-假设'!E44 -> 826.12534 | F8: ='三表-假设'!F44 -> 1163.7592 | G8: ='三表-假设'!G44 -> 1544.4054 | H8: ='三表-假设'!H44 -> 1969.9049 | I8: ='三表-假设'!I44 -> 2363.8858 | J8: ='三表-假设'!J44 -> 2718.4687 | K8: ='三表-假设'!K44 -> 2990.3156 | M8: 存货 = 营业成本 × 存货周转天数 / 365。
A9: 固定资产 + 在建工程 | B9: 13.2107 | C9: 36.1754 | D9: ='三表-假设'!D52 -> 159.19306 | E9: ='三表-假设'!E52 -> 313.40025 | F9: ='三表-假设'!F52 -> 464.58988 | G9: ='三表-假设'!G52 -> 598.81233 | H9: ='三表-假设'!H52 -> 763.59018 | I9: ='三表-假设'!I52 -> 953.8516 | J9: ='三表-假设'!J52 -> 1160.0832 | K9: ='三表-假设'!K52 -> 1368.5388 | M9: 固定资产及在建工程引用固定资产滚动辅助计算。
A10: 其他资产（含财务公司类现金资产） | B10: 786.8158 | C10: 1326.618 | D10: =C10 -> 1326.618 | E10: =D10 -> 1326.618 | F10: =E10 -> 1326.618 | G10: =F10 -> 1326.618 | H10: =G10 -> 1326.618 | I10: =H10 -> 1326.618 | J10: =I10 -> 1326.618 | K10: =J10 -> 1326.618
A11: 资产总计 | B11: =SUM(B6:B10) -> 1527.8694 | C11: =SUM(C6:C10) -> 3208.5383 | D11: =SUM(D6:D10) -> 3881.1494 | E11: =SUM(E6:E10) -> 4771.0469 | F11: =SUM(F6:F10) -> 5914.0349 | G11: =SUM(G6:G10) -> 7357.5416 | H11: =SUM(H6:H10) -> 9126.2338 | I11: =SUM(I6:I10) -> 11238.425 | ... K11: =SUM(K6:K10) -> 16085.507 | M11: 资产总计 = 各项资产合计。
A12: 负债
A13: 应付账款 | B13: 89.9818 | C13: 244.7956 | D13: ='三表-假设'!D45 -> 375.71598 | E13: ='三表-假设'!E45 -> 549.91157 | F13: ='三表-假设'!F45 -> 774.65803 | G13: ='三表-假设'!G45 -> 1028.0358 | H13: ='三表-假设'!H45 -> 1311.2701 | I13: ='三表-假设'!I45 -> 1573.5241 | J13: ='三表-假设'!J45 -> 1809.5528 | K13: ='三表-假设'!K45 -> 1990.508 | M13: 应付账款 = 营业成本 × 应付账款周转天数 / 365。
A14: 有息负债（含租赁负债） | B14: 6.2924 | C14: 30.2472 | D14: ='三表-假设'!D56 -> 30.2472 | E14: ='三表-假设'!E56 -> 30.2472 | F14: ='三表-假设'!F56 -> 30.2472 | G14: ='三表-假设'!G56 -> 30.2472 | H14: ='三表-假设'!H56 -> 30.2472 | I14: ='三表-假设'!I56 -> 30.2472 | J14: ='三表-假设'!J56 -> 30.2472 | K14: ='三表-假设'!K56 -> 30.2472
A15: 其他负债 | B15: 151.0462 | C15: 328.8371 | D15: =C15 -> 328.8371 | E15: =D15 -> 328.8371 | F15: =E15 -> 328.8371 | G15: =F15 -> 328.8371 | H15: =G15 -> 328.8371 | I15: =H15 -> 328.8371 | J15: =I15 -> 328.8371 | K15: =J15 -> 328.8371
A16: 负债合计 | B16: =SUM(B13:B15) -> 247.3204 | C16: =SUM(C13:C15) -> 603.8799 | D16: =SUM(D13:D15) -> 734.80028 | E16: =SUM(E13:E15) -> 908.99587 | F16: =SUM(F13:F15) -> 1133.7423 | G16: =SUM(G13:G15) -> 1387.1201 | H16: =SUM(H13:H15) -> 1670.3544 | I16: =SUM(I13:I15) -> 1932.6084 | ... K16: =SUM(K13:K15) -> 2349.5923
A17: 所有者权益
A18: 股本、资本公积及其他权益 | B18: 1280.549 | C18: 2604.6585 | D18: =C18 -> 2604.6585 | E18: =D18 -> 2604.6585 | F18: =E18 -> 2604.6585 | G18: =F18 -> 2604.6585 | H18: =G18 -> 2604.6585 | I18: =H18 -> 2604.6585 | J18: =I18 -> 2604.6585 | K18: =J18 -> 2604.6585
A19: 留存收益（预测期累计） | B19: 0 | C19: 0 | D19: =C19+'三表-利润表'!D17-'三表-假设'!D59 -> 541.69076 | E19: =D19+'三表-利润表'!E17-'三表-假设'!E59 -> 1257.3926 | F19: =E19+'三表-利润表'!F17-'三表-假设'!F59 -> 2175.6342 | G19: =F19+'三表-利润表'!G17-'三表-假设'!G59 -> 3365.7631 | H19: =G19+'三表-利润表'!H17-'三表-假设'!H59 -> 4851.221 | I19: =H19+'三表-利润表'!I17-'三表-假设'!I59 -> 6701.1577 | J19: =I19+'三表-利润表'!J17-'三表-假设'!J59 -> 8818.1095 | K19: =J19+'三表-利润表'!K17-'三表-假设'!K59 -> 11131.256
A20: 所有者权益合计 | B20: =B18+B19 -> 1280.549 | C20: =C18+C19 -> 2604.6585 | D20: =D18+D19 -> 3146.3493 | E20: =E18+E19 -> 3862.0511 | F20: =F18+F19 -> 4780.2927 | G20: =G18+G19 -> 5970.4216 | H20: =H18+H19 -> 7455.8795 | I20: =I18+I19 -> 9305.8162 | ... K20: =K18+K19 -> 13735.914
A21: 负债和所有者权益总计 | B21: =B16+B20 -> 1527.8694 | C21: =C16+C20 -> 3208.5384 | D21: =D16+D20 -> 3881.1495 | E21: =E16+E20 -> 4771.047 | F21: =F16+F20 -> 5914.035 | G21: =G16+G20 -> 7357.5417 | H21: =H16+H20 -> 9126.2339 | I21: =I16+I20 -> 11238.425 | ... K21: =K16+K20 -> 16085.507 | M21: 负债和权益总计 = 各项负债与权益合计。
A23: 勾稽检查（应全部为 0，显示为“-”）
A24: 资产总计 − 负债和所有者权益总计 | B24: =ROUND(B11-B21,6) -> 0 | C24: =ROUND(C11-C21,6) -> 0 | D24: =ROUND(D11-D21,6) -> 0 | E24: =ROUND(E11-E21,6) -> 0 | F24: =ROUND(F11-F21,6) -> 0 | G24: =ROUND(G11-G21,6) -> 0 | H24: =ROUND(H11-H21,6) -> 0 | I24: =ROUND(I11-I21,6) -> 0 | ... K24: =ROUND(K11-K21,6) -> 0 | M24: 模型检查 = 资产总计 − 负债和权益总计；容差内应为 0.00。
A25: 现金流量表期末现金 − 货币资金 | D25: =ROUND('三表-现金流量表'!D21-D6,6) -> 0 | E25: =ROUND('三表-现金流量表'!E21-E6,6) -> 0 | F25: =ROUND('三表-现金流量表'!F21-F6,6) -> 0 | G25: =ROUND('三表-现金流量表'!G21-G6,6) -> 0 | H25: =ROUND('三表-现金流量表'!H21-H6,6) -> 0 | I25: =ROUND('三表-现金流量表'!I21-I6,6) -> 0 | J25: =ROUND('三表-现金流量表'!J21-J6,6) -> 0 | K25: =ROUND('三表-现金流量表'!K21-K6,6) -> 0
A26: 留存收益滚动（期初 + 净利润 − 分红 − 期末） | D26: =ROUND(C19+'三表-利润表'!D17-'三表-假设'!D59-D19,6) -> 0 | E26: =ROUND(D19+'三表-利润表'!E17-'三表-假设'!E59-E19,6) -> 0 | F26: =ROUND(E19+'三表-利润表'!F17-'三表-假设'!F59-F19,6) -> 0 | G26: =ROUND(F19+'三表-利润表'!G17-'三表-假设'!G59-G19,6) -> 0 | H26: =ROUND(G19+'三表-利润表'!H17-'三表-假设'!H59-H19,6) -> 0 | I26: =ROUND(H19+'三表-利润表'!I17-'三表-假设'!I59-I19,6) -> 0 | J26: =ROUND(I19+'三表-利润表'!J17-'三表-假设'!J59-J19,6) -> 0 | K26: =ROUND(J19+'三表-利润表'!K17-'三表-假设'!K59-K19,6) -> 0
A27: PP&E 滚动（期初 + 资本开支 − 折旧 − 期末） | D27: =ROUND('三表-假设'!D49+'三表-假设'!D50-'三表-假设'!D51-'三表-假设'!D52,6) -> 0 | E27: =ROUND('三表-假设'!E49+'三表-假设'!E50-'三表-假设'!E51-'三表-假设'!E52,6) -> 0 | F27: =ROUND('三表-假设'!F49+'三表-假设'!F50-'三表-假设'!F51-'三表-假设'!F52,6) -> 0 | G27: =ROUND('三表-假设'!G49+'三表-假设'!G50-'三表-假设'!G51-'三表-假设'!G52,6) -> 0 | H27: =ROUND('三表-假设'!H49+'三表-假设'!H50-'三表-假设'!H51-'三表-假设'!H52,6) -> 0 | I27: =ROUND('三表-假设'!I49+'三表-假设'!I50-'三表-假设'!I51-'三表-假设'!I52,6) -> 0 | J27: =ROUND('三表-假设'!J49+'三表-假设'!J50-'三表-假设'!J51-'三表-假设'!J52,6) -> 0 | K27: =ROUND('三表-假设'!K49+'三表-假设'!K50-'三表-假设'!K51-'三表-假设'!K52,6) -> 0
A28: 有息负债滚动（期初 − 偿还 − 期末） | D28: =ROUND('三表-假设'!D54-'三表-假设'!D55-'三表-假设'!D56,6) -> 0 | E28: =ROUND('三表-假设'!E54-'三表-假设'!E55-'三表-假设'!E56,6) -> 0 | F28: =ROUND('三表-假设'!F54-'三表-假设'!F55-'三表-假设'!F56,6) -> 0 | G28: =ROUND('三表-假设'!G54-'三表-假设'!G55-'三表-假设'!G56,6) -> 0 | H28: =ROUND('三表-假设'!H54-'三表-假设'!H55-'三表-假设'!H56,6) -> 0 | I28: =ROUND('三表-假设'!I54-'三表-假设'!I55-'三表-假设'!I56,6) -> 0 | J28: =ROUND('三表-假设'!J54-'三表-假设'!J55-'三表-假设'!J56,6) -> 0 | K28: =ROUND('三表-假设'!K54-'三表-假设'!K55-'三表-假设'!K56,6) -> 0
A29: 勾稽结论 | B29: =IF(SUM(ABS(B24),ABS(C24),ABS(D24),ABS(E24),ABS(F24),ABS(G24),ABS(H24),ABS(I24),ABS(J24),ABS(K24),ABS(B25),ABS(C25),ABS(D25),ABS(E25),ABS(F25),ABS(G25),ABS(H25),ABS(I25),ABS(J25),ABS(K25),ABS(B26),ABS(C26),ABS(D26),ABS(E26),ABS(F26),ABS(G26),ABS(H26),ABS(I26),ABS(J26),ABS(K26),ABS(B27),ABS(C27),ABS(D27),ABS(E27),ABS(F27),ABS(G27),ABS(H27),ABS(I27),ABS(J27),ABS(K27),ABS(B28),ABS(C28),ABS(D28),ABS(E28),ABS(F28),ABS(G28),ABS(H28),ABS(I28),ABS(J28),ABS(K28))<0.001,"全部平衡","不平衡，请检查") -> 全部平衡 | D29: 汇总资产负债、现金、留存收益、PP&E 与有息负债滚动检查。

Sheet 三表-现金流量表
A1: 三表联动模型：现金流量表（情景见“三表-假设”B5，默认基准）
A2: 单位：百万元；蓝色为输入（报表值、驱动假设），黑色为公式，绿色为跨表引用；实际年度经营现金流为报表值，“其他经营项目”为轧差（含财务公司存款变动）
A4: 现金流量表（百万元） | B4: FY2024A | C4: FY2025A | D4: FY2026E | E4: FY2027E | F4: FY2028E | G4: FY2029E | H4: FY2030E | I4: FY2031E | J4: FY2032E | K4: FY2033E | M4: 来源及计算口径
A5: 经营活动
A6: 净利润 | B6: ='三表-利润表'!B17 -> 95.4748 | C6: ='三表-利润表'!C17 -> 278.2105 | D6: ='三表-利润表'!D17 -> 541.69076 | E6: ='三表-利润表'!E17 -> 715.70184 | F6: ='三表-利润表'!F17 -> 918.2416 | G6: ='三表-利润表'!G17 -> 1190.1289 | H6: ='三表-利润表'!H17 -> 1485.4579 | I6: ='三表-利润表'!I17 -> 1849.9368 | ... K6: ='三表-利润表'!K17 -> 2313.1464
A7: 加：折旧摊销 | B7: ='三表-利润表'!B10 -> 2.1122 | C7: ='三表-利润表'!C10 -> 6.3726 | D7: ='三表-利润表'!D10 -> 17.681842 | E7: ='三表-利润表'!E10 -> 42.772105 | F7: ='三表-利润表'!F10 -> 70.412076 | G7: ='三表-利润表'!G10 -> 96.243326 | H7: ='三表-利润表'!H10 -> 123.30438 | I7: ='三表-利润表'!I10 -> 155.43724 | ... K7: ='三表-利润表'!K10 -> 228.85319
A8: 减：营运资本增加 | C8: =-'三表-假设'!C47 -> -109.7731 | D8: =-'三表-假设'!D47 -> -88.078453 | E8: =-'三表-假设'!E47 -> -119.91724 | F8: =-'三表-假设'!F47 -> -152.60303 | G8: =-'三表-假设'!G47 -> -173.22519 | H8: =-'三表-假设'!H47 -> -192.05152 | I8: =-'三表-假设'!I47 -> -181.51337 | J8: =-'三表-假设'!J47 -> -163.36203 | K8: =-'三表-假设'!K47 -> -125.24422
A9: 其他经营项目 | C9: =C10-C6-C7-C8 -> 495.1718 | D9: 0 | E9: 0 | F9: 0 | G9: 0 | H9: 0 | I9: 0 | J9: 0 | K9: 0
A10: 经营活动现金流量净额 | B10: 192.3913 | C10: 669.9818 | D10: =SUM(D6:D9) -> 471.29415 | E10: =SUM(E6:E9) -> 638.55671 | F10: =SUM(F6:F9) -> 836.05065 | G10: =SUM(G6:G9) -> 1113.147 | H10: =SUM(H6:H9) -> 1416.7107 | I10: =SUM(I6:I9) -> 1823.8606 | J10: =SUM(J6:J9) -> 2144.9116 | K10: =SUM(K6:K9) -> 2416.7554 | M10: 经营活动现金流 = 净利润 + 折旧摊销 − 营运资本增加 + 其他经营项目。
A11: 投资活动
A12: 购建长期资产（资本开支） | B12: -9.6953 | C12: -50.3627 | D12: =-'三表-假设'!D50 -> -140.6995 | E12: =-'三表-假设'!E50 -> -196.9793 | F12: =-'三表-假设'!F50 -> -221.60171 | G12: =-'三表-假设'!G50 -> -230.46578 | H12: =-'三表-假设'!H50 -> -288.08222 | I12: =-'三表-假设'!I50 -> -345.69867 | J12: =-'三表-假设'!J50 -> -397.55347 | K12: =-'三表-假设'!K50 -> -437.30881 | M12: 资本开支为现金流出，取负号列示。
A13: 投资活动现金流量净额（模型口径） | D13: =D12 -> -140.6995 | E13: =E12 -> -196.9793 | F13: =F12 -> -221.60171 | G13: =G12 -> -230.46578 | H13: =H12 -> -288.08222 | I13: =I12 -> -345.69867 | J13: =J12 -> -397.55347 | K13: =K12 -> -437.30881
A14: 筹资活动
A15: 偿还有息负债 | D15: =-'三表-假设'!D55 -> 0 | E15: =-'三表-假设'!E55 -> 0 | F15: =-'三表-假设'!F55 -> 0 | G15: =-'三表-假设'!G55 -> 0 | H15: =-'三表-假设'!H55 -> 0 | I15: =-'三表-假设'!I55 -> 0 | J15: =-'三表-假设'!J55 -> 0 | K15: =-'三表-假设'!K55 -> 0
A16: 现金分红 | D16: =-'三表-假设'!D59 -> 0 | E16: =-'三表-假设'!E59 -> 0 | F16: =-'三表-假设'!F59 -> 0 | G16: =-'三表-假设'!G59 -> 0 | H16: =-'三表-假设'!H59 -> 0 | I16: =-'三表-假设'!I59 -> 0 | J16: =-'三表-假设'!J59 -> 0 | K16: =-'三表-假设'!K59 -> 0
A17: 筹资活动现金流量净额（模型口径） | D17: =D15+D16 -> 0 | E17: =E15+E16 -> 0 | F17: =F15+F16 -> 0 | G17: =G15+G16 -> 0 | H17: =H15+H16 -> 0 | I17: =I15+I16 -> 0 | J17: =J15+J16 -> 0 | K17: =K15+K16 -> 0
A19: 现金净增加额 | D19: =D10+D13+D17 -> 330.59465 | E19: =E10+E13+E17 -> 441.57741 | F19: =F10+F13+F17 -> 614.44894 | G19: =G10+G13+G17 -> 882.68127 | H19: =H10+H13+H17 -> 1128.6285 | I19: =I10+I13+I17 -> 1478.162 | J19: =J10+J13+J17 -> 1747.3581 | K19: =K10+K13+K17 -> 1979.4466
A20: 期初现金 | D20: ='三表-资产负债表'!C6 -> 1419.2579 | E20: =D21 -> 1749.8525 | F20: =E21 -> 2191.43 | G20: =F21 -> 2805.8789 | H20: =G21 -> 3688.5602 | I20: =H21 -> 4817.1887 | J20: =I21 -> 6295.3506 | K20: =J21 -> 8042.7088
A21: 期末现金 | D21: =D20+D19 -> 1749.8525 | E21: =E20+E19 -> 2191.43 | F21: =F20+F19 -> 2805.8789 | G21: =G20+G19 -> 3688.5602 | H21: =H20+H19 -> 4817.1887 | I21: =I20+I19 -> 6295.3506 | J21: =J20+J19 -> 8042.7088 | K21: =K20+K19 -> 10022.155 | M21: 期末现金 = 期初现金 + 经营、投资与筹资活动现金流。

Sheet 历史财务
A1: 历史财务数据（2024A / 2025A，合并报表）
A2: 金额单位：百万元（每股为元）；蓝色为年报抽取值（逐字核对原文），黑色为公式；来源为年报 PDF 页码
A4: 项目 | B4: FY2024A | C4: FY2025A | D4: 同比 / 变动 | E4: 来源页 | F4: 原文科目
A5: 利润表
A6: 营业收入（百万元） | B6: 392.7707 | C6: 1699.2693 | D6: =IF(B6=0,"NM",(C6-B6)/ABS(B6)) -> 3.3263647 | E6: p.161 | F6: 一、营业收入
A7: 营业成本（百万元） | B7: 168.0441 | C7: 672.261 | D7: =IF(B7=0,"NM",(C7-B7)/ABS(B7)) -> 3.0005034 | E7: p.161 | F7: 减：营业成本
A8: 销售费用（百万元） | B8: 59.1585 | C8: 141.2032 | D8: =IF(B8=0,"NM",(C8-B8)/ABS(B8)) -> 1.3868624 | E8: p.162 | F8: 销售费用
A9: 管理费用（百万元） | B9: 25.0052 | C9: 399.5961 | D9: =IF(B9=0,"NM",(C9-B9)/ABS(B9)) -> 14.98052 | E9: p.162 | F9: 管理费用
A10: 研发费用（百万元） | B10: 70.017 | C10: 144.9656 | D10: =IF(B10=0,"NM",(C10-B10)/ABS(B10)) -> 1.0704343 | E10: p.162 | F10: 研发费用
A11: 财务费用（百万元） | B11: -17.1864 | C11: 0.9861 | D11: =IF(B11=0,"NM",(C11-B11)/ABS(B11)) -> 1.0573768 | E11: p.162 | F11: 财务费用
A12: 投资收益（百万元） | B12: 9.2746 | C12: 23.0109 | D12: =IF(B12=0,"NM",(C12-B12)/ABS(B12)) -> 1.4810666 | E12: p.162 | F12: 投资收益
A13: 公允价值变动收益（百万元） | B13: 0.9542 | C13: 0.9129 | D13: =IF(B13=0,"NM",(C13-B13)/ABS(B13)) -> -0.043282331 | E13: p.162 | F13: 公允价值变动收益
A14: 营业利润（百万元） | B14: 100.7025 | C14: 367.7135 | D14: =IF(B14=0,"NM",(C14-B14)/ABS(B14)) -> 2.6514833 | E14: p.162 | F14: 二、营业利润
A15: 利润总额（百万元） | B15: 100.6178 | C15: 368.459 | D15: =IF(B15=0,"NM",(C15-B15)/ABS(B15)) -> 2.6619664 | E15: p.162 | F15: 三、利润总额
A16: 所得税费用（百万元） | B16: 5.143 | C16: 90.2485 | D16: =IF(B16=0,"NM",(C16-B16)/ABS(B16)) -> 16.547832 | E16: p.162 | F16: 减：所得税费用
A17: 净利润（百万元） | B17: 95.4747 | C17: 278.2105 | D17: =IF(B17=0,"NM",(C17-B17)/ABS(B17)) -> 1.9139709 | E17: p.162 | F17: 四、净利润
... A20: 非经常性损益合计（百万元） | B20: 16.9982 | C20: -312.5423 | D20: =IF(B20=0,"NM",(C20-B20)/ABS(B20)) -> -19.386788 | E20: p.193 | F20: 归属于母公司股东的非经常性损益净额
A21: 资产负债表
A22: 货币资金（百万元） | B22: 565.9428 | C22: 1419.2579 | D22: =IF(B22=0,"NM",(C22-B22)/ABS(B22)) -> 1.5077762 | E22: p.160 | F22: 货币资金
A23: 应收账款（百万元） | B23: 20.566 | C23: 58.7336 | D23: =IF(B23=0,"NM",(C23-B23)/ABS(B23)) -> 1.8558592 | E23: p.160 | F23: 应收账款
A24: 存货（百万元） | B24: 141.3341 | C24: 367.7534 | D24: =IF(B24=0,"NM",(C24-B24)/ABS(B24)) -> 1.6020147 | E24: p.160 | F24: 存货
A25: 固定资产（百万元） | B25: 11.4321 | C25: 35.138 | D25: =IF(B25=0,"NM",(C25-B25)/ABS(B25)) -> 2.073626 | E25: p.160 | F25: 固定资产
A26: 在建工程（百万元） | B26: 1.7786 | C26: 1.0374 | D26: =IF(B26=0,"NM",(C26-B26)/ABS(B26)) -> -0.41673226 | E26: p.160 | F26: 在建工程
A27: 资产总计（百万元） | B27: 1527.8694 | C27: 3208.5383 | D27: =IF(B27=0,"NM",(C27-B27)/ABS(B27)) -> 1.1000082 | E27: p.161 | F27: 资产总计
A28: 应付账款（百万元） | B28: 89.9818 | C28: 244.7956 | D28: =IF(B28=0,"NM",(C28-B28)/ABS(B28)) -> 1.7205013 | E28: p.161 | F28: 应付账款
A29: 一年内到期的非流动负债（百万元） | B29: 4.9572 | C29: 16.108 | D29: =IF(B29=0,"NM",(C29-B29)/ABS(B29)) -> 2.249415 | E29: p.161 | F29: 一年内到期的非流动负 债
A30: 租赁负债（百万元） | B30: 1.3052 | C30: 14.1392 | D30: =IF(B30=0,"NM",(C30-B30)/ABS(B30)) -> 9.8329758 | E30: p.161 | F30: 租赁负债
A31: 负债合计（百万元） | B31: 247.3204 | C31: 603.8799 | D31: =IF(B31=0,"NM",(C31-B31)/ABS(B31)) -> 1.4416906 | E31: p.161 | F31: 负债合计
A32: 归属于母公司所有者权益合计（百万元） | B32: 1280.549 | C32: 2604.6585 | D32: =IF(B32=0,"NM",(C32-B32)/ABS(B32)) -> 1.0340171 | E32: p.161 | F32: 归属于母公司所有者权 益合计
A33: 所有者权益合计（百万元） | B33: 1280.549 | C33: 2604.6585 | D33: =IF(B33=0,"NM",(C33-B33)/ABS(B33)) -> 1.0340171 | E33: p.161 | F33: 所有者权益合计
A34: 现金流量表
A35: 经营活动产生的现金流量净额（百万元） | B35: 192.3913 | C35: 669.9818 | D35: =IF(B35=0,"NM",(C35-B35)/ABS(B35)) -> 2.4823914 | E35: p.163 | F35: 经营活动产生的现金流量净额
A36: 购建固定资产、无形资产和其他长期资产支付的现金（百万元） | B36: 9.6953 | C36: 50.3627 | D36: =IF(B36=0,"NM",(C36-B36)/ABS(B36)) -> 4.1945479 | E36: p.163 | F36: 购建固定资产、无形资产和其他长期 资产支付的现金
A37: 固定资产折旧、油气资产折耗、生产性生物资产折旧（百万元） | B37: 1.9507 | C37: 6.0388 | D37: =IF(B37=0,"NM",(C37-B37)/ABS(B37)) -> 2.0957092 | E37: p.240 | F37: 固定资产折旧、投资性房地产折旧、油气资产折耗、生产性生物资产折旧
A38: 无形资产摊销（百万元） | B38: 0.1615 | C38: 0.3338 | D38: =IF(B38=0,"NM",(C38-B38)/ABS(B38)) -> 1.0668731 | E38: p.240 | F38: 无形资产摊销
A39: 每股与比率
A40: 基本每股收益（元） | C40: 0.76 | E40: p.197 | F40: 基本每股收益
A41: 加权平均净资产收益率 | B41: 0.1046 | C41: 0.1352 | D41: =(C41-B41)*100 -> 3.06 | E41: p.197 | F41: 加权平均净资产收益率
A42: 毛利率 | B42: =(B6-B7)/B6 -> 0.57215724 | C42: =(C6-C7)/C6 -> 0.60438231 | D42: =(C42-B42)*100 -> 3.2225066 | E42: 派生
A43: 净利率 | B43: =B17/B6 -> 0.24308 | C43: =C17/C6 -> 0.16372361 | D43: =(C43-B43)*100 -> -7.9356388 | E43: 派生
...

Sheet 分季度
A1: 2025 年分季度数据（单季，合并报表）
A2: 单位：百万元；蓝色为年报“分季度主要财务数据”列示值，黑色为公式；差异 = 四季合计 − 全年报表值
A4: 项目（百万元） | B4: Q1 | C4: Q2 | D4: Q3 | E4: Q4 | F4: 四季合计 | G4: 全年（报表） | H4: 差异

Sheet 经营数据
A1: 经营数据（分产品 / 渠道 / 地区，量价）
A2: 金额单位：百万元；蓝色为年报原文数（逐格核对，见 financials/extras.json），黑色为公式；页码为年报 PDF 页
A4: 主营业务收入按产品类别（p.199）
A5: 项目 | B5: 2025年收入（百万元） | C5: 2025年占比 | D5: 2024年收入（百万元） | E5: 2024年占比 | F5: 2023年收入（百万元） | G5: 2023年占比
A6: 四足机器人 | B6: 697.6256 | C6: 0.4162 | D6: 230.5437 | E6: 0.5947 | F6: 119.3809 | G6: 0.7578
A7: 人形机器人 | B7: 867.8319 | C7: 0.5178 | D7: 107.2976 | E7: 0.2768 | F7: 2.9671 | G7: 0.0188
A8: 机器人组件 | B8: 103.7367 | C8: 0.0619 | D8: 44.5382 | E8: 0.1149 | F8: 26.9234 | G8: 0.1709
A9: 其他 | B9: 6.9167 | C9: 0.0041 | D9: 5.2933 | E9: 0.0137 | F9: 8.2651 | G9: 0.0525
A10: 主营业务收入合计 | B10: 1676.1109 | C10: 1 | D10: 387.6728 | E10: 1 | F10: 157.5365 | G10: 1
A11: 四足机器人销售情况（p.199）
A12: 项目 | B12: 销量（台） | C12: 销量同比 | D12: 单价（万元/台） | E12: 单价同比 | F12: 销售收入（百万元） | G12: 销售收入同比
A13: 四足2025年 | B13: 23037 | C13: 2.2283 | D13: 3.03 | E13: -0.0627 | F13: 697.6256 | G13: 2.026
A14: 四足2024年 | B14: 7136 | C14: 1.2864 | D14: 3.23 | E14: -0.1554 | F14: 230.5437 | G14: 0.9312
A15: 四足2023年 | B15: 3121 | D15: 3.83 | F15: 119.3809
A16: 四足机器人收入增长量价贡献（p.200）
A17: 项目 | B17: 2025年金额（百万元） | C17: 2025年贡献度 | D17: 2024年金额（百万元） | E17: 2024年贡献度
A18: 四足销量变动影响 | B18: 513.7157 | C18: 1.0998 | D18: 153.5771 | E18: 1.3816
A19: 四足单价变动影响 | B19: -46.6339 | C19: -0.0998 | D19: -42.4143 | E19: -0.3816
A20: 四足合计影响 | B20: 467.0819 | C20: 1 | D20: 111.1628 | E20: 1
A21: 人形机器人销售情况（p.201）
A22: 项目 | B22: 销量（台） | C22: 销量同比 | D22: 单价（万元/台） | E22: 单价同比 | F22: 销售收入（百万元） | G22: 销售收入同比
A23: 人形2025年 | B23: 5215 | C23: 11.6578 | D23: 16.64 | E23: -0.361 | F23: 867.8319 | G23: 7.0881
A24: 人形2024年 | B24: 412 | C24: 81.4 | D24: 26.04 | E24: -0.5611 | F24: 107.2976 | G24: 35.1624
A25: 人形2023年 | B25: 5 | D25: 59.34 | F25: 2.9671
A26: 人形机器人收入增长量价贡献（p.201）
A27: 项目 | B27: 2025年金额（百万元） | C27: 2025年贡献度 | D27: 2024年金额（百万元） | E27: 2024年贡献度
A28: 人形销量变动影响 | B28: 1250.8509 | C28: 1.6447 | D28: 241.5218 | E28: 2.315
A29: 人形单价变动影响 | B29: -490.3166 | C29: -0.6447 | D29: -137.1912 | E29: -1.315
A30: 人形合计影响 | B30: 760.5343 | C30: 1 | D30: 104.3305 | E30: 1
A31: 主营业务收入按区域（p.202）
A32: 项目 | B32: 2025年收入（百万元） | C32: 2025年占比 | D32: 2024年收入（百万元） | E32: 2024年占比 | F32: 2023年收入（百万元） | G32: 2023年占比
A33: 境内销售 | B33: 944.4556 | C33: 0.5635 | D33: 171.5655 | E33: 0.4426 | F33: 69.8941 | G33: 0.4437
A34: 境外销售 | B34: 731.6553 | C34: 0.4365 | D34: 216.1074 | E34: 0.5574 | F34: 87.6424 | G34: 0.5563
A35: 主营业务收入按季度（p.202）
A36: 项目 | B36: 2025年收入（百万元） | C36: 2025年占比 | D36: 2024年收入（百万元） | E36: 2024年占比 | F36: 2023年收入（百万元） | G36: 2023年占比
A37: 第一季度主营收入 | B37: 248.1592 | C37: 0.1481 | D37: 65.1098 | E37: 0.168 | F37: 30.9317 | G37: 0.1963
A38: 第二季度主营收入 | B38: 520.9534 | C38: 0.3108 | D38: 67.073 | E38: 0.173 | F38: 41.4392 | G38: 0.263
A39: 第三季度主营收入 | B39: 385.4368 | C39: 0.23 | D39: 97.6544 | E39: 0.2519 | F39: 32.2243 | G39: 0.2046
A40: 第四季度主营收入 | B40: 521.5615 | C40: 0.3112 | D40: 157.8355 | E40: 0.4071 | F40: 52.9413 | G40: 0.3361
A41: 主营业务收入按销售模式（p.203）
...

Sheet 模型检查
A1: 模型检查
A2: 硬性失败会使模型状态变为 blocked；警示需在报告中说明
A4: 类型 | B4: 内容
A5: 警示 | B5: 预测期末 EBIT 利润率 24.9% 较历史 20.3% 提升超过 3 个百分点，需有充分依据
A6: 警示 | B6: 以下关键输入依赖分析师假设：forecast、terminal_value、wacc
A7: 提示 | B7: 基准 WACC 11.25%，永续增长率 3.00%
A8: 提示 | B8: DCF 预测与三表模型逐期核对（revenue、ebit、da、capex、nwc），最大偏差 4.55e-13 百万元
