Workbook

Sheet 估值汇总
A1: 中际旭创 估值汇总
A2: 估值基准日 2026-10-03；模型状态 screen-grade；DCF 各情景经营预测取自三表模型；不构成投资建议
A4: 情景 | B4: WACC | C4: 永续增长率 | D4: 企业价值（百万元） | E4: 股权价值（百万元） | F4: 每股价值（元） | G4: 较现价空间 | H4: 终值占 EV | I4: 隐含 EV/EBITDA | J4: 情景说明
A5: 基准 | B5: 0.0993625 | C5: 0.03 | D5: 570166.56 | E5: 579695.41 | F5: 521.72247 | G5: -0.35465529 | H5: 0.77076894 | I5: 10.740968 | J5: 在手订单兑现，2026 年下半年收入略高于上半年；2027 年 800G/1.6T 需求继续增长，之后增速回落。
A6: 悲观 | B6: 0.1093625 | C6: 0.02 | D6: 196888.71 | E6: 206417.55 | F6: 185.77459 | G6: -0.77020609 | H6: 0.65133563 | I6: 8.4575414 | J6: 下半年收入与二季度持平，2027 年云厂商资本开支放缓、1.6T 价格下行，美国法案与 FCC 限制按公司口径落地影响部分订单。
A7: 乐观 | B7: 0.0943625 | C7: 0.035 | D7: 1010544.6 | E7: 1020073.4 | F7: 918.06013 | G7: 0.13559464 | H7: 0.81586517 | I7: 12.600184 | J7: 1.6T 放量快于预期，2027 年订单全面兑现，份额稳定。
A9: 方法 | B9: 低 | C9: 中/基准 | D9: 高
A10: DCF 每股价值（元） | B10: 185.77459 | C10: 521.72247 | D10: 918.06013
A11: 参考股价（元） | C11: 808.44
A12: DCF 与三表模型逐期核对：最大偏差 7.28e-12 百万元（一致）

Sheet 盈利预测
A1: 盈利预测（基准情景）
A2: 单位：百万元（每股为元）；蓝色为报表值或三表模型输出，黑色为公式；预测期归母净利润 = 净利润 × 最近实际年度归母占比；EPS 按最近期末总股本摊薄
A4: 项目 | B4: 2024A | C4: 2025A | D4: 2026E | E4: 2027E | F4: 2028E | G4: 2029E | H4: 2030E
A5: 营业收入 | B5: 23862.16 | C5: 38239.936 | D5: ='三表-利润表'!D5 -> 88431.671 | E5: ='三表-利润表'!E5 -> 133307.58 | F5: ='三表-利润表'!F5 -> 153186.2 | G5: ='三表-利润表'!G5 -> 160440.57 | H5: ='三表-利润表'!H5 -> 164942.91
A6: 营业收入增长率 | C6: =C5/B5-1 -> 0.60253456 | D6: =D5/C5-1 -> 1.3125476 | E6: =E5/D5-1 -> 0.50746419 | F6: =F5/E5-1 -> 0.14911849 | G6: =G5/F5-1 -> 0.047356567 | H6: =H5/G5-1 -> 0.028062302
A7: 营业成本 | B7: 15795.567 | C7: 22165.537 | D7: ='三表-利润表'!D6 -> 47466.421 | E7: ='三表-利润表'!E6 -> 72089.877 | F7: ='三表-利润表'!F6 -> 84327.199 | G7: ='三表-利润表'!G6 -> 89905.952 | H7: ='三表-利润表'!H6 -> 93243.263
A8: 毛利 | B8: =B5-B7 -> 8066.5931 | C8: =C5-C7 -> 16074.399 | D8: =D5-D7 -> 40965.25 | E8: =E5-E7 -> 61217.7 | F8: =F5-F7 -> 68859.002 | G8: =G5-G7 -> 70534.621 | H8: =H5-H7 -> 71699.642
A9: 毛利率 | B9: =B8/B5 -> 0.33804958 | C9: =C8/C5 -> 0.42035632 | D9: =D8/D5 -> 0.46324184 | E9: =E8/E5 -> 0.45922146 | F9: =F8/F5 -> 0.44951178 | G9: =G8/G5 -> 0.43963082 | H9: =H8/H5 -> 0.4346937
A10: EBIT（经营性） | B10: 5873.7406 | C10: 13389.911 | D10: ='三表-利润表'!D11 -> 36479.514 | E10: ='三表-利润表'!E11 -> 54487.482 | F10: ='三表-利润表'!F11 -> 60728.841 | G10: ='三表-利润表'!G11 -> 61539.276 | H10: ='三表-利润表'!H11 -> 62021.176
A11: 净利润 | B11: 5371.7751 | C11: 11579.754 | D11: ='三表-利润表'!D17 -> 30942.445 | E11: ='三表-利润表'!E17 -> 46275.797 | F11: ='三表-利润表'!F17 -> 51590.166 | G11: ='三表-利润表'!G17 -> 52280.232 | H11: ='三表-利润表'!H17 -> 52690.558
A12: 归母净利润 | B12: 5171.486 | C12: 10797.254 | D12: =D11*$C$12/$C$11 -> 28851.514 | E12: =E11*$C$12/$C$11 -> 43148.719 | F12: =F11*$C$12/$C$11 -> 48103.969 | G12: =G11*$C$12/$C$11 -> 48747.404 | H12: =H11*$C$12/$C$11 -> 49130.003
A13: 归母净利润增长率 | C13: =C12/B12-1 -> 1.0878437 | D13: =D12/C12-1 -> 1.6721159 | E13: =E12/D12-1 -> 0.49554433 | F13: =F12/E12-1 -> 0.1148412 | G13: =G12/F12-1 -> 0.013375922 | H13: =H12/G12-1 -> 0.0078485848
A14: 归母净利率 | B14: =B12/B5 -> 0.2167233 | C14: =C12/C5 -> 0.28235545 | D14: =D12/D5 -> 0.32625771 | E14: =E12/E5 -> 0.32367792 | F14: =F12/F5 -> 0.31402286 | G14: =G12/G5 -> 0.30383464 | H14: =H12/H5 -> 0.29786066
A16: 总股本（百万股） | B16: 1111.1183
A17: 参考股价（元） | B17: 808.44
A18: 总市值（百万元） | B18: =B16*B17 -> 898272.51
A20: 每股指标与估值 | B20: 2024A | C20: 2025A | D20: 2026E | E20: 2027E | F20: 2028E | G20: 2029E | H20: 2030E
A21: 每股收益（元） | B21: 4.72 | C21: 9.8 | D21: =D12/$B$16 -> 25.966194 | E21: =E12/$B$16 -> 38.833594 | F21: =F12/$B$16 -> 43.293291 | G21: =G12/$B$16 -> 43.872379 | H21: =H12/$B$16 -> 44.216715
A22: P/E（倍，按参考股价） | B22: =$B$17/B21 -> 171.27966 | C22: =$B$17/C21 -> 82.493878 | D22: =$B$17/D21 -> 31.134328 | E22: =$B$17/E21 -> 20.818057 | F22: =$B$17/F21 -> 18.673563 | G22: =$B$17/G21 -> 18.427084 | H22: =$B$17/H21 -> 18.283584
A23: 注：实际年度 EPS 为报表基本每股收益（加权平均股本）；预测期归母净利润 = 三表模型净利润 × 0.9324（2025 年归母净利润/净利润，假设少数股东损益占比不变）；预测期 EPS 按 2025 年末总股本摊薄，未考虑回购注销对股本的影响

Sheet DCF
A1: 中际旭创 DCF 估值（FCFF，情景随“三表-假设”B5 开关，默认基准）
A2: 单位：百万元（每股为元）；蓝色为输入（财报抽取值、三表模型输出、估值假设），黑色为公式，绿色为跨表引用；预测期经营数据引用三表联动页
A4: 项目（百万元） | B4: FY2025A | C4: FY2026E | D4: FY2027E | E4: FY2028E | F4: FY2029E | G4: FY2030E | I4: 来源及计算口径
A5: 营业收入 | B5: 38239.936 | C5: ='三表-利润表'!D5 -> 88431.671 | D5: ='三表-利润表'!E5 -> 133307.58 | E5: ='三表-利润表'!F5 -> 153186.2 | F5: ='三表-利润表'!G5 -> 160440.57 | G5: ='三表-利润表'!H5 -> 164942.91 | I5: 历史期取合并报表真值表；预测期引用三表-利润表。
A6: 收入增速 | C6: =C5/B5-1 -> 1.3125476 | D6: =D5/C5-1 -> 0.50746419 | E6: =E5/D5-1 -> 0.14911849 | F6: =F5/E5-1 -> 0.047356567 | G6: =G5/F5-1 -> 0.028062302
A7: EBIT（剔除投资收益与公允价值变动） | B7: 13389.911 | C7: ='三表-利润表'!D11 -> 36479.514 | D7: ='三表-利润表'!E11 -> 54487.482 | E7: ='三表-利润表'!F11 -> 60728.841 | F7: ='三表-利润表'!G11 -> 61539.276 | G7: ='三表-利润表'!H11 -> 62021.176 | I7: 经营 EBIT = 利润总额 + 财务费用 − 投资收益 − 公允价值变动收益；预测期引用三表-利润表。
A8: EBIT 利润率 | B8: =B7/B5 -> 0.35015515 | C8: =C7/C5 -> 0.4125164 | D8: =D7/D5 -> 0.40873507 | E8: =E7/E5 -> 0.39643807 | F8: =F7/F5 -> 0.3835643 | G8: =G7/G5 -> 0.37601603
A9: 减：现金税（EBIT × 税率） | B9: 1988.7223 | C9: =C7*'三表-假设'!D19 -> 5418.0812 | D9: =D7*'三表-假设'!E19 -> 8092.6954 | E9: =E7*'三表-假设'!F19 -> 9019.6868 | F9: =F7*'三表-假设'!G19 -> 9140.0558 | G9: =G7*'三表-假设'!H19 -> 9211.6294 | I9: 现金税 = 经营 EBIT × 所得税率；税率引用三表-假设。
A10: NOPAT | B10: =B7-B9 -> 11401.188 | C10: =C7-C9 -> 31061.433 | D10: =D7-D9 -> 46394.786 | E10: =E7-E9 -> 51709.154 | F10: =F7-F9 -> 52399.22 | G10: =G7-G9 -> 52809.546 | I10: NOPAT = 经营 EBIT − 现金税。
A11: 加：折旧摊销 | B11: 826.22595 | C11: ='三表-利润表'!D10 -> 1270.8819 | D11: ='三表-利润表'!E10 -> 1883.9418 | E11: ='三表-利润表'!F10 -> 2561.2146 | F11: ='三表-利润表'!G10 -> 3162.6724 | G11: ='三表-利润表'!H10 -> 3682.1165 | I11: 预测期引用三表-现金流量表。
A12: 减：资本开支 | B12: 2759.9947 | C12: ='三表-假设'!D53 -> 5305.9002 | D12: ='三表-假设'!E53 -> 7998.4546 | E12: ='三表-假设'!F53 -> 7659.31 | F12: ='三表-假设'!G53 -> 8022.0287 | G12: ='三表-假设'!H53 -> 7422.4307 | I12: 预测期引用三表-现金流量表。
A13: 减：营运资本增加 | B13: 2963.7679 | C13: ='三表-假设'!D50 -> 14346.466 | D13: ='三表-假设'!E50 -> 13310.367 | E13: ='三表-假设'!F50 -> 6217.1218 | F13: ='三表-假设'!G50 -> 2537.5062 | G13: ='三表-假设'!H50 -> 1544.6775 | I13: 经营营运资本 = 应收账款 + 存货 − 应付账款；预测期引用三表-假设的辅助计算。
A14: 无杠杆自由现金流（FCFF） | B14: =B10+B11-B12-B13 -> 6503.6517 | C14: =C10+C11-C12-C13 -> 12679.949 | D14: =D10+D11-D12-D13 -> 26969.906 | E14: =E10+E11-E12-E13 -> 40393.937 | F14: =F10+F11-F12-F13 -> 45002.358 | G14: =G10+G11-G12-G13 -> 47524.555 | I14: FCFF = NOPAT + 折旧摊销 − 资本开支 − 营运资本增加。
A16: 折现期（年，年中折现） | C16: 0.5 | D16: 1.5 | E16: 2.5 | F16: 3.5 | G16: 4.5
A17: 折现系数 | C17: =1/(1+$B$21)^C16 -> 0.953739 | D17: =1/(1+$B$21)^D16 -> 0.86753823 | E17: =1/(1+$B$21)^E16 -> 0.78912845 | F17: =1/(1+$B$21)^F16 -> 0.7178055 | G17: =1/(1+$B$21)^G16 -> 0.65292886 | I17: 年中折现：1 / (1 + WACC) ^ 折现期。
A18: FCFF 现值 | C18: =C14*C17 -> 12093.362 | D18: =D14*D17 -> 23397.425 | E18: =E14*E17 -> 31876.005 | F18: =F14*F17 -> 32302.94 | G18: =G14*G17 -> 31030.153
A20: 估值与股权桥 | B20: 百万元 | D20: 来源及计算口径
A21: WACC（基准 + 情景调整） | B21: =WACC!$B$20+'三表-假设'!$D$44 -> 0.0993625
A22: 永续增长率 | B22: ='三表-假设'!$D$40 -> 0.03
A23: 预测期 FCFF 现值合计 | B23: =SUM(C18:G18) -> 130699.88
A24: 终值（永续增长法） | B24: =G14*(1+B22)/(B21-B22) -> 705716.94 | D24: Gordon 增长模型：末年 FCFF × (1 + g) / (WACC − g)。
A25: 终值现值 | B25: =B24/(1+B21)^COUNT(C16:G16) -> 439466.67
A26: 企业价值（EV） | B26: =B23+B25 -> 570166.56 | D26: 企业价值 = 预测期 FCFF 现值合计 + 终值现值。
A27: 终值占 EV | B27: =B25/B26 -> 0.77076894
A28: 加：货币资金 | B28: 10986.893
A29: 加：非经营性资产 | B29: ='非经营性资产'!$B$8 -> 2068.3202
A30: 加：联营投资 | B30: 0
A31: 减：有息负债 | B31: 1595.5928
A32: 减：租赁负债 | B32: 74.731132
A33: 减：少数股东权益 | B33: 1856.0423
A34: 减：养老金、优先股、期权及其他类债务 | B34: 0
A35: 股权价值 | B35: =B26+B28+B29+B30-B31-B32-B33-B34 -> 579695.41 | D35: 股权价值 = 企业价值 + 货币资金 + 非经营性资产 + 联营投资 − 有息负债 − 租赁负债 − 少数股东权益等。
A36: 摊薄股本（百万股） | B36: 1111.1183
A37: 每股价值（元） | B37: =B35/B36 -> 521.72247 | D37: 每股价值 = 股权价值（百万元）/ 摊薄股本（百万股）。
A38: 参考股价（元） | B38: 808.44
A39: 较现价空间 | B39: =B37/B38-1 -> -0.35465529

Sheet WACC
A1: WACC 测算（基准情景）
A2: 蓝色为估值假设文件输入，黑色为公式；各情景在基准 WACC 上加情景调整
A4: 项目 | B4: 数值 | C4: 说明
A5: 无风险利率 | B5: 0.017 | C5: 10 年期国债收益率
A6: β | B6: 1.25 | C6: 可比公司均值
A7: 股权风险溢价 | B7: 0.065
A8: 规模溢价 | B8: 0
A9: 公司特定风险溢价 | B9: 0.005
A10: 国别风险溢价 | B10: 0
A11: 股权成本 Ke | B11: =B5+B6*B7+B8+B9+B10 -> 0.10325 | C11: Rf + β × ERP + 各项溢价
A12: 税前债务成本 | B12: 0.03
A13: 边际税率 | B13: 0.15
A14: 税后债务成本 Kd | B14: =B12*(1-B13) -> 0.0255 | C14: 税前债务成本 × (1 − 税率)
A15: 目标债务占比 | B15: 0.05
A16: 目标股权占比 | B16: 0.95
A17: 优先股占比 | B17: 0
A18: 优先股成本 | B18: 0
A19: 情景调整（基准） | B19: 0
A20: WACC | B20: =B16*B11+B15*B14+B17*B18+B19 -> 0.0993625 | C20: E% × Ke + D% × Kd + P% × Kp + 情景调整

Sheet 敏感性
A1: DCF 敏感性分析（基准情景，每股价值，元）
A2: 黄色为基准情景；WACC、永续增长率与退出倍数为绝对值，收入增速与利润率为相对基准的变动
A4: WACC × 永续增长率
A5: WACC ↓ ／ 永续增长率 → | B5: 0.02 | C5: 0.025 | D5: 0.03 | E5: 0.035 | F5: 0.04
A6: 0.0893625 | B6: 539.31347 | C6: 573.32924 | D6: 613.0752 | E6: 660.13244 | F6: 716.72268
A7: 0.0943625 | B7: 501.51389 | C7: 530.42097 | D7: 563.81934 | E7: 602.84388 | F7: 649.04701
A8: 0.0993625 | B8: 468.52954 | C8: 493.33771 | D8: 521.72247 | E8: 554.51738 | F8: 592.83681
A9: 0.1043625 | B9: 439.50257 | C9: 460.97674 | D9: 485.33868 | E9: 513.21288 | F9: 545.41789
A10: 0.1093625 | B10: 413.7672 | C10: 432.49683 | D10: 453.58646 | E10: 477.51215 | F10: 504.88722
A12: WACC × 退出 EV/EBITDA 倍数
A13: WACC ↓ ／ 退出 EV/EBITDA → | B13: 14 | C13: 16 | D13: 18 | E13: 20 | F13: 22
A14: 0.0893625 | B14: 668.95139 | C14: 746.0408 | D14: 823.1302 | E14: 900.21961 | F14: 977.30902
A15: 0.0943625 | B15: 655.16008 | C15: 730.50445 | D15: 805.84882 | E15: 881.19319 | F15: 956.53756
A16: 0.0993625 | B16: 641.73066 | C16: 715.37718 | D16: 789.0237 | E16: 862.67022 | F16: 936.31674
A17: 0.1043625 | B17: 628.65195 | C17: 700.64633 | D17: 772.6407 | E17: 844.63507 | F17: 916.62945
A18: 0.1093625 | B18: 615.91317 | C18: 686.29967 | D18: 756.68618 | E18: 827.07268 | F18: 897.45919
A20: 收入增速 × EBIT 利润率
A21: 收入增速变动 ↓ ／ EBIT 利润率变动 → | B21: -0.04 | C21: -0.02 | D21: 0 | E21: 0.02 | F21: 0.04
A22: -0.1 | B22: 356.9177 | C22: 379.21731 | D22: 401.51692 | E22: 423.81652 | F22: 446.11613
A23: -0.05 | B23: 405.15612 | C23: 431.80872 | D23: 458.46132 | E23: 485.11392 | F23: 511.76652
A24: 0 | B24: 458.30195 | C24: 490.01221 | D24: 521.72247 | E24: 553.43273 | F24: 585.14299
A25: 0.05 | B25: 516.63231 | C25: 554.18794 | D25: 591.74357 | E25: 629.2992 | F25: 666.85482
A26: 0.1 | B26: 580.42608 | C26: 624.70402 | D26: 668.98196 | E26: 713.2599 | F26: 757.53784

Sheet 非经营性资产
A1: 股权桥：非经营性资产明细
A2: 单位：百万元；逐项核对年报原文（valuation/non_operating_assets.json）；负数为类负债项
A4: 项目 | B4: 百万元 | C4: 来源页 | D4: 原文数（元）
A5: 交易性金融资产 | B5: 10.016137 | C5: p.90 | D5: 10,016,136.99
A6: 长期股权投资 | B6: 1262.9649 | C6: p.90 | D6: 1,262,964,881.17
A7: 其他非流动金融资产 | B7: 795.33921 | C7: p.90 | D7: 795,339,205.36
A8: 合计 | B8: =SUM(B5:B7) -> 2068.3202

Sheet 分部预测
A1: 分部预测：产品量价、毛利率与费用率（驱动三表）
A2: 单位：百万元；蓝色为输入（报表值、驱动假设），黑色为公式，绿色为跨表引用；吨价单位万元/吨；收入增速、综合毛利率、经营费用率由“三表-假设”按情景开关引用
A4: 分部预测（百万元） | B4: FY2024A | C4: FY2025A | D4: FY2026E | E4: FY2027E | F4: FY2028E | G4: FY2029E | H4: FY2030E
A5: 基准情景
A6: 光模块：销量增速 | D6: 0.95 | E6: 0.35 | F6: 0.15 | G6: 0.08 | H6: 0.06
A7: 光模块：销量（吨） | C7: 2109 | D7: =C7*(1+D6) -> 4112.55 | E7: =D7*(1+E6) -> 5551.9425 | F7: =E7*(1+F6) -> 6384.7339 | G7: =F7*(1+G6) -> 6895.5126 | H7: =G7*(1+H6) -> 7309.2433
A8: 光模块：吨价增速 | D8: 0.2 | E8: 0.12 | F8: 0 | G8: -0.03 | H8: -0.03
A9: 光模块：吨价（万元/吨） | C9: =C10*100/C7 -> 1776.0322 | D9: =C9*(1+D8) -> 2131.2386 | E9: =D9*(1+E8) -> 2386.9873 | F9: =E9*(1+F8) -> 2386.9873 | G9: =F9*(1+G8) -> 2315.3776 | H9: =G9*(1+H8) -> 2245.9163
A10: 光模块：收入 | C10: 37456.519 | D10: =D7*D9/100 -> 87648.254 | E10: =E7*E9/100 -> 132524.16 | F10: =F7*F9/100 -> 152402.78 | G10: =G7*G9/100 -> 159657.16 | H10: =H7*H9/100 -> 164159.49
A11: 光模块：毛利率变动（百分点） | D11: 4 | E11: -0.5 | F11: -1 | G11: -1 | H11: -0.5
A12: 光模块：毛利率 | C12: =1-C13/C10 -> 0.42606459 | D12: =C12+D11/100 -> 0.46606459 | E12: =D12+E11/100 -> 0.46106459 | F12: =E12+F11/100 -> 0.45106459 | G12: =F12+G11/100 -> 0.44106459 | H12: =G12+H11/100 -> 0.43606459
A13: 光模块：营业成本 | C13: 21497.622 | D13: =D10*(1-D12) -> 46798.506 | E13: =E10*(1-E12) -> 71421.962 | F13: =F10*(1-F12) -> 83659.284 | G13: =G10*(1-G12) -> 89238.038 | H13: =H10*(1-H12) -> 92575.348
A14: 其他业务收入（保持不变） | C14: 783.41689 | D14: =C14 -> 783.41689 | E14: =D14 -> 783.41689 | F14: =E14 -> 783.41689 | G14: =F14 -> 783.41689 | H14: =G14 -> 783.41689
A15: 其他业务成本（保持不变） | C15: 667.91478 | D15: =C15 -> 667.91478 | E15: =D15 -> 667.91478 | F15: =E15 -> 667.91478 | G15: =F15 -> 667.91478 | H15: =G15 -> 667.91478
A16: 营业收入 | C16: =C10+C14 -> 38239.936 | D16: =D10+D14 -> 88431.671 | E16: =E10+E14 -> 133307.58 | F16: =F10+F14 -> 153186.2 | G16: =G10+G14 -> 160440.57 | H16: =H10+H14 -> 164942.91
A17: 营业收入增速 | D17: =D16/C16-1 -> 1.3125476 | E17: =E16/D16-1 -> 0.50746419 | F17: =F16/E16-1 -> 0.14911849 | G17: =G16/F16-1 -> 0.047356567 | H17: =H16/G16-1 -> 0.028062302
A18: 营业成本 | C18: =C13+C15 -> 22165.537 | D18: =D13+D15 -> 47466.421 | E18: =E13+E15 -> 72089.877 | F18: =F13+F15 -> 84327.199 | G18: =G13+G15 -> 89905.952 | H18: =H13+H15 -> 93243.263
A19: 综合毛利率 | C19: =1-C18/C16 -> 0.42035632 | D19: =1-D18/D16 -> 0.46324184 | E19: =1-E18/E16 -> 0.45922146 | F19: =1-F18/F16 -> 0.44951178 | G19: =1-G18/G16 -> 0.43963082 | H19: =1-H18/H16 -> 0.4346937
A20: 税金及附加率 | C20: 0.0020298516 | D20: 0.0020298516 | E20: 0.0020298516 | F20: 0.0020298516 | G20: 0.0020298516 | H20: 0.0020298516
A21: 销售费用率 | C21: 0.0059146324 | D21: 0.0059146324 | E21: 0.0059146324 | F21: 0.0059146324 | G21: 0.0059146324 | H21: 0.0059146324
A22: 管理费用率 | C22: 0.01989738 | D22: 0.01989738 | E22: 0.01989738 | F22: 0.01989738 | G22: 0.01989738 | H22: 0.01989738
A23: 研发费用率 | C23: 0.042240703 | D23: 0.03 | E23: 0.03 | F23: 0.03 | G23: 0.03 | H23: 0.03
A24: 其他（基期轧差：财务公司利息、折旧重分类等） | C24: -0.021487768 | D24: -0.021487768 | E24: -0.021487768 | F24: -0.021487768 | G24: -0.021487768 | H24: -0.021487768
A25: 经营费用率（不含折旧摊销） | C25: =SUM(C20:C24) -> 0.048594799 | D25: =SUM(D20:D24) -> 0.036354097 | E25: =SUM(E20:E24) -> 0.036354097 | F25: =SUM(F20:F24) -> 0.036354097 | G25: =SUM(G20:G24) -> 0.036354097 | H25: =SUM(H20:H24) -> 0.036354097
A26: 悲观情景
A27: 光模块：销量增速 | D27: 0.85 | E27: 0 | F27: -0.05 | G27: 0.03 | H27: 0.03
A28: 光模块：销量（吨） | C28: 2109 | D28: =C28*(1+D27) -> 3901.65 | E28: =D28*(1+E27) -> 3901.65 | F28: =E28*(1+F27) -> 3706.5675 | G28: =F28*(1+G27) -> 3817.7645 | H28: =G28*(1+H27) -> 3932.2975
A29: 光模块：吨价增速 | D29: 0.18 | E29: -0.08 | F29: -0.05 | G29: -0.03 | H29: -0.03
A30: 光模块：吨价（万元/吨） | C30: =C31*100/C28 -> 1776.0322 | D30: =C30*(1+D29) -> 2095.718 | E30: =D30*(1+E29) -> 1928.0605 | F30: =E30*(1+F29) -> 1831.6575 | G30: =F30*(1+G29) -> 1776.7078 | H30: =G30*(1+H29) -> 1723.4066
A31: 光模块：收入 | C31: 37456.519 | D31: =D28*D30/100 -> 81767.58 | E31: =E28*E30/100 -> 75226.174 | F31: =F28*F30/100 -> 67891.622 | G31: =G28*G30/100 -> 67830.52 | H31: =H28*H30/100 -> 67769.472
A32: 光模块：毛利率变动（百分点） | D32: 3 | E32: -2 | F32: -1 | G32: -0.5 | H32: -0.5
A33: 光模块：毛利率 | C33: =1-C34/C31 -> 0.42606459 | D33: =C33+D32/100 -> 0.45606459 | E33: =D33+E32/100 -> 0.43606459 | F33: =E33+F32/100 -> 0.42606459 | G33: =F33+G32/100 -> 0.42106459 | H33: =G33+H32/100 -> 0.41606459
A34: 光模块：营业成本 | C34: 21497.622 | D34: =D31*(1-D33) -> 44476.282 | E34: =E31*(1-E33) -> 42422.703 | F34: =F31*(1-F33) -> 38965.406 | G34: =G31*(1-G33) -> 39269.489 | H34: =H31*(1-H33) -> 39572.994
A35: 其他业务收入（保持不变） | C35: 783.41689 | D35: =C35 -> 783.41689 | E35: =D35 -> 783.41689 | F35: =E35 -> 783.41689 | G35: =F35 -> 783.41689 | H35: =G35 -> 783.41689
A36: 其他业务成本（保持不变） | C36: 667.91478 | D36: =C36 -> 667.91478 | E36: =D36 -> 667.91478 | F36: =E36 -> 667.91478 | G36: =F36 -> 667.91478 | H36: =G36 -> 667.91478
A37: 营业收入 | C37: =C31+C35 -> 38239.936 | D37: =D31+D35 -> 82550.997 | E37: =E31+E35 -> 76009.591 | F37: =F31+F35 -> 68675.039 | G37: =G31+G35 -> 68613.936 | H37: =H31+H35 -> 68552.889
A38: 营业收入增速 | D38: =D37/C37-1 -> 1.158764 | E38: =E37/D37-1 -> -0.079240792 | F38: =F37/E37-1 -> -0.096495085 | G38: =G37/F37-1 -> -0.00088973317 | H38: =H37/G37-1 -> -0.00088972402
A39: 营业成本 | C39: =C34+C36 -> 22165.537 | D39: =D34+D36 -> 45144.197 | E39: =E34+E36 -> 43090.618 | F39: =F34+F36 -> 39633.321 | G39: =G34+G36 -> 39937.404 | H39: =H34+H36 -> 40240.909
A40: 综合毛利率 | C40: =1-C39/C37 -> 0.42035632 | D40: =1-D39/D37 -> 0.45313566 | E40: =1-E39/E37 -> 0.43308973 | F40: =1-F39/F37 -> 0.42288609 | G40: =1-G39/G37 -> 0.41794034 | H40: =1-H39/H37 -> 0.4129947
A41: 税金及附加率 | C41: 0.0020298516 | D41: 0.0020298516 | E41: 0.0020298516 | F41: 0.0020298516 | G41: 0.0020298516 | H41: 0.0020298516
...

Sheet 三表-假设
A1: 三表联动模型：驱动假设与辅助计算
A2: 单位：百万元；蓝色为输入（报表值、驱动假设），黑色为公式，绿色为跨表引用；改 B5 情景开关（1 悲观 / 2 基准 / 3 乐观）即联动三表与 DCF
A4: 驱动假设 | B4: FY2024A | C4: FY2025A | D4: FY2026E | E4: FY2027E | F4: FY2028E | G4: FY2029E | H4: FY2030E | J4: 来源及计算口径
A5: 情景开关（1 悲观 / 2 基准 / 3 乐观） | B5: 2 | C5: =CHOOSE(B5,"悲观","基准","乐观") -> 基准
A6: 收入与利润率
A7: 收入增速：悲观 | D7: ='分部预测'!D38 -> 1.158764 | E7: ='分部预测'!E38 -> -0.079240792 | F7: ='分部预测'!F38 -> -0.096495085 | G7: ='分部预测'!G38 -> -0.00088973317 | H7: ='分部预测'!H38 -> -0.00088972402
A8: 收入增速：基准 | D8: ='分部预测'!D17 -> 1.3125476 | E8: ='分部预测'!E17 -> 0.50746419 | F8: ='分部预测'!F17 -> 0.14911849 | G8: ='分部预测'!G17 -> 0.047356567 | H8: ='分部预测'!H17 -> 0.028062302
A9: 收入增速：乐观 | D9: ='分部预测'!D59 -> 1.4702492 | E9: ='分部预测'!E59 -> 0.82212473 | F9: ='分部预测'!F59 -> 0.23492584 | G9: ='分部预测'!G59 -> 0.077712518 | H9: ='分部预测'!H59 -> 0.058200278
A10: 收入增速（选用） | C10: ='三表-利润表'!C5/'三表-利润表'!B5-1 -> 0.60253456 | D10: =CHOOSE($B$5,D7,D8,D9) -> 1.3125476 | E10: =CHOOSE($B$5,E7,E8,E9) -> 0.50746419 | F10: =CHOOSE($B$5,F7,F8,F9) -> 0.14911849 | G10: =CHOOSE($B$5,G7,G8,G9) -> 0.047356567 | H10: =CHOOSE($B$5,H7,H8,H9) -> 0.028062302 | J10: 实际期由历史收入反算；预测期按情景开关选用悲观、基准或乐观假设。
A11: 毛利率：悲观 | D11: ='分部预测'!D40 -> 0.45313566 | E11: ='分部预测'!E40 -> 0.43308973 | F11: ='分部预测'!F40 -> 0.42288609 | G11: ='分部预测'!G40 -> 0.41794034 | H11: ='分部预测'!H40 -> 0.4129947
A12: 毛利率：基准 | D12: ='分部预测'!D19 -> 0.46324184 | E12: ='分部预测'!E19 -> 0.45922146 | F12: ='分部预测'!F19 -> 0.44951178 | G12: ='分部预测'!G19 -> 0.43963082 | H12: ='分部预测'!H19 -> 0.4346937
A13: 毛利率：乐观 | D13: ='分部预测'!D61 -> 0.47333911 | E13: ='分部预测'!E61 -> 0.47456882 | F13: ='分部预测'!F61 -> 0.4698718 | G13: ='分部预测'!G61 -> 0.46497491 | H13: ='分部预测'!H61 -> 0.460051
A14: 毛利率（选用） | B14: =1-'三表-利润表'!B6/'三表-利润表'!B5 -> 0.33804958 | C14: =1-'三表-利润表'!C6/'三表-利润表'!C5 -> 0.42035632 | D14: =CHOOSE($B$5,D11,D12,D13) -> 0.46324184 | E14: =CHOOSE($B$5,E11,E12,E13) -> 0.45922146 | F14: =CHOOSE($B$5,F11,F12,F13) -> 0.44951178 | G14: =CHOOSE($B$5,G11,G12,G13) -> 0.43963082 | H14: =CHOOSE($B$5,H11,H12,H13) -> 0.4346937 | J14: 实际期由收入与营业成本反算；预测期按情景开关选用。
A15: 经营费用率（不含折旧摊销，含税金及附加）：悲观 | D15: ='分部预测'!D46 -> 0.041354097 | E15: ='分部预测'!E46 -> 0.041354097 | F15: ='分部预测'!F46 -> 0.041354097 | G15: ='分部预测'!G46 -> 0.041354097 | H15: ='分部预测'!H46 -> 0.041354097
A16: 经营费用率（不含折旧摊销，含税金及附加）：基准 | D16: ='分部预测'!D25 -> 0.036354097 | E16: ='分部预测'!E25 -> 0.036354097 | F16: ='分部预测'!F25 -> 0.036354097 | G16: ='分部预测'!G25 -> 0.036354097 | H16: ='分部预测'!H25 -> 0.036354097
A17: 经营费用率（不含折旧摊销，含税金及附加）：乐观 | D17: ='分部预测'!D67 -> 0.036354097 | E17: ='分部预测'!E67 -> 0.036354097 | F17: ='分部预测'!F67 -> 0.036354097 | G17: ='分部预测'!G67 -> 0.036354097 | H17: ='分部预测'!H67 -> 0.036354097
A18: 经营费用率（不含折旧摊销，含税金及附加）（选用） | B18: ='三表-利润表'!B8/'三表-利润表'!B5 -> 0.06493029 | C18: ='三表-利润表'!C8/'三表-利润表'!C5 -> 0.048594799 | D18: =CHOOSE($B$5,D15,D16,D17) -> 0.036354097 | E18: =CHOOSE($B$5,E15,E16,E17) -> 0.036354097 | F18: =CHOOSE($B$5,F15,F16,F17) -> 0.036354097 | G18: =CHOOSE($B$5,G15,G16,G17) -> 0.036354097 | H18: =CHOOSE($B$5,H15,H16,H17) -> 0.036354097 | J18: 经营费用率不含折旧摊销，含税金及附加；预测期按收入比例计算。
A19: 所得税率 | B19: ='三表-利润表'!B16/'三表-利润表'!B15 -> 0.11246085 | C19: ='三表-利润表'!C16/'三表-利润表'!C15 -> 0.14852394 | D19: 0.14852394 | E19: 0.14852394 | F19: 0.14852394 | G19: 0.14852394 | H19: 0.14852394 | J19: 所得税率 = 所得税费用 / 利润总额；预测期用于计算账面税与现金税。
A20: 现金分红率（占净利润） | D20: 0.15 | E20: 0.15 | F20: 0.15 | G20: 0.15 | H20: 0.15
A21: 营运资本（天）
A22: 应收账款周转天数：悲观 | D22: 74.912751 | E22: 74.912751 | F22: 74.912751 | G22: 74.912751 | H22: 74.912751
A23: 应收账款周转天数：基准 | D23: 59.912751 | E23: 59.912751 | F23: 59.912751 | G23: 59.912751 | H23: 59.912751
A24: 应收账款周转天数：乐观 | D24: 59.912751 | E24: 59.912751 | F24: 59.912751 | G24: 59.912751 | H24: 59.912751
A25: 应收账款周转天数（选用） | B25: ='三表-资产负债表'!B7/'三表-利润表'!B5*365 -> 70.416852 | C25: ='三表-资产负债表'!C7/'三表-利润表'!C5*365 -> 59.912751 | D25: =CHOOSE($B$5,D22,D23,D24) -> 59.912751 | E25: =CHOOSE($B$5,E22,E23,E24) -> 59.912751 | F25: =CHOOSE($B$5,F22,F23,F24) -> 59.912751 | G25: =CHOOSE($B$5,G22,G23,G24) -> 59.912751 | H25: =CHOOSE($B$5,H22,H23,H24) -> 59.912751 | J25: 应收账款周转天数 = 应收账款 / 营业收入 × 365。
A26: 存货周转天数（按营业成本） | B26: ='三表-资产负债表'!B8/'三表-利润表'!B6*365 -> 162.94014 | C26: ='三表-资产负债表'!C8/'三表-利润表'!C6*365 -> 208.81327 | D26: 208.81327 | E26: 208.81327 | F26: 208.81327 | G26: 208.81327 | H26: 208.81327 | J26: 存货周转天数 = 存货 / 营业成本 × 365。
A27: 应付账款周转天数（按营业成本） | B27: ='三表-资产负债表'!B13/'三表-利润表'!B6*365 -> 69.112747 | C27: ='三表-资产负债表'!C13/'三表-利润表'!C6*365 -> 120.70033 | D27: 120.70033 | E27: 120.70033 | F27: 120.70033 | G27: 120.70033 | H27: 120.70033 | J27: 应付账款周转天数 = 应付账款 / 营业成本 × 365。
A28: 资本开支、折旧与财务
A29: 资本开支 / 收入：悲观 | D29: 0.06 | E29: 0.06 | F29: 0.05 | G29: 0.05 | H29: 0.045
A30: 资本开支 / 收入：基准 | D30: 0.06 | E30: 0.06 | F30: 0.05 | G30: 0.05 | H30: 0.045
A31: 资本开支 / 收入：乐观 | D31: 0.06 | E31: 0.055 | F31: 0.05 | G31: 0.045 | H31: 0.04
A32: 资本开支 / 收入（选用） | B32: =-'三表-现金流量表'!B12/'三表-利润表'!B5 -> 0.12011307 | C32: =-'三表-现金流量表'!C12/'三表-利润表'!C5 -> 0.072175715 | D32: =CHOOSE($B$5,D29,D30,D31) -> 0.06 | E32: =CHOOSE($B$5,E29,E30,E31) -> 0.06 | F32: =CHOOSE($B$5,F29,F30,F31) -> 0.05 | G32: =CHOOSE($B$5,G29,G30,G31) -> 0.05 | H32: =CHOOSE($B$5,H29,H30,H31) -> 0.045 | J32: 资本开支率 = 资本开支 / 营业收入。
A33: 折旧率（期初 PP&E + 半年资本开支） | C33: ='三表-利润表'!C10/('三表-资产负债表'!B9-0.5*'三表-现金流量表'!C12) -> 0.11392423 | D33: 0.11392423 | E33: 0.11392423 | F33: 0.11392423 | G33: 0.11392423 | H33: 0.11392423
A34: 利率（财务费用 / 平均有息负债；财务费用为净利息收入时为负） | C34: ='三表-利润表'!C12/AVERAGE('三表-资产负债表'!B14,'三表-资产负债表'!C14) -> 0.083662828 | D34: 0.083662828 | E34: 0.083662828 | F34: 0.083662828 | G34: 0.083662828 | H34: 0.083662828
A35: 有息负债计划还款 | D35: 0 | E35: 0 | F35: 0 | G35: 0 | H35: 0
A36: 估值参数（DCF，全预测期适用）
A37: 永续增长率：悲观 | D37: 0.02
A38: 永续增长率：基准 | D38: 0.03
A39: 永续增长率：乐观 | D39: 0.035
A40: 永续增长率（选用） | D40: =CHOOSE($B$5,D37,D38,D39) -> 0.03
A41: WACC 情景调整：悲观 | D41: 0.01
...

Sheet 三表-利润表
A1: 三表联动模型：利润表（情景见“三表-假设”B5，默认基准）
A2: 单位：百万元；蓝色为输入（报表值、驱动假设），黑色为公式，绿色为跨表引用；预测期由“三表-假设”驱动
A4: 利润表（百万元） | B4: FY2024A | C4: FY2025A | D4: FY2026E | E4: FY2027E | F4: FY2028E | G4: FY2029E | H4: FY2030E | J4: 来源及计算口径
A5: 营业收入 | B5: 23862.16 | C5: 38239.936 | D5: =C5*(1+'三表-假设'!D10) -> 88431.671 | E5: =D5*(1+'三表-假设'!E10) -> 133307.58 | F5: =E5*(1+'三表-假设'!F10) -> 153186.2 | G5: =F5*(1+'三表-假设'!G10) -> 160440.57 | H5: =G5*(1+'三表-假设'!H10) -> 164942.91 | J5: 实际期取合并利润表；预测期 = 上年收入 × (1 + 收入增速)。
A6: 营业成本 | B6: 15795.567 | C6: 22165.537 | D6: =D5*(1-'三表-假设'!D14) -> 47466.421 | E6: =E5*(1-'三表-假设'!E14) -> 72089.877 | F6: =F5*(1-'三表-假设'!F14) -> 84327.199 | G6: =G5*(1-'三表-假设'!G14) -> 89905.952 | H6: =H5*(1-'三表-假设'!H14) -> 93243.263 | J6: 营业成本 = 营业收入 × (1 − 毛利率)。
A7: 毛利 | B7: =B5-B6 -> 8066.5931 | C7: =C5-C6 -> 16074.399 | D7: =D5-D6 -> 40965.25 | E7: =E5-E6 -> 61217.7 | F7: =F5-F6 -> 68859.002 | G7: =G5-G6 -> 70534.621 | H7: =H5-H6 -> 71699.642 | J7: 毛利 = 营业收入 − 营业成本。
A8: 经营费用（不含折旧摊销） | B8: 1549.3769 | C8: 1858.262 | D8: =D5*'三表-假设'!D18 -> 3214.8535 | E8: =E5*'三表-假设'!E18 -> 4846.2765 | F8: =F5*'三表-假设'!F18 -> 5568.946 | G8: =G5*'三表-假设'!G18 -> 5832.6721 | H8: =H5*'三表-假设'!H18 -> 5996.3503
A9: EBITDA | B9: =B7-B8 -> 6517.2162 | C9: =C7-C8 -> 14216.137 | D9: =D7-D8 -> 37750.396 | E9: =E7-E8 -> 56371.423 | F9: =F7-F8 -> 63290.056 | G9: =G7-G8 -> 64701.949 | H9: =H7-H8 -> 65703.292
A10: 折旧摊销 | B10: 643.47558 | C10: 826.22595 | D10: ='三表-假设'!D54 -> 1270.8819 | E10: ='三表-假设'!E54 -> 1883.9418 | F10: ='三表-假设'!F54 -> 2561.2146 | G10: ='三表-假设'!G54 -> 3162.6724 | H10: ='三表-假设'!H54 -> 3682.1165
A11: EBIT（经营性） | B11: =B9-B10 -> 5873.7406 | C11: =C9-C10 -> 13389.911 | D11: =D9-D10 -> 36479.514 | E11: =E9-E10 -> 54487.482 | F11: =F9-F10 -> 60728.841 | G11: =G9-G10 -> 61539.276 | H11: =H9-H10 -> 62021.176 | J11: 经营 EBIT = 毛利 − 经营费用 − 折旧摊销；不含投资收益与公允价值变动收益。
A12: 利息费用（财务费用） | B12: -144.43115 | C12: 182.79816 | D12: ='三表-假设'!D60 -> 139.74403 | E12: ='三表-假设'!E60 -> 139.74403 | F12: ='三表-假设'!F60 -> 139.74403 | G12: ='三表-假设'!G60 -> 139.74403 | H12: ='三表-假设'!H60 -> 139.74403
A13: 经营性税前利润 | B13: =B11-B12 -> 6018.1718 | C13: =C11-C12 -> 13207.112 | D13: =D11-D12 -> 36339.77 | E13: =E11-E12 -> 54347.737 | F13: =F11-F12 -> 60589.097 | G13: =G11-G12 -> 61399.532 | H13: =H11-H12 -> 61881.432
A14: 加：投资收益与公允价值变动 | B14: 34.265605 | C14: 392.51141 | D14: 0 | E14: 0 | F14: 0 | G14: 0 | H14: 0
A15: 利润总额 | B15: =B13+B14 -> 6052.4374 | C15: =C13+C14 -> 13599.624 | D15: =D13+D14 -> 36339.77 | E15: =E13+E14 -> 54347.737 | F15: =F13+F14 -> 60589.097 | G15: =G13+G14 -> 61399.532 | H15: =H13+H14 -> 61881.432 | J15: 利润总额 = 经营 EBIT − 利息费用 + 投资收益及公允价值变动收益。
A16: 减：所得税 | B16: 680.66223 | C16: 2019.8697 | D16: =MAX(D15,0)*'三表-假设'!D19 -> 5397.3259 | E16: =MAX(E15,0)*'三表-假设'!E19 -> 8071.9401 | F16: =MAX(F15,0)*'三表-假设'!F19 -> 8998.9314 | G16: =MAX(G15,0)*'三表-假设'!G19 -> 9119.3004 | H16: =MAX(H15,0)*'三表-假设'!H19 -> 9190.874
A17: 净利润 | B17: =B15-B16 -> 5371.7751 | C17: =C15-C16 -> 11579.754 | D17: =D15-D16 -> 30942.445 | E17: =E15-E16 -> 46275.797 | F17: =F15-F16 -> 51590.166 | G17: =G15-G16 -> 52280.232 | H17: =H15-H16 -> 52690.558 | J17: 净利润 = 利润总额 − 所得税费用。
A19: 主要比率
A20: 营业收入增长率 | C20: =C5/B5-1 -> 0.60253456 | D20: =D5/C5-1 -> 1.3125476 | E20: =E5/D5-1 -> 0.50746419 | F20: =F5/E5-1 -> 0.14911849 | G20: =G5/F5-1 -> 0.047356567 | H20: =H5/G5-1 -> 0.028062302
A21: 毛利率 | B21: =B7/B5 -> 0.33804958 | C21: =C7/C5 -> 0.42035632 | D21: =D7/D5 -> 0.46324184 | E21: =E7/E5 -> 0.45922146 | F21: =F7/F5 -> 0.44951178 | G21: =G7/G5 -> 0.43963082 | H21: =H7/H5 -> 0.4346937
A22: EBIT 利润率 | B22: =B11/B5 -> 0.24615293 | C22: =C11/C5 -> 0.35015515 | D22: =D11/D5 -> 0.4125164 | E22: =E11/E5 -> 0.40873507 | F22: =F11/F5 -> 0.39643807 | G22: =G11/G5 -> 0.3835643 | H22: =H11/H5 -> 0.37601603
A23: 净利率 | B23: =B17/B5 -> 0.22511689 | C23: =C17/C5 -> 0.30281835 | D23: =D17/D5 -> 0.3499023 | E23: =E17/E5 -> 0.34713554 | F23: =F17/F5 -> 0.33678076 | G23: =G17/G5 -> 0.32585418 | H23: =H17/H5 -> 0.31944725
A24: 有效税率 | B24: =B16/B15 -> 0.11246085 | C24: =C16/C15 -> 0.14852394 | D24: =D16/D15 -> 0.14852394 | E24: =E16/E15 -> 0.14852394 | F24: =F16/F15 -> 0.14852394 | G24: =G16/G15 -> 0.14852394 | H24: =H16/H15 -> 0.14852394

Sheet 三表-资产负债表
A1: 三表联动模型：资产负债表（情景见“三表-假设”B5，默认基准）
A2: 单位：百万元；蓝色为输入（报表值、驱动假设），黑色为公式，绿色为跨表引用；权益（含少数股东）合并列示，留存收益为预测期累计
A4: 资产负债表（百万元） | B4: FY2024A | C4: FY2025A | D4: FY2026E | E4: FY2027E | F4: FY2028E | G4: FY2029E | H4: FY2030E | J4: 来源及计算口径
A5: 资产
A6: 货币资金 | B6: 5053.8051 | C6: 10986.893 | D6: ='三表-现金流量表'!D21 -> 18906.486 | E6: ='三表-现金流量表'!E21 -> 38816.034 | F6: ='三表-现金流量表'!F21 -> 71352.458 | G6: ='三表-现金流量表'!G21 -> 108393.79 | H6: ='三表-现金流量表'!H21 -> 147895.77 | J6: 预测期货币资金引用现金流量表期末现金。
A7: 应收账款 | B7: 4603.5566 | C7: 6276.876 | D7: ='三表-假设'!D46 -> 14515.574 | E7: ='三表-假设'!E46 -> 21881.709 | F7: ='三表-假设'!F46 -> 25144.676 | G7: ='三表-假设'!G46 -> 26335.441 | H7: ='三表-假设'!H46 -> 27074.475 | J7: 应收账款 = 营业收入 × 应收账款周转天数 / 365。
A8: 存货 | B8: 7051.3202 | C8: 12680.708 | D8: ='三表-假设'!D47 -> 27155.119 | E8: ='三表-假设'!E47 -> 41241.981 | F8: ='三表-假设'!F47 -> 48242.844 | G8: ='三表-假设'!G47 -> 51434.4 | H8: ='三表-假设'!H47 -> 53343.645 | J8: 存货 = 营业成本 × 存货周转天数 / 365。
A9: 固定资产 + 在建工程 | B9: 5872.4188 | C9: 8502.5505 | D9: ='三表-假设'!D55 -> 12537.569 | E9: ='三表-假设'!E55 -> 18652.082 | F9: ='三表-假设'!F55 -> 23750.177 | G9: ='三表-假设'!G55 -> 28609.533 | H9: ='三表-假设'!H55 -> 32349.848 | J9: 固定资产及在建工程引用固定资产滚动辅助计算。
A10: 其他资产（含财务公司类现金资产） | B10: 6285.1758 | C10: 6841.9436 | D10: =C10 -> 6841.9436 | E10: =D10 -> 6841.9436 | F10: =E10 -> 6841.9436 | G10: =F10 -> 6841.9436 | H10: =G10 -> 6841.9436
A11: 资产总计 | B11: =SUM(B6:B10) -> 28866.277 | C11: =SUM(C6:C10) -> 45288.971 | D11: =SUM(D6:D10) -> 79956.693 | E11: =SUM(E6:E10) -> 127433.75 | F11: =SUM(F6:F10) -> 175332.1 | G11: =SUM(G6:G10) -> 221615.11 | H11: =SUM(H6:H10) -> 267505.69 | J11: 资产总计 = 各项资产合计。
A12: 负债
A13: 应付账款 | B13: 2990.8904 | C13: 7329.8293 | D13: ='三表-假设'!D48 -> 15696.473 | E13: ='三表-假设'!E48 -> 23839.102 | F13: ='三表-假设'!F48 -> 27885.811 | G13: ='三表-假设'!G48 -> 29730.626 | H13: ='三表-假设'!H48 -> 30834.227 | J13: 应付账款 = 营业成本 × 应付账款周转天数 / 365。
A14: 有息负债（含租赁负债） | B14: 2699.5536 | C14: 1670.324 | D14: ='三表-假设'!D59 -> 1670.324 | E14: ='三表-假设'!E59 -> 1670.324 | F14: ='三表-假设'!F59 -> 1670.324 | G14: ='三表-假设'!G59 -> 1670.324 | H14: ='三表-假设'!H59 -> 1670.324
A15: 其他负债 | B15: 2882.9914 | C15: 4667.6191 | D15: =C15 -> 4667.6191 | E15: =D15 -> 4667.6191 | F15: =E15 -> 4667.6191 | G15: =F15 -> 4667.6191 | H15: =G15 -> 4667.6191
A16: 负债合计 | B16: =SUM(B13:B15) -> 8573.4354 | C16: =SUM(C13:C15) -> 13667.772 | D16: =SUM(D13:D15) -> 22034.416 | E16: =SUM(E13:E15) -> 30177.045 | F16: =SUM(F13:F15) -> 34223.754 | G16: =SUM(G13:G15) -> 36068.569 | H16: =SUM(H13:H15) -> 37172.17
A17: 所有者权益
A18: 股本、资本公积及其他权益 | B18: 20292.841 | C18: 31621.199 | D18: =C18 -> 31621.199 | E18: =D18 -> 31621.199 | F18: =E18 -> 31621.199 | G18: =F18 -> 31621.199 | H18: =G18 -> 31621.199
A19: 留存收益（预测期累计） | B19: 0 | C19: 0 | D19: =C19+'三表-利润表'!D17-'三表-假设'!D62 -> 26301.078 | E19: =D19+'三表-利润表'!E17-'三表-假设'!E62 -> 65635.506 | F19: =E19+'三表-利润表'!F17-'三表-假设'!F62 -> 109487.15 | G19: =F19+'三表-利润表'!G17-'三表-假设'!G62 -> 153925.34 | H19: =G19+'三表-利润表'!H17-'三表-假设'!H62 -> 198712.32
A20: 所有者权益合计 | B20: =B18+B19 -> 20292.841 | C20: =C18+C19 -> 31621.199 | D20: =D18+D19 -> 57922.276 | E20: =E18+E19 -> 97256.704 | F20: =F18+F19 -> 141108.35 | G20: =G18+G19 -> 185546.54 | H20: =H18+H19 -> 230333.52
A21: 负债和所有者权益总计 | B21: =B16+B20 -> 28866.277 | C21: =C16+C20 -> 45288.971 | D21: =D16+D20 -> 79956.693 | E21: =E16+E20 -> 127433.75 | F21: =F16+F20 -> 175332.1 | G21: =G16+G20 -> 221615.11 | H21: =H16+H20 -> 267505.69 | J21: 负债和权益总计 = 各项负债与权益合计。
A23: 勾稽检查（应全部为 0，显示为“-”）
A24: 资产总计 − 负债和所有者权益总计 | B24: =ROUND(B11-B21,6) -> 0 | C24: =ROUND(C11-C21,6) -> 0 | D24: =ROUND(D11-D21,6) -> 0 | E24: =ROUND(E11-E21,6) -> 0 | F24: =ROUND(F11-F21,6) -> 0 | G24: =ROUND(G11-G21,6) -> 0 | H24: =ROUND(H11-H21,6) -> 0 | J24: 模型检查 = 资产总计 − 负债和权益总计；容差内应为 0.00。
A25: 现金流量表期末现金 − 货币资金 | D25: =ROUND('三表-现金流量表'!D21-D6,6) -> 0 | E25: =ROUND('三表-现金流量表'!E21-E6,6) -> 0 | F25: =ROUND('三表-现金流量表'!F21-F6,6) -> 0 | G25: =ROUND('三表-现金流量表'!G21-G6,6) -> 0 | H25: =ROUND('三表-现金流量表'!H21-H6,6) -> 0
A26: 留存收益滚动（期初 + 净利润 − 分红 − 期末） | D26: =ROUND(C19+'三表-利润表'!D17-'三表-假设'!D62-D19,6) -> 0 | E26: =ROUND(D19+'三表-利润表'!E17-'三表-假设'!E62-E19,6) -> 0 | F26: =ROUND(E19+'三表-利润表'!F17-'三表-假设'!F62-F19,6) -> 0 | G26: =ROUND(F19+'三表-利润表'!G17-'三表-假设'!G62-G19,6) -> 0 | H26: =ROUND(G19+'三表-利润表'!H17-'三表-假设'!H62-H19,6) -> 0
A27: PP&E 滚动（期初 + 资本开支 − 折旧 − 期末） | D27: =ROUND('三表-假设'!D52+'三表-假设'!D53-'三表-假设'!D54-'三表-假设'!D55,6) -> 0 | E27: =ROUND('三表-假设'!E52+'三表-假设'!E53-'三表-假设'!E54-'三表-假设'!E55,6) -> 0 | F27: =ROUND('三表-假设'!F52+'三表-假设'!F53-'三表-假设'!F54-'三表-假设'!F55,6) -> 0 | G27: =ROUND('三表-假设'!G52+'三表-假设'!G53-'三表-假设'!G54-'三表-假设'!G55,6) -> 0 | H27: =ROUND('三表-假设'!H52+'三表-假设'!H53-'三表-假设'!H54-'三表-假设'!H55,6) -> 0
A28: 有息负债滚动（期初 − 偿还 − 期末） | D28: =ROUND('三表-假设'!D57-'三表-假设'!D58-'三表-假设'!D59,6) -> 0 | E28: =ROUND('三表-假设'!E57-'三表-假设'!E58-'三表-假设'!E59,6) -> 0 | F28: =ROUND('三表-假设'!F57-'三表-假设'!F58-'三表-假设'!F59,6) -> 0 | G28: =ROUND('三表-假设'!G57-'三表-假设'!G58-'三表-假设'!G59,6) -> 0 | H28: =ROUND('三表-假设'!H57-'三表-假设'!H58-'三表-假设'!H59,6) -> 0
A29: 勾稽结论 | B29: =IF(SUM(ABS(B24),ABS(C24),ABS(D24),ABS(E24),ABS(F24),ABS(G24),ABS(H24),ABS(B25),ABS(C25),ABS(D25),ABS(E25),ABS(F25),ABS(G25),ABS(H25),ABS(B26),ABS(C26),ABS(D26),ABS(E26),ABS(F26),ABS(G26),ABS(H26),ABS(B27),ABS(C27),ABS(D27),ABS(E27),ABS(F27),ABS(G27),ABS(H27),ABS(B28),ABS(C28),ABS(D28),ABS(E28),ABS(F28),ABS(G28),ABS(H28))<0.001,"全部平衡","不平衡，请检查") -> 全部平衡 | D29: 汇总资产负债、现金、留存收益、PP&E 与有息负债滚动检查。

Sheet 三表-现金流量表
A1: 三表联动模型：现金流量表（情景见“三表-假设”B5，默认基准）
A2: 单位：百万元；蓝色为输入（报表值、驱动假设），黑色为公式，绿色为跨表引用；实际年度经营现金流为报表值，“其他经营项目”为轧差（含财务公司存款变动）
A4: 现金流量表（百万元） | B4: FY2024A | C4: FY2025A | D4: FY2026E | E4: FY2027E | F4: FY2028E | G4: FY2029E | H4: FY2030E | J4: 来源及计算口径
A5: 经营活动
A6: 净利润 | B6: ='三表-利润表'!B17 -> 5371.7751 | C6: ='三表-利润表'!C17 -> 11579.754 | D6: ='三表-利润表'!D17 -> 30942.445 | E6: ='三表-利润表'!E17 -> 46275.797 | F6: ='三表-利润表'!F17 -> 51590.166 | G6: ='三表-利润表'!G17 -> 52280.232 | H6: ='三表-利润表'!H17 -> 52690.558
A7: 加：折旧摊销 | B7: ='三表-利润表'!B10 -> 643.47558 | C7: ='三表-利润表'!C10 -> 826.22595 | D7: ='三表-利润表'!D10 -> 1270.8819 | E7: ='三表-利润表'!E10 -> 1883.9418 | F7: ='三表-利润表'!F10 -> 2561.2146 | G7: ='三表-利润表'!G10 -> 3162.6724 | H7: ='三表-利润表'!H10 -> 3682.1165
A8: 减：营运资本增加 | C8: =-'三表-假设'!C50 -> -2963.7679 | D8: =-'三表-假设'!D50 -> -14346.466 | E8: =-'三表-假设'!E50 -> -13310.367 | F8: =-'三表-假设'!F50 -> -6217.1218 | G8: =-'三表-假设'!G50 -> -2537.5062 | H8: =-'三表-假设'!H50 -> -1544.6775
A9: 其他经营项目 | C9: =C10-C6-C7-C8 -> 1453.914 | D9: 0 | E9: 0 | F9: 0 | G9: 0 | H9: 0
A10: 经营活动现金流量净额 | B10: 3164.583 | C10: 10896.126 | D10: =SUM(D6:D9) -> 17866.86 | E10: =SUM(E6:E9) -> 34849.372 | F10: =SUM(F6:F9) -> 47934.259 | G10: =SUM(G6:G9) -> 52905.398 | H10: =SUM(H6:H9) -> 54827.997 | J10: 经营活动现金流 = 净利润 + 折旧摊销 − 营运资本增加 + 其他经营项目。
A11: 投资活动
A12: 购建长期资产（资本开支） | B12: -2866.1573 | C12: -2759.9947 | D12: =-'三表-假设'!D53 -> -5305.9002 | E12: =-'三表-假设'!E53 -> -7998.4546 | F12: =-'三表-假设'!F53 -> -7659.31 | G12: =-'三表-假设'!G53 -> -8022.0287 | H12: =-'三表-假设'!H53 -> -7422.4307 | J12: 资本开支为现金流出，取负号列示。
A13: 投资活动现金流量净额（模型口径） | D13: =D12 -> -5305.9002 | E13: =E12 -> -7998.4546 | F13: =F12 -> -7659.31 | G13: =G12 -> -8022.0287 | H13: =H12 -> -7422.4307
A14: 筹资活动
A15: 偿还有息负债 | D15: =-'三表-假设'!D58 -> 0 | E15: =-'三表-假设'!E58 -> 0 | F15: =-'三表-假设'!F58 -> 0 | G15: =-'三表-假设'!G58 -> 0 | H15: =-'三表-假设'!H58 -> 0
A16: 现金分红 | D16: =-'三表-假设'!D62 -> -4641.3667 | E16: =-'三表-假设'!E62 -> -6941.3696 | F16: =-'三表-假设'!F62 -> -7738.5249 | G16: =-'三表-假设'!G62 -> -7842.0348 | H16: =-'三表-假设'!H62 -> -7903.5836
A17: 筹资活动现金流量净额（模型口径） | D17: =D15+D16 -> -4641.3667 | E17: =E15+E16 -> -6941.3696 | F17: =F15+F16 -> -7738.5249 | G17: =G15+G16 -> -7842.0348 | H17: =H15+H16 -> -7903.5836
A19: 现金净增加额 | D19: =D10+D13+D17 -> 7919.5934 | E19: =E10+E13+E17 -> 19909.548 | F19: =F10+F13+F17 -> 32536.424 | G19: =G10+G13+G17 -> 37041.335 | H19: =H10+H13+H17 -> 39501.982
A20: 期初现金 | D20: ='三表-资产负债表'!C6 -> 10986.893 | E20: =D21 -> 18906.486 | F20: =E21 -> 38816.034 | G20: =F21 -> 71352.458 | H20: =G21 -> 108393.79
A21: 期末现金 | D21: =D20+D19 -> 18906.486 | E21: =E20+E19 -> 38816.034 | F21: =F20+F19 -> 71352.458 | G21: =G20+G19 -> 108393.79 | H21: =H20+H19 -> 147895.77 | J21: 期末现金 = 期初现金 + 经营、投资与筹资活动现金流。

Sheet 历史财务
A1: 历史财务数据（2024A / 2025A，合并报表）
A2: 金额单位：百万元（每股为元）；蓝色为年报抽取值（逐字核对原文），黑色为公式；来源为年报 PDF 页码
A4: 项目 | B4: FY2024A | C4: FY2025A | D4: 同比 / 变动 | E4: 来源页 | F4: 原文科目
A5: 利润表
A6: 营业收入（百万元） | B6: 23862.16 | C6: 38239.936 | D6: =IF(B6=0,"NM",(C6-B6)/ABS(B6)) -> 0.60253456 | E6: p.94 | F6: 其中：营业收入
A7: 营业成本（百万元） | B7: 15795.567 | C7: 22165.537 | D7: =IF(B7=0,"NM",(C7-B7)/ABS(B7)) -> 0.40327585 | E7: p.94 | F7: 其中：营业成本
A8: 销售费用（百万元） | B8: 199.26812 | C8: 226.17516 | D8: =IF(B8=0,"NM",(C8-B8)/ABS(B8)) -> 0.13502934 | E8: p.94 | F8: 销售费用
A9: 管理费用（百万元） | B9: 679.53645 | C9: 760.87454 | D9: =IF(B9=0,"NM",(C9-B9)/ABS(B9)) -> 0.11969643 | E9: p.94 | F9: 管理费用
A10: 研发费用（百万元） | B10: 1244.0269 | C10: 1615.2817 | D10: =IF(B10=0,"NM",(C10-B10)/ABS(B10)) -> 0.29842997 | E10: p.95 | F10: 研发费用
A11: 财务费用（百万元） | B11: -144.43115 | C11: 182.79816 | D11: =IF(B11=0,"NM",(C11-B11)/ABS(B11)) -> 2.2656422 | E11: p.95 | F11: 财务费用
A12: 投资收益（百万元） | B12: -32.610478 | C12: 378.88503 | D12: =IF(B12=0,"NM",(C12-B12)/ABS(B12)) -> 12.618506 | E12: p.95 | F12: 投资收益
A13: 公允价值变动收益（百万元） | B13: 66.876082 | C13: 13.626373 | D13: =IF(B13=0,"NM",(C13-B13)/ABS(B13)) -> -0.79624446 | E13: p.95 | F13: 公允价值变动收益
A14: 营业利润（百万元） | B14: 6049.9432 | C14: 13596.92 | D14: =IF(B14=0,"NM",(C14-B14)/ABS(B14)) -> 1.2474459 | E14: p.95 | F14: 三、营业利润
A15: 利润总额（百万元） | B15: 6052.4374 | C15: 13599.624 | D15: =IF(B15=0,"NM",(C15-B15)/ABS(B15)) -> 1.2469665 | E15: p.95 | F15: 四、利润总额
A16: 所得税费用（百万元） | B16: 680.66223 | C16: 2019.8697 | D16: =IF(B16=0,"NM",(C16-B16)/ABS(B16)) -> 1.9675067 | E16: p.95 | F16: 所得税费用
A17: 净利润（百万元） | B17: 5371.7751 | C17: 11579.754 | D17: =IF(B17=0,"NM",(C17-B17)/ABS(B17)) -> 1.1556662 | E17: p.95 | F17: 五、净利润
... A20: 非经常性损益合计（百万元） | B20: 103.12963 | C20: 87.201054 | D20: =IF(B20=0,"NM",(C20-B20)/ABS(B20)) -> -0.15445198 | E20: p.9 | F20: 合计
A21: 资产负债表
A22: 货币资金（百万元） | B22: 5053.8051 | C22: 10986.893 | D22: =IF(B22=0,"NM",(C22-B22)/ABS(B22)) -> 1.1739843 | E22: p.90 | F22: 货币资金
A23: 应收账款（百万元） | B23: 4603.5566 | C23: 6276.876 | D23: =IF(B23=0,"NM",(C23-B23)/ABS(B23)) -> 0.36348404 | E23: p.90 | F23: 应收账款
A24: 存货（百万元） | B24: 7051.3202 | C24: 12680.708 | D24: =IF(B24=0,"NM",(C24-B24)/ABS(B24)) -> 0.79834517 | E24: p.90 | F24: 存货
A25: 固定资产（百万元） | B25: 5819.8818 | C25: 7080.6131 | D25: =IF(B25=0,"NM",(C25-B25)/ABS(B25)) -> 0.2166249 | E25: p.90 | F25: 固定资产
A26: 在建工程（百万元） | B26: 52.537004 | C26: 1421.9374 | D26: =IF(B26=0,"NM",(C26-B26)/ABS(B26)) -> 26.065445 | E26: p.90 | F26: 在建工程
A27: 资产总计（百万元） | B27: 28866.277 | C27: 45288.971 | D27: =IF(B27=0,"NM",(C27-B27)/ABS(B27)) -> 0.5689232 | E27: p.91 | F27: 资产总计
A28: 应付账款（百万元） | B28: 2990.8904 | C28: 7329.8293 | D28: =IF(B28=0,"NM",(C28-B28)/ABS(B28)) -> 1.4507181 | E28: p.91 | F28: 应付账款
A29: 一年内到期的非流动负债（百万元） | B29: 644.41704 | C29: 784.23937 | D29: =IF(B29=0,"NM",(C29-B29)/ABS(B29)) -> 0.21697492 | E29: p.91 | F29: 一年内到期的非流动负债
A30: 租赁负债（百万元） | B30: 23.175094 | C30: 74.731132 | D30: =IF(B30=0,"NM",(C30-B30)/ABS(B30)) -> 2.2246312 | E30: p.91 | F30: 租赁负债
A31: 负债合计（百万元） | B31: 8573.4354 | C31: 13667.772 | D31: =IF(B31=0,"NM",(C31-B31)/ABS(B31)) -> 0.59420019 | E31: p.92 | F31: 负债合计
A32: 归属于母公司所有者权益合计（百万元） | B32: 19133.887 | C32: 29765.156 | D32: =IF(B32=0,"NM",(C32-B32)/ABS(B32)) -> 0.55562517 | E32: p.92 | F32: 归属于母公司所有者权益合计
A33: 少数股东权益（百万元） | B33: 1158.9542 | C33: 1856.0423 | D33: =IF(B33=0,"NM",(C33-B33)/ABS(B33)) -> 0.60148035 | E33: p.92 | F33: 少数股东权益
A34: 所有者权益合计（百万元） | B34: 20292.841 | C34: 31621.199 | D34: =IF(B34=0,"NM",(C34-B34)/ABS(B34)) -> 0.55824403 | E34: p.92 | F34: 所有者权益合计
A35: 现金流量表
A36: 经营活动产生的现金流量净额（百万元） | B36: 3164.583 | C36: 10896.126 | D36: =IF(B36=0,"NM",(C36-B36)/ABS(B36)) -> 2.4431476 | E36: p.98 | F36: 经营活动产生的现金流量净额
A37: 购建固定资产、无形资产和其他长期资产支付的现金（百万元） | B37: 2866.1573 | C37: 2759.9947 | D37: =IF(B37=0,"NM",(C37-B37)/ABS(B37)) -> -0.037040055 | E37: p.98 | F37: 购建固定资产、无形资产和其他长期资产支付的现金
A38: 固定资产折旧、油气资产折耗、生产性生物资产折旧（百万元） | B38: 545.14848 | C38: 739.76311 | D38: =IF(B38=0,"NM",(C38-B38)/ABS(B38)) -> 0.35699379 | E38: p.190 | F38: 固定资产折旧、油气资产折耗、生产性生物资产折旧
A39: 无形资产摊销（百万元） | B39: 98.327096 | C39: 86.46284 | D39: =IF(B39=0,"NM",(C39-B39)/ABS(B39)) -> -0.1206611 | E39: p.191 | F39: 无形资产摊销
A40: 每股与比率
A41: 基本每股收益（元） | B41: 4.72 | C41: 9.8 | D41: =IF(B41=0,"NM",(C41-B41)/ABS(B41)) -> 1.0762712 | E41: p.8 | F41: 基本每股收益（元/股）
A42: 加权平均净资产收益率 | B42: 0.3123 | C42: 0.4384 | D42: =(C42-B42)*100 -> 12.61 | E42: p.8 | F42: 加权平均净资产收益率
A43: 毛利率 | B43: =(B6-B7)/B6 -> 0.33804958 | C43: =(C6-C7)/C6 -> 0.42035632 | D43: =(C43-B43)*100 -> 8.2306735 | E43: 派生
...

Sheet 分季度
A1: 2025 年分季度数据（单季，合并报表）
A2: 单位：百万元；蓝色为年报“分季度主要财务数据”列示值，黑色为公式；差异 = 四季合计 − 全年报表值
A4: 项目（百万元） | B4: Q1 | C4: Q2 | D4: Q3 | E4: Q4 | F4: 四季合计 | G4: 全年（报表） | H4: 差异
A5: 营业收入 | B5: 6674.1765 | C5: 8114.8984 | D5: 10215.726 | E5: 13235.135 | F5: =SUM(B5:E5) -> 38239.936 | G5: 38239.936 | H5: =ROUND(F5-G5,2) -> 0
A6: 归属于上市公司股东的净利润 | B6: 1582.8761 | C6: 2412.2393 | D6: 3136.8171 | E6: 3665.3219 | F6: =SUM(B6:E6) -> 10797.254 | G6: 10797.254 | H6: =ROUND(F6-G6,2) -> 0
A7: 归属于上市公司股东的扣除非经常性损益的净利润 | B7: 1568.3853 | C7: 2406.9963 | D7: 3108.3181 | E7: 3626.3535 | F7: =SUM(B7:E7) -> 10710.053 | G7: 10710.053 | H7: =ROUND(F7-G7,2) -> 0
A8: 非经常性损益合计 | B8: =B6-B7 -> 14.490841 | C8: =C6-C7 -> 5.2429484 | D8: =D6-D7 -> 28.498934 | E8: =E6-E7 -> 38.96833 | F8: =SUM(B8:E8) -> 87.201054 | G8: 87.201054 | H8: =ROUND(F8-G8,2) -> 0
A9: 经营活动产生的现金流量净额 | B9: 2164.4596 | C9: 1054.0037 | D9: 2236.3579 | E9: 5441.3049 | F9: =SUM(B9:E9) -> 10896.126 | G9: 10896.126 | H9: =ROUND(F9-G9,2) -> 0

Sheet 经营数据
A1: 经营数据（分产品 / 渠道 / 地区，量价）
A2: 金额单位：百万元；蓝色为年报原文数（逐格核对，见 financials/extras.json），黑色为公式；页码为年报 PDF 页
A4: 光通信收发模块收入与成本（分产品）（p.25）
A5: 项目 | B5: 营业收入（百万元） | C5: 营业成本（百万元） | D5: 毛利率
A6: 光通信收发模块 | B6: 37456.519 | C6: 21497.622 | D6: 0.4261
A7: 营业收入分产品（p.24）
A8: 项目 | B8: 营业收入（百万元） | C8: 占营业收入比重 | D8: 上年营业收入（百万元） | E8: 上年占营业收入比重 | F8: 营业收入同比
A9: 光通信收发模块 | B9: 37456.519 | C9: 0.9795 | D9: 22885.757 | E9: 0.9591 | F9: 0.6367
A10: 其他 | B10: 783.41689 | C10: 0.0205 | D10: 976.40301 | E10: 0.0409 | F10: -0.1977
A11: 占营业收入10%以上的产品、地区、销售模式（p.25）
A12: 项目 | B12: 营业收入（百万元） | C12: 营业成本（百万元） | D12: 毛利率 | E12: 营业收入同比 | F12: 营业成本同比 | G12: 毛利率同比
A13: 光通信收发模块 | B13: 37456.519 | C13: 21497.622 | D13: 0.4261 | E13: 0.6367 | F13: 0.4374 | G13: 7.96
A14: 境外 | B14: 34636.523 | C14: 19176.165 | D14: 0.4464 | E14: 0.672 | F14: 0.4634 | G14: 7.89
A15: 直销 | B15: 37738.951 | C15: 21842.688 | D15: 0.4212 | E15: 0.6059 | F15: 0.4038 | G15: 8.33
A16: 光通信收发模块产能、产量、销量、毛利率（p.13）
A17: 项目 | B17: 产能（万只） | C17: 产量（万只） | D17: 销量（万只） | E17: 毛利率
A18: 2025年 | B18: 2806 | C18: 2376 | D18: 2109 | E18: 0.4261
A19: 2024年 | B19: 2088 | C19: 1536 | D19: 1459 | E19: 0.3465
A20: 分产品产销存（2025年）（p.25）
A21: 项目 | B21: 销量（万只） | C21: 产量（万只） | D21: 库存量（万只）
A22: 光通信收发模块 | B22: 2109 | C22: 2376 | D22: 521
A23: 其他 | B23: 3424 | C23: 3366 | D23: 909
A24: 光通信模块产销存（p.25）
A25: 项目 | B25: 2025年（万只） | C25: 2024年（万只） | D25: 同比
A26: 销售量 | B26: 2109 | C26: 1459 | D26: 0.4455
A27: 生产量 | B27: 2376 | C27: 1536 | D27: 0.5469
A28: 库存量 | B28: 521 | C28: 254 | D28: 1.0512
A29: 其他业务（光组件/汽车光电子）产销存（p.25）
A30: 项目 | B30: 2025年（万只/件） | C30: 2024年（万只/件） | D30: 同比
A31: 其他销售量 | B31: 3424 | C31: 5782 | D31: -0.4078
A32: 营业成本构成（行业分类）（p.25）
A33: 项目 | B33: 营业成本（百万元） | C33: 占营业成本比重 | D33: 上年营业成本（百万元） | E33: 上年占营业成本比重 | F33: 同比
A34: 光通信收发模块 | B34: 21497.622 | C34: 0.9699 | D34: 14956.342 | E34: 0.9468 | F34: 0.4374
A35: 其他 | B35: 667.91478 | C35: 0.0301 | D35: 839.22478 | E35: 0.0532 | F35: -0.2041
A36: 营业收入分地区（p.24）
A37: 项目 | B37: 营业收入（百万元） | C37: 占营业收入比重 | D37: 上年营业收入（百万元） | E37: 上年占营业收入比重 | F37: 营业收入同比
A38: 境外 | B38: 34636.523 | C38: 0.9058 | D38: 20715.714 | E38: 0.8681 | F38: 0.672
A39: 境内 | B39: 3603.4123 | C39: 0.0942 | D39: 3146.4452 | E39: 0.1319 | F39: 0.1452
A40: 营业收入分销售模式（p.24）
A41: 项目 | B41: 营业收入（百万元） | C41: 占营业收入比重 | D41: 上年营业收入（百万元） | E41: 上年占营业收入比重 | F41: 营业收入同比
...

Sheet 模型检查
A1: 模型检查
A2: 硬性失败会使模型状态变为 blocked；警示需在报告中说明
A4: 类型 | B4: 内容
A5: 警示 | B5: 终值占企业价值 77.1%，结论高度依赖终值假设，需重点复核 WACC 与永续增长率
A6: 警示 | B6: 以下关键输入依赖分析师假设：forecast、terminal_value、wacc
A7: 提示 | B7: 基准 WACC 9.94%，永续增长率 3.00%
A8: 提示 | B8: DCF 预测与三表模型逐期核对（revenue、ebit、da、capex、nwc），最大偏差 7.28e-12 百万元
